Workbook

Sheet 00_使い方
A1: 応答曲面法（RSM）ツール v1.1 ── 4因子・2次モデル
A2: 作成日 2026-09-30 ／ 同梱データは架空の乾燥炉データ（検証用） ／ 2因子版・3因子版・4因子版は別ファイル
A4: この版でできること
B5: 4因子の中心複合計画（面心／回転可能）・Box-Behnken計画の生成、安全限界チェック、ランダマイズ（完全ランダム／変更困難因子でグループ化した順序生成）、2次回帰・ANOVA・適合度の欠如・残差診断・モデル縮小、正準解析（停留点・固有値）、領域内の最適化（点予測／予測限界ベース）、工程窓の可視化と組合せチェック、確認実験の判定
A6: 手順と判断ゲート
A7: ① 01_因子設定 | B7: 因子名・単位・範囲（±1）・安全限界、Yの方向と規格、計画の種類、中心点数を入力。『安全限界チェック』が×の計画は実行不可。
A8: ② 02_実験計画 | B8: 標準順の計画と実験順序を確認（通常は触らない）。順序を変えたいときは乱数キーを入れ替え。
A9: ③ 03_実験結果 | B9: 実験順に実施し、Yを入力。異常があればメモ欄へ。
A10: ④ 04_回帰ANOVA | B10: 判断ゲートに×がないことを確認し、△は内容を理解して記録。不要項はB列を0にして除外（階層性に注意）。
A11: ⑤ 05_残差診断 | B11: グラフでパターン・外れ値を目視確認。外れ値は消す前に原因を調査。
A12: ⑥ 06_正準解析 | B12: 停留点が最大／最小／鞍点か、領域内か外かを確認。鞍点・領域外なら07の探索結果を採用。
A13: ⑦ 07_最適化 | B13: ロバスト最適（規格側の予測限界と規格の差が最大）を推奨条件とする。必要ならSolverで精密化。
A14: ⑧ 08_工程窓 | B14: 2因子断面の緑領域が工程窓。③の1因子窓は楽観的なので、④で運用範囲の全組合せを必ず確認。
A15: ⑨ 09_確認実験 | B15: 推奨条件で確認実験。両側予測区間内なら採用、外れたら計画・モデルを見直す。
A16: セルの色
A17: 黄色・青字 | B17: 入力セル。ほかは計算式なので編集しない。
A18: 『_』で始まるシート | B18: 計算用（編集不要）。_XtX＝回帰の行列計算、_grid＝6561点の探索、_eig＝固有値、_slice＝断面、_win＝工程窓。
A19: 前提と限界（重要）
A20: コード化単位 | B20: 回帰係数は −1〜+1 に正規化した単位。係数の大小がそのまま効果の大きさ比較になる。
A21: 予測限界の片側／両側 | B21: 工程窓・ロバスト最適は、最大化・最小化では片側の予測限界（信頼水準95%なら下側95%限界＝t0.95）、目標値では両側予測区間（t0.975）で判定。確認実験の判定は常に両側予測区間。
A22: 予測区間と許容区間 | B22: 予測区間が保証するのは『将来の1回の測定値』。量産で『ロットの大部分（例：99%）が規格内』と言うには許容区間（Tolerance Interval）が本来の指標で、予測区間より広くなる。この工程窓は量産の工程能力保証ではなく、条件設定の目安として使う。量産移行時は工程能力調査（Cpk）で確認。
A23: 探索範囲 | B23: 最適化・工程窓は ±1（要因点の範囲）内のみ。外挿はしない。BBDは頂点付近にデータがないため半径√2の球内に限定。
A24: 分割区画（Split-Plot） | B24: v1は分割区画の解析に対応していない。『変更困難因子でグループ化』は実験順序を作るだけで、解析は完全ランダムとみなした近似（変更困難因子のp値は小さく出やすい）。04の判断ゲートに△を表示。正式な解析はJMP・R（lme4等）で。
A25: 固有値 | B25: Jacobi法の数値計算（48回転）。4×4行列では十分収束する。
A26: この版にないもの | B26: スクリーニング（Plackett-Burman）・曲率判定・最急上昇法（v2予定）、多目的最適化（望ましさ関数）・モンテカルロ・分割区画の正式解析（v3予定）。
A27: 動作環境 | B27: Excel 2019以降または Microsoft 365（1因子窓で MAXIFS/MINIFS を使用）。マクロなし。
A28: 架空データについて | B28: 炉温55〜75℃・乾燥時間20〜40min・循環風速1〜3m/s・給気率20〜60%、Y＝剥離強度（最大化、LSL=46.5）。数値はツール検証用の作り物。安全上限（炉温80℃等）も仮値なので、実案件では必ず再設定。01で回転可能CCDを選ぶと炉温の軸点が85℃になり、安全限界チェックが×になる例になっている。

Sheet 01_因子設定
A1: 01 因子と目的変数の設定（4因子）
A2: 黄色セル（青字）が入力欄。架空の乾燥炉データ（接着剤塗布後の溶剤乾燥・バッチ式）を例として入れてあります。
A4: No | B4: 因子名 | C4: 記号 | D4: 単位 | E4: 下限(-1) | F4: 上限(+1) | G4: 中心(0) | H4: 半幅 | I4: 安全下限 | J4: 安全上限 | K4: 変更困難 | L4: 安全下限(コード) | M4: 安全上限(コード) | N4: 備考
A5: 1 | B5: 炉温 | C5: X1 | D5: ℃ | E5: 55 | F5: 75 | G5: =(E5+F5)/2 -> 65 | H5: =(F5-E5)/2 -> 10 | J5: 80 | K5: ○ | L5: =IF(I5="",-99,(I5-G5)/H5) -> -99 | M5: =IF(J5="",99,(J5-G5)/H5) -> 1.5 | N5: 安全上限80℃は仮値。溶剤の引火点・防爆の温度等級から必ず再設定
A6: 2 | B6: 乾燥時間 | C6: X2 | D6: min | E6: 20 | F6: 40 | G6: =(E6+F6)/2 -> 30 | H6: =(F6-E6)/2 -> 10 | I6: 10 | L6: =IF(I6="",-99,(I6-G6)/H6) -> -2 | M6: =IF(J6="",99,(J6-G6)/H6) -> 99
A7: 3 | B7: 循環風速 | C7: X3 | D7: m/s | E7: 1 | F7: 3 | G7: =(E7+F7)/2 -> 2 | H7: =(F7-E7)/2 -> 1 | I7: 0.5 | J7: 4 | L7: =IF(I7="",-99,(I7-G7)/H7) -> -1.5 | M7: =IF(J7="",99,(J7-G7)/H7) -> 2 | N7: ファン能力の範囲
A8: 4 | B8: 給気率 | C8: X4 | D8: % | E8: 20 | F8: 60 | G8: =(E8+F8)/2 -> 40 | H8: =(F8-E8)/2 -> 20 | I8: 20 | J8: 100 | L8: =IF(I8="",-99,(I8-G8)/H8) -> -1 | M8: =IF(J8="",99,(J8-G8)/H8) -> 3 | N8: 防爆上、溶剤濃度を下げるため給気率下限あり（仮値）
A10: 目的変数（Y）
A11: 名称 | B11: 剥離強度
A12: 単位 | B12: N/25mm
A13: 最適化の方向 | B13: 最大化 | C13: 最大化→LSLのみ使用 / 最小化→USLのみ / 目標値→LSL・USL・T を使用
A14: 下限規格 LSL | B14: 46.5
A15: 上限規格 USL
A16: 目標値 T
A17: 予測区間の信頼水準 | B17: 0.95 | C17: 最大化・最小化は片側の予測限界（例：95%なら下側95%限界）、目標値は両側の予測区間で工程窓を判定
A19: 実験計画
A20: 計画の種類 | B20: 面心CCD(α=1) | C20: 4因子: CCD=要因16+軸8+中心、BBD=24+中心。BBDは全因子同時の極端条件（立方体の頂点）を含まない
A21: 中心点の数 | B21: 6 | C21: 純誤差（適合度の欠如の検定）に使うため3以上。推奨5〜6
A22: α（軸点距離） | B22: =IF(B20="回転可能CCD(α=2.000)",2,1) -> 1
A23: 総実験数 N | B23: =B26+B21 -> 30
A24: ランダマイズ方式 | B24: 完全ランダム | C24: グループ化＝変更困難因子の水準ごとに実験をまとめる順序生成のみ。解析は分割区画に対応していない（04に警告表示）
A25: 変更困難因子 No | B25: =IFERROR(MATCH("○",K5:K8,0),0) -> 1
A26: 計画点数（中心点除く） | B26: =IF(B20="Box-Behnken",24,24) -> 24
A27: 安全限界チェック（計画上の最小・最大の実値）
A28: 因子 | B28: 計画の最小 | C28: 計画の最大 | D28: 安全下限 | E28: 安全上限 | F28: 判定
A29: =B5 -> 炉温 | B29: =G5-$B$22*H5 -> 55 | C29: =G5+$B$22*H5 -> 75 | D29: =IF(I5="","―",I5) -> ― | E29: =IF(J5="","―",J5) -> 80 | F29: =IF(AND(OR(I5="",B29>=I5),OR(J5="",C29<=J5)),"OK","安全限界超過") -> OK
A30: =B6 -> 乾燥時間 | B30: =G6-$B$22*H6 -> 20 | C30: =G6+$B$22*H6 -> 40 | D30: =IF(I6="","―",I6) -> 10 | E30: =IF(J6="","―",J6) -> ― | F30: =IF(AND(OR(I6="",B30>=I6),OR(J6="",C30<=J6)),"OK","安全限界超過") -> OK
A31: =B7 -> 循環風速 | B31: =G7-$B$22*H7 -> 1 | C31: =G7+$B$22*H7 -> 3 | D31: =IF(I7="","―",I7) -> 0.5 | E31: =IF(J7="","―",J7) -> 4 | F31: =IF(AND(OR(I7="",B31>=I7),OR(J7="",C31<=J7)),"OK","安全限界超過") -> OK
A32: =B8 -> 給気率 | B32: =G8-$B$22*H8 -> 20 | C32: =G8+$B$22*H8 -> 60 | D32: =IF(I8="","―",I8) -> 20 | E32: =IF(J8="","―",J8) -> 100 | F32: =IF(AND(OR(I8="",B32>=I8),OR(J8="",C32<=J8)),"OK","安全限界超過") -> OK
A33: 総合判定 | B33: =IF(COUNTIF(F29:F32,"安全限界超過")>0,"× 安全限界を超える実験点あり → この計画は実行不可。面心CCDかBox-Behnkenへ変更、または範囲を縮小","○ 全実験点が安全限界内") -> ○ 全実験点が安全限界内

Sheet 02_実験計画
A1: 02 実験計画（標準順）とランダマイズ
A2: 計画の種類・中心点数は01で選択。乱数キーを入れ替えると実験順序が変わります（=RAND()を入れ→コピー→値貼り付け）。
A4: 標準順 | B4: 区分 | C4: 使用 | D4: X1(コード) | E4: X2(コード) | F4: X3(コード) | G4: X4(コード) | H4: ="X1 "&01_因子設定!B5&"["&01_因子設定!D5&"]" -> X1 炉温[℃] | I4: ="X2 "&01_因子設定!B6&"["&01_因子設定!D6&"]" -> X2 乾燥時間[min] | J4: ="X3 "&01_因子設定!B7&"["&01_因子設定!D7&"]" -> X3 循環風速[m/s] | K4: ="X4 "&01_因子設定!B8&"["&01_因子設定!D8&"]" -> X4 給気率[%] | L4: 安全判定 | M4: 乱数キー | N4: 並べ替えキー | O4: 実験順序 | P4: Y（03から） | R4: CCD1 | S4: CCD2 | T4: CCD3 | U4: CCD4 | V4: BBD1 | W4: BBD2 | X4: BBD3 | Y4: BBD4 | AA4: 水準(コード) | AB4: グループ順位
A5: 1 | B5: =IF(A5>01_因子設定!$B$23,"未使用",IF(A5>01_因子設定!$B$26,"中心点",IF(01_因子設定!$B$20="Box-Behnken","BBD点",IF(A5<=16,"要因点","軸点")))) -> 要因点 | C5: =IF(A5<=01_因子設定!$B$23,1,0) -> 1 | D5: =IF($C5=0,0,IF(01_因子設定!$B$20="Box-Behnken",V5,R5*IF($A5>16,01_因子設定!$B$22,1))) -> -1 | E5: =IF($C5=0,0,IF(01_因子設定!$B$20="Box-Behnken",W5,S5*IF($A5>16,01_因子設定!$B$22,1))) -> -1 | F5: =IF($C5=0,0,IF(01_因子設定!$B$20="Box-Behnken",X5,T5*IF($A5>16,01_因子設定!$B$22,1))) -> -1 | G5: =IF($C5=0,0,IF(01_因子設定!$B$20="Box-Behnken",Y5,U5*IF($A5>16,01_因子設定!$B$22,1))) -> -1 | H5: =IF($C5=1,01_因子設定!$G$5+D5*01_因子設定!$H$5,"") -> 55 | I5: =IF($C5=1,01_因子設定!$G$6+E5*01_因子設定!$H$6,"") -> 20 | J5: =IF($C5=1,01_因子設定!$G$7+F5*01_因子設定!$H$7,"") -> 1 | K5: =IF($C5=1,01_因子設定!$G$8+G5*01_因子設定!$H$8,"") -> 20 | L5: =IF(C5=0,"",IF(AND(OR(01_因子設定!$I$5="",H5>=01_因子設定!$I$5),OR(01_因子設定!$J$5="",H5<=01_因子設定!$J$5),OR(01_因子設定!$I$6="",I5>=01_因子設定!$I$6),OR(01_因子設定!$J$6="",I5<=01_因子設定!$J$6),OR(01_因子設定!$I$7="",J5>=01_因子設定!$I$7),OR(01_因子設定!$J$7="",J5<=01_因子設定!$J$7),OR(01_因子設定!$I$8="",K5>=01_因子設定!$I$8),OR(01_因子設定!$J$8="",K5<=01_因子設定!$J$8)),"OK","安全限界超過")) -> OK | M5: 0.091432 | N5: =IF(C5=0,99,IF(AND(01_因子設定!$B$24="変更困難因子でグループ化",01_因子設定!$B$25>0),VLOOKUP(ROUND(INDEX(D5:G5,01_因子設定!$B$25),6),$AA$5:$AB$9,2,FALSE())+M5*0.9,M5)) -> 0.091432 | O5: =IF(C5=1,SUMPRODUCT(($C$5:$C$38=1)*($N$5:$N$38<N5))+1,"") -> 5 | P5: =IF(C5=1,INDEX(03_実験結果!$I$5:$I$38,O5),0) -> 37.7 | R5: -1 | S5: -1 | T5: -1 | U5: -1 | V5: -1 | W5: -1 | X5: 0 | Y5: 0 | AA5: -2 | AB5: 3
A6: 2 | B6: =IF(A6>01_因子設定!$B$23,"未使用",IF(A6>01_因子設定!$B$26,"中心点",IF(01_因子設定!$B$20="Box-Behnken","BBD点",IF(A6<=16,"要因点","軸点")))) -> 要因点 | C6: =IF(A6<=01_因子設定!$B$23,1,0) -> 1 | D6: =IF($C6=0,0,IF(01_因子設定!$B$20="Box-Behnken",V6,R6*IF($A6>16,01_因子設定!$B$22,1))) -> 1 | E6: =IF($C6=0,0,IF(01_因子設定!$B$20="Box-Behnken",W6,S6*IF($A6>16,01_因子設定!$B$22,1))) -> -1 | F6: =IF($C6=0,0,IF(01_因子設定!$B$20="Box-Behnken",X6,T6*IF($A6>16,01_因子設定!$B$22,1))) -> -1 | G6: =IF($C6=0,0,IF(01_因子設定!$B$20="Box-Behnken",Y6,U6*IF($A6>16,01_因子設定!$B$22,1))) -> -1 | H6: =IF($C6=1,01_因子設定!$G$5+D6*01_因子設定!$H$5,"") -> 75 | I6: =IF($C6=1,01_因子設定!$G$6+E6*01_因子設定!$H$6,"") -> 20 | J6: =IF($C6=1,01_因子設定!$G$7+F6*01_因子設定!$H$7,"") -> 1 | K6: =IF($C6=1,01_因子設定!$G$8+G6*01_因子設定!$H$8,"") -> 20 | L6: =IF(C6=0,"",IF(AND(OR(01_因子設定!$I$5="",H6>=01_因子設定!$I$5),OR(01_因子設定!$J$5="",H6<=01_因子設定!$J$5),OR(01_因子設定!$I$6="",I6>=01_因子設定!$I$6),OR(01_因子設定!$J$6="",I6<=01_因子設定!$J$6),OR(01_因子設定!$I$7="",J6>=01_因子設定!$I$7),OR(01_因子設定!$J$7="",J6<=01_因子設定!$J$7),OR(01_因子設定!$I$8="",K6>=01_因子設定!$I$8),OR(01_因子設定!$J$8="",K6<=01_因子設定!$J$8)),"OK","安全限界超過")) -> OK | M6: 0.069287 | N6: =IF(C6=0,99,IF(AND(01_因子設定!$B$24="変更困難因子でグループ化",01_因子設定!$B$25>0),VLOOKUP(ROUND(INDEX(D6:G6,01_因子設定!$B$25),6),$AA$5:$AB$9,2,FALSE())+M6*0.9,M6)) -> 0.069287 | O6: =IF(C6=1,SUMPRODUCT(($C$5:$C$38=1)*($N$5:$N$38<N6))+1,"") -> 3 | P6: =IF(C6=1,INDEX(03_実験結果!$I$5:$I$38,O6),0) -> 39.4 | R6: 1 | S6: -1 | T6: -1 | U6: -1 | V6: 1 | W6: -1 | X6: 0 | Y6: 0 | AA6: -1 | AB6: 1
A7: 3 | B7: =IF(A7>01_因子設定!$B$23,"未使用",IF(A7>01_因子設定!$B$26,"中心点",IF(01_因子設定!$B$20="Box-Behnken","BBD点",IF(A7<=16,"要因点","軸点")))) -> 要因点 | C7: =IF(A7<=01_因子設定!$B$23,1,0) -> 1 | D7: =IF($C7=0,0,IF(01_因子設定!$B$20="Box-Behnken",V7,R7*IF($A7>16,01_因子設定!$B$22,1))) -> -1 | E7: =IF($C7=0,0,IF(01_因子設定!$B$20="Box-Behnken",W7,S7*IF($A7>16,01_因子設定!$B$22,1))) -> 1 | F7: =IF($C7=0,0,IF(01_因子設定!$B$20="Box-Behnken",X7,T7*IF($A7>16,01_因子設定!$B$22,1))) -> -1 | G7: =IF($C7=0,0,IF(01_因子設定!$B$20="Box-Behnken",Y7,U7*IF($A7>16,01_因子設定!$B$22,1))) -> -1 | H7: =IF($C7=1,01_因子設定!$G$5+D7*01_因子設定!$H$5,"") -> 55 | I7: =IF($C7=1,01_因子設定!$G$6+E7*01_因子設定!$H$6,"") -> 40 | J7: =IF($C7=1,01_因子設定!$G$7+F7*01_因子設定!$H$7,"") -> 1 | K7: =IF($C7=1,01_因子設定!$G$8+G7*01_因子設定!$H$8,"") -> 20 | L7: =IF(C7=0,"",IF(AND(OR(01_因子設定!$I$5="",H7>=01_因子設定!$I$5),OR(01_因子設定!$J$5="",H7<=01_因子設定!$J$5),OR(01_因子設定!$I$6="",I7>=01_因子設定!$I$6),OR(01_因子設定!$J$6="",I7<=01_因子設定!$J$6),OR(01_因子設定!$I$7="",J7>=01_因子設定!$I$7),OR(01_因子設定!$J$7="",J7<=01_因子設定!$J$7),OR(01_因子設定!$I$8="",K7>=01_因子設定!$I$8),OR(01_因子設定!$J$8="",K7<=01_因子設定!$J$8)),"OK","安全限界超過")) -> OK | M7: 0.635644 | N7: =IF(C7=0,99,IF(AND(01_因子設定!$B$24="変更困難因子でグループ化",01_因子設定!$B$25>0),VLOOKUP(ROUND(INDEX(D7:G7,01_因子設定!$B$25),6),$AA$5:$AB$9,2,FALSE())+M7*0.9,M7)) -> 0.635644 | O7: =IF(C7=1,SUMPRODUCT(($C$5:$C$38=1)*($N$5:$N$38<N7))+1,"") -> 23 | P7: =IF(C7=1,INDEX(03_実験結果!$I$5:$I$38,O7),0) -> 38.7 | R7: -1 | S7: 1 | T7: -1 | U7: -1 | V7: -1 | W7: 1 | X7: 0 | Y7: 0 | AA7: 0 | AB7: 5
A8: 4 | B8: =IF(A8>01_因子設定!$B$23,"未使用",IF(A8>01_因子設定!$B$26,"中心点",IF(01_因子設定!$B$20="Box-Behnken","BBD点",IF(A8<=16,"要因点","軸点")))) -> 要因点 | C8: =IF(A8<=01_因子設定!$B$23,1,0) -> 1 | D8: =IF($C8=0,0,IF(01_因子設定!$B$20="Box-Behnken",V8,R8*IF($A8>16,01_因子設定!$B$22,1))) -> 1 | E8: =IF($C8=0,0,IF(01_因子設定!$B$20="Box-Behnken",W8,S8*IF($A8>16,01_因子設定!$B$22,1))) -> 1 | F8: =IF($C8=0,0,IF(01_因子設定!$B$20="Box-Behnken",X8,T8*IF($A8>16,01_因子設定!$B$22,1))) -> -1 | G8: =IF($C8=0,0,IF(01_因子設定!$B$20="Box-Behnken",Y8,U8*IF($A8>16,01_因子設定!$B$22,1))) -> -1 | H8: =IF($C8=1,01_因子設定!$G$5+D8*01_因子設定!$H$5,"") -> 75 | I8: =IF($C8=1,01_因子設定!$G$6+E8*01_因子設定!$H$6,"") -> 40 | J8: =IF($C8=1,01_因子設定!$G$7+F8*01_因子設定!$H$7,"") -> 1 | K8: =IF($C8=1,01_因子設定!$G$8+G8*01_因子設定!$H$8,"") -> 20 | L8: =IF(C8=0,"",IF(AND(OR(01_因子設定!$I$5="",H8>=01_因子設定!$I$5),OR(01_因子設定!$J$5="",H8<=01_因子設定!$J$5),OR(01_因子設定!$I$6="",I8>=01_因子設定!$I$6),OR(01_因子設定!$J$6="",I8<=01_因子設定!$J$6),OR(01_因子設定!$I$7="",J8>=01_因子設定!$I$7),OR(01_因子設定!$J$7="",J8<=01_因子設定!$J$7),OR(01_因子設定!$I$8="",K8>=01_因子設定!$I$8),OR(01_因子設定!$J$8="",K8<=01_因子設定!$J$8)),"OK","安全限界超過")) -> OK | M8: 0.367067 | N8: =IF(C8=0,99,IF(AND(01_因子設定!$B$24="変更困難因子でグループ化",01_因子設定!$B$25>0),VLOOKUP(ROUND(INDEX(D8:G8,01_因子設定!$B$25),6),$AA$5:$AB$9,2,FALSE())+M8*0.9,M8)) -> 0.367067 | O8: =IF(C8=1,SUMPRODUCT(($C$5:$C$38=1)*($N$5:$N$38<N8))+1,"") -> 17 | P8: =IF(C8=1,INDEX(03_実験結果!$I$5:$I$38,O8),0) -> 46.6 | R8: 1 | S8: 1 | T8: -1 | U8: -1 | V8: 1 | W8: 1 | X8: 0 | Y8: 0 | AA8: 1 | AB8: 2
A9: 5 | B9: =IF(A9>01_因子設定!$B$23,"未使用",IF(A9>01_因子設定!$B$26,"中心点",IF(01_因子設定!$B$20="Box-Behnken","BBD点",IF(A9<=16,"要因点","軸点")))) -> 要因点 | C9: =IF(A9<=01_因子設定!$B$23,1,0) -> 1 | D9: =IF($C9=0,0,IF(01_因子設定!$B$20="Box-Behnken",V9,R9*IF($A9>16,01_因子設定!$B$22,1))) -> -1 | E9: =IF($C9=0,0,IF(01_因子設定!$B$20="Box-Behnken",W9,S9*IF($A9>16,01_因子設定!$B$22,1))) -> -1 | F9: =IF($C9=0,0,IF(01_因子設定!$B$20="Box-Behnken",X9,T9*IF($A9>16,01_因子設定!$B$22,1))) -> 1 | G9: =IF($C9=0,0,IF(01_因子設定!$B$20="Box-Behnken",Y9,U9*IF($A9>16,01_因子設定!$B$22,1))) -> -1 | H9: =IF($C9=1,01_因子設定!$G$5+D9*01_因子設定!$H$5,"") -> 55 | I9: =IF($C9=1,01_因子設定!$G$6+E9*01_因子設定!$H$6,"") -> 20 | J9: =IF($C9=1,01_因子設定!$G$7+F9*01_因子設定!$H$7,"") -> 3 | K9: =IF($C9=1,01_因子設定!$G$8+G9*01_因子設定!$H$8,"") -> 20 | L9: =IF(C9=0,"",IF(AND(OR(01_因子設定!$I$5="",H9>=01_因子設定!$I$5),OR(01_因子設定!$J$5="",H9<=01_因子設定!$J$5),OR(01_因子設定!$I$6="",I9>=01_因子設定!$I$6),OR(01_因子設定!$J$6="",I9<=01_因子設定!$J$6),OR(01_因子設定!$I$7="",J9>=01_因子設定!$I$7),OR(01_因子設定!$J$7="",J9<=01_因子設定!$J$7),OR(01_因子設定!$I$8="",K9>=01_因子設定!$I$8),OR(01_因子設定!$J$8="",K9<=01_因子設定!$J$8)),"OK","安全限界超過")) -> OK | M9: 0.101094 | N9: =IF(C9=0,99,IF(AND(01_因子設定!$B$24="変更困難因子でグループ化",01_因子設定!$B$25>0),VLOOKUP(ROUND(INDEX(D9:G9,01_因子設定!$B$25),6),$AA$5:$AB$9,2,FALSE())+M9*0.9,M9)) -> 0.101094 | O9: =IF(C9=1,SUMPRODUCT(($C$5:$C$38=1)*($N$5:$N$38<N9))+1,"") -> 6 | P9: =IF(C9=1,INDEX(03_実験結果!$I$5:$I$38,O9),0) -> 38.7 | R9: -1 | S9: -1 | T9: 1 | U9: -1 | V9: -1 | W9: 0 | X9: -1 | Y9: 0 | AA9: 2 | AB9: 4
A10: 6 | B10: =IF(A10>01_因子設定!$B$23,"未使用",IF(A10>01_因子設定!$B$26,"中心点",IF(01_因子設定!$B$20="Box-Behnken","BBD点",IF(A10<=16,"要因点","軸点")))) -> 要因点 | C10: =IF(A10<=01_因子設定!$B$23,1,0) -> 1 | D10: =IF($C10=0,0,IF(01_因子設定!$B$20="Box-Behnken",V10,R10*IF($A10>16,01_因子設定!$B$22,1))) -> 1 | E10: =IF($C10=0,0,IF(01_因子設定!$B$20="Box-Behnken",W10,S10*IF($A10>16,01_因子設定!$B$22,1))) -> -1 | F10: =IF($C10=0,0,IF(01_因子設定!$B$20="Box-Behnken",X10,T10*IF($A10>16,01_因子設定!$B$22,1))) -> 1 | G10: =IF($C10=0,0,IF(01_因子設定!$B$20="Box-Behnken",Y10,U10*IF($A10>16,01_因子設定!$B$22,1))) -> -1 | H10: =IF($C10=1,01_因子設定!$G$5+D10*01_因子設定!$H$5,"") -> 75 | I10: =IF($C10=1,01_因子設定!$G$6+E10*01_因子設定!$H$6,"") -> 20 | J10: =IF($C10=1,01_因子設定!$G$7+F10*01_因子設定!$H$7,"") -> 3 | K10: =IF($C10=1,01_因子設定!$G$8+G10*01_因子設定!$H$8,"") -> 20 | L10: =IF(C10=0,"",IF(AND(OR(01_因子設定!$I$5="",H10>=01_因子設定!$I$5),OR(01_因子設定!$J$5="",H10<=01_因子設定!$J$5),OR(01_因子設定!$I$6="",I10>=01_因子設定!$I$6),OR(01_因子設定!$J$6="",I10<=01_因子設定!$J$6),OR(01_因子設定!$I$7="",J10>=01_因子設定!$I$7),OR(01_因子設定!$J$7="",J10<=01_因子設定!$J$7),OR(01_因子設定!$I$8="",K10>=01_因子設定!$I$8),OR(01_因子設定!$J$8="",K10<=01_因子設定!$J$8)),"OK","安全限界超過")) -> OK | M10: 0.090437 | N10: =IF(C10=0,99,IF(AND(01_因子設定!$B$24="変更困難因子でグループ化",01_因子設定!$B$25>0),VLOOKUP(ROUND(INDEX(D10:G10,01_因子設定!$B$25),6),$AA$5:$AB$9,2,FALSE())+M10*0.9,M10)) -> 0.090437 | O10: =IF(C10=1,SUMPRODUCT(($C$5:$C$38=1)*($N$5:$N$38<N10))+1,"") -> 4 | P10: =IF(C10=1,INDEX(03_実験結果!$I$5:$I$38,O10),0) -> 40.1 | R10: 1 | S10: -1 | T10: 1 | U10: -1 | V10: 1 | W10: 0 | X10: -1 | Y10: 0
A11: 7 | B11: =IF(A11>01_因子設定!$B$23,"未使用",IF(A11>01_因子設定!$B$26,"中心点",IF(01_因子設定!$B$20="Box-Behnken","BBD点",IF(A11<=16,"要因点","軸点")))) -> 要因点 | C11: =IF(A11<=01_因子設定!$B$23,1,0) -> 1 | D11: =IF($C11=0,0,IF(01_因子設定!$B$20="Box-Behnken",V11,R11*IF($A11>16,01_因子設定!$B$22,1))) -> -1 | E11: =IF($C11=0,0,IF(01_因子設定!$B$20="Box-Behnken",W11,S11*IF($A11>16,01_因子設定!$B$22,1))) -> 1 | F11: =IF($C11=0,0,IF(01_因子設定!$B$20="Box-Behnken",X11,T11*IF($A11>16,01_因子設定!$B$22,1))) -> 1 | G11: =IF($C11=0,0,IF(01_因子設定!$B$20="Box-Behnken",Y11,U11*IF($A11>16,01_因子設定!$B$22,1))) -> -1 | H11: =IF($C11=1,01_因子設定!$G$5+D11*01_因子設定!$H$5,"") -> 55 | I11: =IF($C11=1,01_因子設定!$G$6+E11*01_因子設定!$H$6,"") -> 40 | J11: =IF($C11=1,01_因子設定!$G$7+F11*01_因子設定!$H$7,"") -> 3 | K11: =IF($C11=1,01_因子設定!$G$8+G11*01_因子設定!$H$8,"") -> 20 | L11: =IF(C11=0,"",IF(AND(OR(01_因子設定!$I$5="",H11>=01_因子設定!$I$5),OR(01_因子設定!$J$5="",H11<=01_因子設定!$J$5),OR(01_因子設定!$I$6="",I11>=01_因子設定!$I$6),OR(01_因子設定!$J$6="",I11<=01_因子設定!$J$6),OR(01_因子設定!$I$7="",J11>=01_因子設定!$I$7),OR(01_因子設定!$J$7="",J11<=01_因子設定!$J$7),OR(01_因子設定!$I$8="",K11>=01_因子設定!$I$8),OR(01_因子設定!$J$8="",K11<=01_因子設定!$J$8)),"OK","安全限界超過")) -> OK | M11: 0.588757 | N11: =IF(C11=0,99,IF(AND(01_因子設定!$B$24="変更困難因子でグループ化",01_因子設定!$B$25>0),VLOOKUP(ROUND(INDEX(D11:G11,01_因子設定!$B$25),6),$AA$5:$AB$9,2,FALSE())+M11*0.9,M11)) -> 0.588757 | O11: =IF(C11=1,SUMPRODUCT(($C$5:$C$38=1)*($N$5:$N$38<N11))+1,"") -> 22 | P11: =IF(C11=1,INDEX(03_実験結果!$I$5:$I$38,O11),0) -> 42.7 | R11: -1 | S11: 1 | T11: 1 | U11: -1 | V11: -1 | W11: 0 | X11: 1 | Y11: 0 | AA11: グループ順位＝変更困難因子の水準を実施する順番（1が最初）。入れ替え可
A12: 8 | B12: =IF(A12>01_因子設定!$B$23,"未使用",IF(A12>01_因子設定!$B$26,"中心点",IF(01_因子設定!$B$20="Box-Behnken","BBD点",IF(A12<=16,"要因点","軸点")))) -> 要因点 | C12: =IF(A12<=01_因子設定!$B$23,1,0) -> 1 | D12: =IF($C12=0,0,IF(01_因子設定!$B$20="Box-Behnken",V12,R12*IF($A12>16,01_因子設定!$B$22,1))) -> 1 | E12: =IF($C12=0,0,IF(01_因子設定!$B$20="Box-Behnken",W12,S12*IF($A12>16,01_因子設定!$B$22,1))) -> 1 | F12: =IF($C12=0,0,IF(01_因子設定!$B$20="Box-Behnken",X12,T12*IF($A12>16,01_因子設定!$B$22,1))) -> 1 | G12: =IF($C12=0,0,IF(01_因子設定!$B$20="Box-Behnken",Y12,U12*IF($A12>16,01_因子設定!$B$22,1))) -> -1 | H12: =IF($C12=1,01_因子設定!$G$5+D12*01_因子設定!$H$5,"") -> 75 | I12: =IF($C12=1,01_因子設定!$G$6+E12*01_因子設定!$H$6,"") -> 40 | J12: =IF($C12=1,01_因子設定!$G$7+F12*01_因子設定!$H$7,"") -> 3 | K12: =IF($C12=1,01_因子設定!$G$8+G12*01_因子設定!$H$8,"") -> 20 | L12: =IF(C12=0,"",IF(AND(OR(01_因子設定!$I$5="",H12>=01_因子設定!$I$5),OR(01_因子設定!$J$5="",H12<=01_因子設定!$J$5),OR(01_因子設定!$I$6="",I12>=01_因子設定!$I$6),OR(01_因子設定!$J$6="",I12<=01_因子設定!$J$6),OR(01_因子設定!$I$7="",J12>=01_因子設定!$I$7),OR(01_因子設定!$J$7="",J12<=01_因子設定!$J$7),OR(01_因子設定!$I$8="",K12>=01_因子設定!$I$8),OR(01_因子設定!$J$8="",K12<=01_因子設定!$J$8)),"OK","安全限界超過")) -> OK | M12: 0.395521 | N12: =IF(C12=0,99,IF(AND(01_因子設定!$B$24="変更困難因子でグループ化",01_因子設定!$B$25>0),VLOOKUP(ROUND(INDEX(D12:G12,01_因子設定!$B$25),6),$AA$5:$AB$9,2,FALSE())+M12*0.9,M12)) -> 0.395521 | O12: =IF(C12=1,SUMPRODUCT(($C$5:$C$38=1)*($N$5:$N$38<N12))+1,"") -> 18 | P12: =IF(C12=1,INDEX(03_実験結果!$I$5:$I$38,O12),0) -> 46.7 | R12: 1 | S12: 1 | T12: 1 | U12: -1 | V12: 1 | W12: 0 | X12: 1 | Y12: 0
A13: 9 | B13: =IF(A13>01_因子設定!$B$23,"未使用",IF(A13>01_因子設定!$B$26,"中心点",IF(01_因子設定!$B$20="Box-Behnken","BBD点",IF(A13<=16,"要因点","軸点")))) -> 要因点 | C13: =IF(A13<=01_因子設定!$B$23,1,0) -> 1 | D13: =IF($C13=0,0,IF(01_因子設定!$B$20="Box-Behnken",V13,R13*IF($A13>16,01_因子設定!$B$22,1))) -> -1 | E13: =IF($C13=0,0,IF(01_因子設定!$B$20="Box-Behnken",W13,S13*IF($A13>16,01_因子設定!$B$22,1))) -> -1 | F13: =IF($C13=0,0,IF(01_因子設定!$B$20="Box-Behnken",X13,T13*IF($A13>16,01_因子設定!$B$22,1))) -> -1 | G13: =IF($C13=0,0,IF(01_因子設定!$B$20="Box-Behnken",Y13,U13*IF($A13>16,01_因子設定!$B$22,1))) -> 1 | H13: =IF($C13=1,01_因子設定!$G$5+D13*01_因子設定!$H$5,"") -> 55 | I13: =IF($C13=1,01_因子設定!$G$6+E13*01_因子設定!$H$6,"") -> 20 | J13: =IF($C13=1,01_因子設定!$G$7+F13*01_因子設定!$H$7,"") -> 1 | K13: =IF($C13=1,01_因子設定!$G$8+G13*01_因子設定!$H$8,"") -> 60 | L13: =IF(C13=0,"",IF(AND(OR(01_因子設定!$I$5="",H13>=01_因子設定!$I$5),OR(01_因子設定!$J$5="",H13<=01_因子設定!$J$5),OR(01_因子設定!$I$6="",I13>=01_因子設定!$I$6),OR(01_因子設定!$J$6="",I13<=01_因子設定!$J$6),OR(01_因子設定!$I$7="",J13>=01_因子設定!$I$7),OR(01_因子設定!$J$7="",J13<=01_因子設定!$J$7),OR(01_因子設定!$I$8="",K13>=01_因子設定!$I$8),OR(01_因子設定!$J$8="",K13<=01_因子設定!$J$8)),"OK","安全限界超過")) -> OK | M13: 0.955168 | N13: =IF(C13=0,99,IF(AND(01_因子設定!$B$24="変更困難因子でグループ化",01_因子設定!$B$25>0),VLOOKUP(ROUND(INDEX(D13:G13,01_因子設定!$B$25),6),$AA$5:$AB$9,2,FALSE())+M13*0.9,M13)) -> 0.955168 | O13: =IF(C13=1,SUMPRODUCT(($C$5:$C$38=1)*($N$5:$N$38<N13))+1,"") -> 29 | P13: =IF(C13=1,INDEX(03_実験結果!$I$5:$I$38,O13),0) -> 37.4 | R13: -1 | S13: -1 | T13: -1 | U13: 1 | V13: -1 | W13: 0 | X13: 0 | Y13: -1
A14: 10 | B14: =IF(A14>01_因子設定!$B$23,"未使用",IF(A14>01_因子設定!$B$26,"中心点",IF(01_因子設定!$B$20="Box-Behnken","BBD点",IF(A14<=16,"要因点","軸点")))) -> 要因点 | C14: =IF(A14<=01_因子設定!$B$23,1,0) -> 1 | D14: =IF($C14=0,0,IF(01_因子設定!$B$20="Box-Behnken",V14,R14*IF($A14>16,01_因子設定!$B$22,1))) -> 1 | E14: =IF($C14=0,0,IF(01_因子設定!$B$20="Box-Behnken",W14,S14*IF($A14>16,01_因子設定!$B$22,1))) -> -1 | F14: =IF($C14=0,0,IF(01_因子設定!$B$20="Box-Behnken",X14,T14*IF($A14>16,01_因子設定!$B$22,1))) -> -1 | G14: =IF($C14=0,0,IF(01_因子設定!$B$20="Box-Behnken",Y14,U14*IF($A14>16,01_因子設定!$B$22,1))) -> 1 | H14: =IF($C14=1,01_因子設定!$G$5+D14*01_因子設定!$H$5,"") -> 75 | I14: =IF($C14=1,01_因子設定!$G$6+E14*01_因子設定!$H$6,"") -> 20 | J14: =IF($C14=1,01_因子設定!$G$7+F14*01_因子設定!$H$7,"") -> 1 | K14: =IF($C14=1,01_因子設定!$G$8+G14*01_因子設定!$H$8,"") -> 60 | L14: =IF(C14=0,"",IF(AND(OR(01_因子設定!$I$5="",H14>=01_因子設定!$I$5),OR(01_因子設定!$J$5="",H14<=01_因子設定!$J$5),OR(01_因子設定!$I$6="",I14>=01_因子設定!$I$6),OR(01_因子設定!$J$6="",I14<=01_因子設定!$J$6),OR(01_因子設定!$I$7="",J14>=01_因子設定!$I$7),OR(01_因子設定!$J$7="",J14<=01_因子設定!$J$7),OR(01_因子設定!$I$8="",K14>=01_因子設定!$I$8),OR(01_因子設定!$J$8="",K14<=01_因子設定!$J$8)),"OK","安全限界超過")) -> OK | M14: 0.232974 | N14: =IF(C14=0,99,IF(AND(01_因子設定!$B$24="変更困難因子でグループ化",01_因子設定!$B$25>0),VLOOKUP(ROUND(INDEX(D14:G14,01_因子設定!$B$25),6),$AA$5:$AB$9,2,FALSE())+M14*0.9,M14)) -> 0.232974 | O14: =IF(C14=1,SUMPRODUCT(($C$5:$C$38=1)*($N$5:$N$38<N14))+1,"") -> 12 | P14: =IF(C14=1,INDEX(03_実験結果!$I$5:$I$38,O14),0) -> 40.7 | R14: 1 | S14: -1 | T14: -1 | U14: 1 | V14: 1 | W14: 0 | X14: 0 | Y14: -1
A15: 11 | B15: =IF(A15>01_因子設定!$B$23,"未使用",IF(A15>01_因子設定!$B$26,"中心点",IF(01_因子設定!$B$20="Box-Behnken","BBD点",IF(A15<=16,"要因点","軸点")))) -> 要因点 | C15: =IF(A15<=01_因子設定!$B$23,1,0) -> 1 | D15: =IF($C15=0,0,IF(01_因子設定!$B$20="Box-Behnken",V15,R15*IF($A15>16,01_因子設定!$B$22,1))) -> -1 | E15: =IF($C15=0,0,IF(01_因子設定!$B$20="Box-Behnken",W15,S15*IF($A15>16,01_因子設定!$B$22,1))) -> 1 | F15: =IF($C15=0,0,IF(01_因子設定!$B$20="Box-Behnken",X15,T15*IF($A15>16,01_因子設定!$B$22,1))) -> -1 | G15: =IF($C15=0,0,IF(01_因子設定!$B$20="Box-Behnken",Y15,U15*IF($A15>16,01_因子設定!$B$22,1))) -> 1 | H15: =IF($C15=1,01_因子設定!$G$5+D15*01_因子設定!$H$5,"") -> 55 | I15: =IF($C15=1,01_因子設定!$G$6+E15*01_因子設定!$H$6,"") -> 40 | J15: =IF($C15=1,01_因子設定!$G$7+F15*01_因子設定!$H$7,"") -> 1 | K15: =IF($C15=1,01_因子設定!$G$8+G15*01_因子設定!$H$8,"") -> 60 | L15: =IF(C15=0,"",IF(AND(OR(01_因子設定!$I$5="",H15>=01_因子設定!$I$5),OR(01_因子設定!$J$5="",H15<=01_因子設定!$J$5),OR(01_因子設定!$I$6="",I15>=01_因子設定!$I$6),OR(01_因子設定!$J$6="",I15<=01_因子設定!$J$6),OR(01_因子設定!$I$7="",J15>=01_因子設定!$I$7),OR(01_因子設定!$J$7="",J15<=01_因子設定!$J$7),OR(01_因子設定!$I$8="",K15>=01_因子設定!$I$8),OR(01_因子設定!$J$8="",K15<=01_因子設定!$J$8)),"OK","安全限界超過")) -> OK | M15: 0.337461 | N15: =IF(C15=0,99,IF(AND(01_因子設定!$B$24="変更困難因子でグループ化",01_因子設定!$B$25>0),VLOOKUP(ROUND(INDEX(D15:G15,01_因子設定!$B$25),6),$AA$5:$AB$9,2,FALSE())+M15*0.9,M15)) -> 0.337461 | O15: =IF(C15=1,SUMPRODUCT(($C$5:$C$38=1)*($N$5:$N$38<N15))+1,"") -> 16 | P15: =IF(C15=1,INDEX(03_実験結果!$I$5:$I$38,O15),0) -> 38.1 | R15: -1 | S15: 1 | T15: -1 | U15: 1 | V15: -1 | W15: 0 | X15: 0 | Y15: 1
A16: 12 | B16: =IF(A16>01_因子設定!$B$23,"未使用",IF(A16>01_因子設定!$B$26,"中心点",IF(01_因子設定!$B$20="Box-Behnken","BBD点",IF(A16<=16,"要因点","軸点")))) -> 要因点 | C16: =IF(A16<=01_因子設定!$B$23,1,0) -> 1 | D16: =IF($C16=0,0,IF(01_因子設定!$B$20="Box-Behnken",V16,R16*IF($A16>16,01_因子設定!$B$22,1))) -> 1 | E16: =IF($C16=0,0,IF(01_因子設定!$B$20="Box-Behnken",W16,S16*IF($A16>16,01_因子設定!$B$22,1))) -> 1 | F16: =IF($C16=0,0,IF(01_因子設定!$B$20="Box-Behnken",X16,T16*IF($A16>16,01_因子設定!$B$22,1))) -> -1 | G16: =IF($C16=0,0,IF(01_因子設定!$B$20="Box-Behnken",Y16,U16*IF($A16>16,01_因子設定!$B$22,1))) -> 1 | H16: =IF($C16=1,01_因子設定!$G$5+D16*01_因子設定!$H$5,"") -> 75 | I16: =IF($C16=1,01_因子設定!$G$6+E16*01_因子設定!$H$6,"") -> 40 | J16: =IF($C16=1,01_因子設定!$G$7+F16*01_因子設定!$H$7,"") -> 1 | K16: =IF($C16=1,01_因子設定!$G$8+G16*01_因子設定!$H$8,"") -> 60 | L16: =IF(C16=0,"",IF(AND(OR(01_因子設定!$I$5="",H16>=01_因子設定!$I$5),OR(01_因子設定!$J$5="",H16<=01_因子設定!$J$5),OR(01_因子設定!$I$6="",I16>=01_因子設定!$I$6),OR(01_因子設定!$J$6="",I16<=01_因子設定!$J$6),OR(01_因子設定!$I$7="",J16>=01_因子設定!$I$7),OR(01_因子設定!$J$7="",J16<=01_因子設定!$J$7),OR(01_因子設定!$I$8="",K16>=01_因子設定!$I$8),OR(01_因子設定!$J$8="",K16<=01_因子設定!$J$8)),"OK","安全限界超過")) -> OK | M16: 0.262412 | N16: =IF(C16=0,99,IF(AND(01_因子設定!$B$24="変更困難因子でグループ化",01_因子設定!$B$25>0),VLOOKUP(ROUND(INDEX(D16:G16,01_因子設定!$B$25),6),$AA$5:$AB$9,2,FALSE())+M16*0.9,M16)) -> 0.262412 | O16: =IF(C16=1,SUMPRODUCT(($C$5:$C$38=1)*($N$5:$N$38<N16))+1,"") -> 14 | P16: =IF(C16=1,INDEX(03_実験結果!$I$5:$I$38,O16),0) -> 46.4 | R16: 1 | S16: 1 | T16: -1 | U16: 1 | V16: 1 | W16: 0 | X16: 0 | Y16: 1
A17: 13 | B17: =IF(A17>01_因子設定!$B$23,"未使用",IF(A17>01_因子設定!$B$26,"中心点",IF(01_因子設定!$B$20="Box-Behnken","BBD点",IF(A17<=16,"要因点","軸点")))) -> 要因点 | C17: =IF(A17<=01_因子設定!$B$23,1,0) -> 1 | D17: =IF($C17=0,0,IF(01_因子設定!$B$20="Box-Behnken",V17,R17*IF($A17>16,01_因子設定!$B$22,1))) -> -1 | E17: =IF($C17=0,0,IF(01_因子設定!$B$20="Box-Behnken",W17,S17*IF($A17>16,01_因子設定!$B$22,1))) -> -1 | F17: =IF($C17=0,0,IF(01_因子設定!$B$20="Box-Behnken",X17,T17*IF($A17>16,01_因子設定!$B$22,1))) -> 1 | G17: =IF($C17=0,0,IF(01_因子設定!$B$20="Box-Behnken",Y17,U17*IF($A17>16,01_因子設定!$B$22,1))) -> 1 | H17: =IF($C17=1,01_因子設定!$G$5+D17*01_因子設定!$H$5,"") -> 55 | I17: =IF($C17=1,01_因子設定!$G$6+E17*01_因子設定!$H$6,"") -> 20 | J17: =IF($C17=1,01_因子設定!$G$7+F17*01_因子設定!$H$7,"") -> 3 | K17: =IF($C17=1,01_因子設定!$G$8+G17*01_因子設定!$H$8,"") -> 60 | L17: =IF(C17=0,"",IF(AND(OR(01_因子設定!$I$5="",H17>=01_因子設定!$I$5),OR(01_因子設定!$J$5="",H17<=01_因子設定!$J$5),OR(01_因子設定!$I$6="",I17>=01_因子設定!$I$6),OR(01_因子設定!$J$6="",I17<=01_因子設定!$J$6),OR(01_因子設定!$I$7="",J17>=01_因子設定!$I$7),OR(01_因子設定!$J$7="",J17<=01_因子設定!$J$7),OR(01_因子設定!$I$8="",K17>=01_因子設定!$I$8),OR(01_因子設定!$J$8="",K17<=01_因子設定!$J$8)),"OK","安全限界超過")) -> OK | M17: 0.180005 | N17: =IF(C17=0,99,IF(AND(01_因子設定!$B$24="変更困難因子でグループ化",01_因子設定!$B$25>0),VLOOKUP(ROUND(INDEX(D17:G17,01_因子設定!$B$25),6),$AA$5:$AB$9,2,FALSE())+M17*0.9,M17)) -> 0.180005 | O17: =IF(C17=1,SUMPRODUCT(($C$5:$C$38=1)*($N$5:$N$38<N17))+1,"") -> 9 | P17: =IF(C17=1,INDEX(03_実験結果!$I$5:$I$38,O17),0) -> 40.7 | R17: -1 | S17: -1 | T17: 1 | U17: 1 | V17: 0 | W17: -1 | X17: -1 | Y17: 0
A18: 14 | B18: =IF(A18>01_因子設定!$B$23,"未使用",IF(A18>01_因子設定!$B$26,"中心点",IF(01_因子設定!$B$20="Box-Behnken","BBD点",IF(A18<=16,"要因点","軸点")))) -> 要因点 | C18: =IF(A18<=01_因子設定!$B$23,1,0) -> 1 | D18: =IF($C18=0,0,IF(01_因子設定!$B$20="Box-Behnken",V18,R18*IF($A18>16,01_因子設定!$B$22,1))) -> 1 | E18: =IF($C18=0,0,IF(01_因子設定!$B$20="Box-Behnken",W18,S18*IF($A18>16,01_因子設定!$B$22,1))) -> -1 | F18: =IF($C18=0,0,IF(01_因子設定!$B$20="Box-Behnken",X18,T18*IF($A18>16,01_因子設定!$B$22,1))) -> 1 | G18: =IF($C18=0,0,IF(01_因子設定!$B$20="Box-Behnken",Y18,U18*IF($A18>16,01_因子設定!$B$22,1))) -> 1 | H18: =IF($C18=1,01_因子設定!$G$5+D18*01_因子設定!$H$5,"") -> 75 | I18: =IF($C18=1,01_因子設定!$G$6+E18*01_因子設定!$H$6,"") -> 20 | J18: =IF($C18=1,01_因子設定!$G$7+F18*01_因子設定!$H$7,"") -> 3 | K18: =IF($C18=1,01_因子設定!$G$8+G18*01_因子設定!$H$8,"") -> 60 | L18: =IF(C18=0,"",IF(AND(OR(01_因子設定!$I$5="",H18>=01_因子設定!$I$5),OR(01_因子設定!$J$5="",H18<=01_因子設定!$J$5),OR(01_因子設定!$I$6="",I18>=01_因子設定!$I$6),OR(01_因子設定!$J$6="",I18<=01_因子設定!$J$6),OR(01_因子設定!$I$7="",J18>=01_因子設定!$I$7),OR(01_因子設定!$J$7="",J18<=01_因子設定!$J$7),OR(01_因子設定!$I$8="",K18>=01_因子設定!$I$8),OR(01_因子設定!$J$8="",K18<=01_因子設定!$J$8)),"OK","安全限界超過")) -> OK | M18: 0.24259 | N18: =IF(C18=0,99,IF(AND(01_因子設定!$B$24="変更困難因子でグループ化",01_因子設定!$B$25>0),VLOOKUP(ROUND(INDEX(D18:G18,01_因子設定!$B$25),6),$AA$5:$AB$9,2,FALSE())+M18*0.9,M18)) -> 0.24259 | O18: =IF(C18=1,SUMPRODUCT(($C$5:$C$38=1)*($N$5:$N$38<N18))+1,"") -> 13 | P18: =IF(C18=1,INDEX(03_実験結果!$I$5:$I$38,O18),0) -> 41.3 | R18: 1 | S18: -1 | T18: 1 | U18: 1 | V18: 0 | W18: 1 | X18: -1 | Y18: 0
A19: 15 | B19: =IF(A19>01_因子設定!$B$23,"未使用",IF(A19>01_因子設定!$B$26,"中心点",IF(01_因子設定!$B$20="Box-Behnken","BBD点",IF(A19<=16,"要因点","軸点")))) -> 要因点 | C19: =IF(A19<=01_因子設定!$B$23,1,0) -> 1 | D19: =IF($C19=0,0,IF(01_因子設定!$B$20="Box-Behnken",V19,R19*IF($A19>16,01_因子設定!$B$22,1))) -> -1 | E19: =IF($C19=0,0,IF(01_因子設定!$B$20="Box-Behnken",W19,S19*IF($A19>16,01_因子設定!$B$22,1))) -> 1 | F19: =IF($C19=0,0,IF(01_因子設定!$B$20="Box-Behnken",X19,T19*IF($A19>16,01_因子設定!$B$22,1))) -> 1 | G19: =IF($C19=0,0,IF(01_因子設定!$B$20="Box-Behnken",Y19,U19*IF($A19>16,01_因子設定!$B$22,1))) -> 1 | H19: =IF($C19=1,01_因子設定!$G$5+D19*01_因子設定!$H$5,"") -> 55 | I19: =IF($C19=1,01_因子設定!$G$6+E19*01_因子設定!$H$6,"") -> 40 | J19: =IF($C19=1,01_因子設定!$G$7+F19*01_因子設定!$H$7,"") -> 3 | K19: =IF($C19=1,01_因子設定!$G$8+G19*01_因子設定!$H$8,"") -> 60 | L19: =IF(C19=0,"",IF(AND(OR(01_因子設定!$I$5="",H19>=01_因子設定!$I$5),OR(01_因子設定!$J$5="",H19<=01_因子設定!$J$5),OR(01_因子設定!$I$6="",I19>=01_因子設定!$I$6),OR(01_因子設定!$J$6="",I19<=01_因子設定!$J$6),OR(01_因子設定!$I$7="",J19>=01_因子設定!$I$7),OR(01_因子設定!$J$7="",J19<=01_因子設定!$J$7),OR(01_因子設定!$I$8="",K19>=01_因子設定!$I$8),OR(01_因子設定!$J$8="",K19<=01_因子設定!$J$8)),"OK","安全限界超過")) -> OK | M19: 0.854317 | N19: =IF(C19=0,99,IF(AND(01_因子設定!$B$24="変更困難因子でグループ化",01_因子設定!$B$25>0),VLOOKUP(ROUND(INDEX(D19:G19,01_因子設定!$B$25),6),$AA$5:$AB$9,2,FALSE())+M19*0.9,M19)) -> 0.854317 | O19: =IF(C19=1,SUMPRODUCT(($C$5:$C$38=1)*($N$5:$N$38<N19))+1,"") -> 26 | P19: =IF(C19=1,INDEX(03_実験結果!$I$5:$I$38,O19),0) -> 43.1 | R19: -1 | S19: 1 | T19: 1 | U19: 1 | V19: 0 | W19: -1 | X19: 1 | Y19: 0
A20: 16 | B20: =IF(A20>01_因子設定!$B$23,"未使用",IF(A20>01_因子設定!$B$26,"中心点",IF(01_因子設定!$B$20="Box-Behnken","BBD点",IF(A20<=16,"要因点","軸点")))) -> 要因点 | C20: =IF(A20<=01_因子設定!$B$23,1,0) -> 1 | D20: =IF($C20=0,0,IF(01_因子設定!$B$20="Box-Behnken",V20,R20*IF($A20>16,01_因子設定!$B$22,1))) -> 1 | E20: =IF($C20=0,0,IF(01_因子設定!$B$20="Box-Behnken",W20,S20*IF($A20>16,01_因子設定!$B$22,1))) -> 1 | F20: =IF($C20=0,0,IF(01_因子設定!$B$20="Box-Behnken",X20,T20*IF($A20>16,01_因子設定!$B$22,1))) -> 1 | G20: =IF($C20=0,0,IF(01_因子設定!$B$20="Box-Behnken",Y20,U20*IF($A20>16,01_因子設定!$B$22,1))) -> 1 | H20: =IF($C20=1,01_因子設定!$G$5+D20*01_因子設定!$H$5,"") -> 75 | I20: =IF($C20=1,01_因子設定!$G$6+E20*01_因子設定!$H$6,"") -> 40 | J20: =IF($C20=1,01_因子設定!$G$7+F20*01_因子設定!$H$7,"") -> 3 | K20: =IF($C20=1,01_因子設定!$G$8+G20*01_因子設定!$H$8,"") -> 60 | L20: =IF(C20=0,"",IF(AND(OR(01_因子設定!$I$5="",H20>=01_因子設定!$I$5),OR(01_因子設定!$J$5="",H20<=01_因子設定!$J$5),OR(01_因子設定!$I$6="",I20>=01_因子設定!$I$6),OR(01_因子設定!$J$6="",I20<=01_因子設定!$J$6),OR(01_因子設定!$I$7="",J20>=01_因子設定!$I$7),OR(01_因子設定!$J$7="",J20<=01_因子設定!$J$7),OR(01_因子設定!$I$8="",K20>=01_因子設定!$I$8),OR(01_因子設定!$J$8="",K20<=01_因子設定!$J$8)),"OK","安全限界超過")) -> OK | M20: 0.962463 | N20: =IF(C20=0,99,IF(AND(01_因子設定!$B$24="変更困難因子でグループ化",01_因子設定!$B$25>0),VLOOKUP(ROUND(INDEX(D20:G20,01_因子設定!$B$25),6),$AA$5:$AB$9,2,FALSE())+M20*0.9,M20)) -> 0.962463 | O20: =IF(C20=1,SUMPRODUCT(($C$5:$C$38=1)*($N$5:$N$38<N20))+1,"") -> 30 | P20: =IF(C20=1,INDEX(03_実験結果!$I$5:$I$38,O20),0) -> 47.9 | R20: 1 | S20: 1 | T20: 1 | U20: 1 | V20: 0 | W20: 1 | X20: 1 | Y20: 0
A21: 17 | B21: =IF(A21>01_因子設定!$B$23,"未使用",IF(A21>01_因子設定!$B$26,"中心点",IF(01_因子設定!$B$20="Box-Behnken","BBD点",IF(A21<=16,"要因点","軸点")))) -> 軸点 | C21: =IF(A21<=01_因子設定!$B$23,1,0) -> 1 | D21: =IF($C21=0,0,IF(01_因子設定!$B$20="Box-Behnken",V21,R21*IF($A21>16,01_因子設定!$B$22,1))) -> -1 | E21: =IF($C21=0,0,IF(01_因子設定!$B$20="Box-Behnken",W21,S21*IF($A21>16,01_因子設定!$B$22,1))) -> 0 | F21: =IF($C21=0,0,IF(01_因子設定!$B$20="Box-Behnken",X21,T21*IF($A21>16,01_因子設定!$B$22,1))) -> 0 | G21: =IF($C21=0,0,IF(01_因子設定!$B$20="Box-Behnken",Y21,U21*IF($A21>16,01_因子設定!$B$22,1))) -> 0 | H21: =IF($C21=1,01_因子設定!$G$5+D21*01_因子設定!$H$5,"") -> 55 | I21: =IF($C21=1,01_因子設定!$G$6+E21*01_因子設定!$H$6,"") -> 30 | J21: =IF($C21=1,01_因子設定!$G$7+F21*01_因子設定!$H$7,"") -> 2 | K21: =IF($C21=1,01_因子設定!$G$8+G21*01_因子設定!$H$8,"") -> 40 | L21: =IF(C21=0,"",IF(AND(OR(01_因子設定!$I$5="",H21>=01_因子設定!$I$5),OR(01_因子設定!$J$5="",H21<=01_因子設定!$J$5),OR(01_因子設定!$I$6="",I21>=01_因子設定!$I$6),OR(01_因子設定!$J$6="",I21<=01_因子設定!$J$6),OR(01_因子設定!$I$7="",J21>=01_因子設定!$I$7),OR(01_因子設定!$J$7="",J21<=01_因子設定!$J$7),OR(01_因子設定!$I$8="",K21>=01_因子設定!$I$8),OR(01_因子設定!$J$8="",K21<=01_因子設定!$J$8)),"OK","安全限界超過")) -> OK | M21: 0.182583 | N21: =IF(C21=0,99,IF(AND(01_因子設定!$B$24="変更困難因子でグループ化",01_因子設定!$B$25>0),VLOOKUP(ROUND(INDEX(D21:G21,01_因子設定!$B$25),6),$AA$5:$AB$9,2,FALSE())+M21*0.9,M21)) -> 0.182583 | O21: =IF(C21=1,SUMPRODUCT(($C$5:$C$38=1)*($N$5:$N$38<N21))+1,"") -> 10 | P21: =IF(C21=1,INDEX(03_実験結果!$I$5:$I$38,O21),0) -> 43.6 | R21: -1 | S21: 0 | T21: 0 | U21: 0 | V21: 0 | W21: -1 | X21: 0 | Y21: -1
A22: 18 | B22: =IF(A22>01_因子設定!$B$23,"未使用",IF(A22>01_因子設定!$B$26,"中心点",IF(01_因子設定!$B$20="Box-Behnken","BBD点",IF(A22<=16,"要因点","軸点")))) -> 軸点 | C22: =IF(A22<=01_因子設定!$B$23,1,0) -> 1 | D22: =IF($C22=0,0,IF(01_因子設定!$B$20="Box-Behnken",V22,R22*IF($A22>16,01_因子設定!$B$22,1))) -> 1 | E22: =IF($C22=0,0,IF(01_因子設定!$B$20="Box-Behnken",W22,S22*IF($A22>16,01_因子設定!$B$22,1))) -> 0 | F22: =IF($C22=0,0,IF(01_因子設定!$B$20="Box-Behnken",X22,T22*IF($A22>16,01_因子設定!$B$22,1))) -> 0 | G22: =IF($C22=0,0,IF(01_因子設定!$B$20="Box-Behnken",Y22,U22*IF($A22>16,01_因子設定!$B$22,1))) -> 0 | H22: =IF($C22=1,01_因子設定!$G$5+D22*01_因子設定!$H$5,"") -> 75 | I22: =IF($C22=1,01_因子設定!$G$6+E22*01_因子設定!$H$6,"") -> 30 | J22: =IF($C22=1,01_因子設定!$G$7+F22*01_因子設定!$H$7,"") -> 2 | K22: =IF($C22=1,01_因子設定!$G$8+G22*01_因子設定!$H$8,"") -> 40 | L22: =IF(C22=0,"",IF(AND(OR(01_因子設定!$I$5="",H22>=01_因子設定!$I$5),OR(01_因子設定!$J$5="",H22<=01_因子設定!$J$5),OR(01_因子設定!$I$6="",I22>=01_因子設定!$I$6),OR(01_因子設定!$J$6="",I22<=01_因子設定!$J$6),OR(01_因子設定!$I$7="",J22>=01_因子設定!$I$7),OR(01_因子設定!$J$7="",J22<=01_因子設定!$J$7),OR(01_因子設定!$I$8="",K22>=01_因子設定!$I$8),OR(01_因子設定!$J$8="",K22<=01_因子設定!$J$8)),"OK","安全限界超過")) -> OK | M22: 0.18503 | N22: =IF(C22=0,99,IF(AND(01_因子設定!$B$24="変更困難因子でグループ化",01_因子設定!$B$25>0),VLOOKUP(ROUND(INDEX(D22:G22,01_因子設定!$B$25),6),$AA$5:$AB$9,2,FALSE())+M22*0.9,M22)) -> 0.18503 | O22: =IF(C22=1,SUMPRODUCT(($C$5:$C$38=1)*($N$5:$N$38<N22))+1,"") -> 11 | P22: =IF(C22=1,INDEX(03_実験結果!$I$5:$I$38,O22),0) -> 47.7 | R22: 1 | S22: 0 | T22: 0 | U22: 0 | V22: 0 | W22: 1 | X22: 0 | Y22: -1
A23: 19 | B23: =IF(A23>01_因子設定!$B$23,"未使用",IF(A23>01_因子設定!$B$26,"中心点",IF(01_因子設定!$B$20="Box-Behnken","BBD点",IF(A23<=16,"要因点","軸点")))) -> 軸点 | C23: =IF(A23<=01_因子設定!$B$23,1,0) -> 1 | D23: =IF($C23=0,0,IF(01_因子設定!$B$20="Box-Behnken",V23,R23*IF($A23>16,01_因子設定!$B$22,1))) -> 0 | E23: =IF($C23=0,0,IF(01_因子設定!$B$20="Box-Behnken",W23,S23*IF($A23>16,01_因子設定!$B$22,1))) -> -1 | F23: =IF($C23=0,0,IF(01_因子設定!$B$20="Box-Behnken",X23,T23*IF($A23>16,01_因子設定!$B$22,1))) -> 0 | G23: =IF($C23=0,0,IF(01_因子設定!$B$20="Box-Behnken",Y23,U23*IF($A23>16,01_因子設定!$B$22,1))) -> 0 | H23: =IF($C23=1,01_因子設定!$G$5+D23*01_因子設定!$H$5,"") -> 65 | I23: =IF($C23=1,01_因子設定!$G$6+E23*01_因子設定!$H$6,"") -> 20 | J23: =IF($C23=1,01_因子設定!$G$7+F23*01_因子設定!$H$7,"") -> 2 | K23: =IF($C23=1,01_因子設定!$G$8+G23*01_因子設定!$H$8,"") -> 40 | L23: =IF(C23=0,"",IF(AND(OR(01_因子設定!$I$5="",H23>=01_因子設定!$I$5),OR(01_因子設定!$J$5="",H23<=01_因子設定!$J$5),OR(01_因子設定!$I$6="",I23>=01_因子設定!$I$6),OR(01_因子設定!$J$6="",I23<=01_因子設定!$J$6),OR(01_因子設定!$I$7="",J23>=01_因子設定!$I$7),OR(01_因子設定!$J$7="",J23<=01_因子設定!$J$7),OR(01_因子設定!$I$8="",K23>=01_因子設定!$I$8),OR(01_因子設定!$J$8="",K23<=01_因子設定!$J$8)),"OK","安全限界超過")) -> OK | M23: 0.492097 | N23: =IF(C23=0,99,IF(AND(01_因子設定!$B$24="変更困難因子でグループ化",01_因子設定!$B$25>0),VLOOKUP(ROUND(INDEX(D23:G23,01_因子設定!$B$25),6),$AA$5:$AB$9,2,FALSE())+M23*0.9,M23)) -> 0.492097 | O23: =IF(C23=1,SUMPRODUCT(($C$5:$C$38=1)*($N$5:$N$38<N23))+1,"") -> 19 | P23: =IF(C23=1,INDEX(03_実験結果!$I$5:$I$38,O23),0) -> 43.9 | R23: 0 | S23: -1 | T23: 0 | U23: 0 | V23: 0 | W23: -1 | X23: 0 | Y23: 1
... A38: 34 | B38: =IF(A38>01_因子設定!$B$23,"未使用",IF(A38>01_因子設定!$B$26,"中心点",IF(01_因子設定!$B$20="Box-Behnken","BBD点",IF(A38<=16,"要因点","軸点")))) -> 未使用 | C38: =IF(A38<=01_因子設定!$B$23,1,0) -> 0 | D38: =IF($C38=0,0,IF(01_因子設定!$B$20="Box-Behnken",V38,R38*IF($A38>16,01_因子設定!$B$22,1))) -> 0 | E38: =IF($C38=0,0,IF(01_因子設定!$B$20="Box-Behnken",W38,S38*IF($A38>16,01_因子設定!$B$22,1))) -> 0 | F38: =IF($C38=0,0,IF(01_因子設定!$B$20="Box-Behnken",X38,T38*IF($A38>16,01_因子設定!$B$22,1))) -> 0 | G38: =IF($C38=0,0,IF(01_因子設定!$B$20="Box-Behnken",Y38,U38*IF($A38>16,01_因子設定!$B$22,1))) -> 0 | H38: =IF($C38=1,01_因子設定!$G$5+D38*01_因子設定!$H$5,"") | I38: =IF($C38=1,01_因子設定!$G$6+E38*01_因子設定!$H$6,"") | J38: =IF($C38=1,01_因子設定!$G$7+F38*01_因子設定!$H$7,"") | K38: =IF($C38=1,01_因子設定!$G$8+G38*01_因子設定!$H$8,"") | L38: =IF(C38=0,"",IF(AND(OR(01_因子設定!$I$5="",H38>=01_因子設定!$I$5),OR(01_因子設定!$J$5="",H38<=01_因子設定!$J$5),OR(01_因子設定!$I$6="",I38>=01_因子設定!$I$6),OR(01_因子設定!$J$6="",I38<=01_因子設定!$J$6),OR(01_因子設定!$I$7="",J38>=01_因子設定!$I$7),OR(01_因子設定!$J$7="",J38<=01_因子設定!$J$7),OR(01_因子設定!$I$8="",K38>=01_因子設定!$I$8),OR(01_因子設定!$J$8="",K38<=01_因子設定!$J$8)),"OK","安全限界超過")) | M38: 0.908461 | N38: =IF(C38=0,99,IF(AND(01_因子設定!$B$24="変更困難因子でグループ化",01_因子設定!$B$25>0),VLOOKUP(ROUND(INDEX(D38:G38,01_因子設定!$B$25),6),$AA$5:$AB$9,2,FALSE())+M38*0.9,M38)) -> 99 | O38: =IF(C38=1,SUMPRODUCT(($C$5:$C$38=1)*($N$5:$N$38<N38))+1,"") | P38: =IF(C38=1,INDEX(03_実験結果!$I$5:$I$38,O38),0) -> 0 | R38: 0 | S38: 0 | T38: 0 | U38: 0 | V38: 0 | W38: 0 | X38: 0 | Y38: 0
R40: 右側のパターン列：CCD／BBDの基本パターン（編集不要）

Sheet 03_実験結果
A1: 03 実験指示書・結果入力（実験順）
A2: この順番で実験し、Yを入力。現在のYは検証用の架空データ。計画を変えたら入れ直してください。
A4: 実験順序 | B4: 標準順 | C4: 区分 | D4: =01_因子設定!B5&"["&01_因子設定!D5&"]" -> 炉温[℃] | E4: =01_因子設定!B6&"["&01_因子設定!D6&"]" -> 乾燥時間[min] | F4: =01_因子設定!B7&"["&01_因子設定!D7&"]" -> 循環風速[m/s] | G4: =01_因子設定!B8&"["&01_因子設定!D8&"]" -> 給気率[%] | H4: 変更困難因子の水準 | I4: ="Y："&01_因子設定!B11&"["&01_因子設定!B12&"]" -> Y：剥離強度[N/25mm] | J4: メモ（異常・気付き）
A5: 1 | B5: =IF(A5<=01_因子設定!$B$23,INDEX(02_実験計画!$A$5:$A$38,MATCH(A5,02_実験計画!$O$5:$O$38,0)),"") -> 30 | C5: =IF(B5="","",INDEX(02_実験計画!$B$5:$B$38,B5)) -> 中心点 | D5: =IF($B5="","",INDEX(02_実験計画!$H$5:$H$38,$B5)) -> 65 | E5: =IF($B5="","",INDEX(02_実験計画!$I$5:$I$38,$B5)) -> 30 | F5: =IF($B5="","",INDEX(02_実験計画!$J$5:$J$38,$B5)) -> 2 | G5: =IF($B5="","",INDEX(02_実験計画!$K$5:$K$38,$B5)) -> 40 | H5: =IF(OR(B5="",01_因子設定!$B$25=0),"",INDEX(D5:G5,01_因子設定!$B$25)) -> 65 | I5: 47.7
A6: 2 | B6: =IF(A6<=01_因子設定!$B$23,INDEX(02_実験計画!$A$5:$A$38,MATCH(A6,02_実験計画!$O$5:$O$38,0)),"") -> 27 | C6: =IF(B6="","",INDEX(02_実験計画!$B$5:$B$38,B6)) -> 中心点 | D6: =IF($B6="","",INDEX(02_実験計画!$H$5:$H$38,$B6)) -> 65 | E6: =IF($B6="","",INDEX(02_実験計画!$I$5:$I$38,$B6)) -> 30 | F6: =IF($B6="","",INDEX(02_実験計画!$J$5:$J$38,$B6)) -> 2 | G6: =IF($B6="","",INDEX(02_実験計画!$K$5:$K$38,$B6)) -> 40 | H6: =IF(OR(B6="",01_因子設定!$B$25=0),"",INDEX(D6:G6,01_因子設定!$B$25)) -> 65 | I6: 47.7
A7: 3 | B7: =IF(A7<=01_因子設定!$B$23,INDEX(02_実験計画!$A$5:$A$38,MATCH(A7,02_実験計画!$O$5:$O$38,0)),"") -> 2 | C7: =IF(B7="","",INDEX(02_実験計画!$B$5:$B$38,B7)) -> 要因点 | D7: =IF($B7="","",INDEX(02_実験計画!$H$5:$H$38,$B7)) -> 75 | E7: =IF($B7="","",INDEX(02_実験計画!$I$5:$I$38,$B7)) -> 20 | F7: =IF($B7="","",INDEX(02_実験計画!$J$5:$J$38,$B7)) -> 1 | G7: =IF($B7="","",INDEX(02_実験計画!$K$5:$K$38,$B7)) -> 20 | H7: =IF(OR(B7="",01_因子設定!$B$25=0),"",INDEX(D7:G7,01_因子設定!$B$25)) -> 75 | I7: 39.4
A8: 4 | B8: =IF(A8<=01_因子設定!$B$23,INDEX(02_実験計画!$A$5:$A$38,MATCH(A8,02_実験計画!$O$5:$O$38,0)),"") -> 6 | C8: =IF(B8="","",INDEX(02_実験計画!$B$5:$B$38,B8)) -> 要因点 | D8: =IF($B8="","",INDEX(02_実験計画!$H$5:$H$38,$B8)) -> 75 | E8: =IF($B8="","",INDEX(02_実験計画!$I$5:$I$38,$B8)) -> 20 | F8: =IF($B8="","",INDEX(02_実験計画!$J$5:$J$38,$B8)) -> 3 | G8: =IF($B8="","",INDEX(02_実験計画!$K$5:$K$38,$B8)) -> 20 | H8: =IF(OR(B8="",01_因子設定!$B$25=0),"",INDEX(D8:G8,01_因子設定!$B$25)) -> 75 | I8: 40.1
A9: 5 | B9: =IF(A9<=01_因子設定!$B$23,INDEX(02_実験計画!$A$5:$A$38,MATCH(A9,02_実験計画!$O$5:$O$38,0)),"") -> 1 | C9: =IF(B9="","",INDEX(02_実験計画!$B$5:$B$38,B9)) -> 要因点 | D9: =IF($B9="","",INDEX(02_実験計画!$H$5:$H$38,$B9)) -> 55 | E9: =IF($B9="","",INDEX(02_実験計画!$I$5:$I$38,$B9)) -> 20 | F9: =IF($B9="","",INDEX(02_実験計画!$J$5:$J$38,$B9)) -> 1 | G9: =IF($B9="","",INDEX(02_実験計画!$K$5:$K$38,$B9)) -> 20 | H9: =IF(OR(B9="",01_因子設定!$B$25=0),"",INDEX(D9:G9,01_因子設定!$B$25)) -> 55 | I9: 37.7
A10: 6 | B10: =IF(A10<=01_因子設定!$B$23,INDEX(02_実験計画!$A$5:$A$38,MATCH(A10,02_実験計画!$O$5:$O$38,0)),"") -> 5 | C10: =IF(B10="","",INDEX(02_実験計画!$B$5:$B$38,B10)) -> 要因点 | D10: =IF($B10="","",INDEX(02_実験計画!$H$5:$H$38,$B10)) -> 55 | E10: =IF($B10="","",INDEX(02_実験計画!$I$5:$I$38,$B10)) -> 20 | F10: =IF($B10="","",INDEX(02_実験計画!$J$5:$J$38,$B10)) -> 3 | G10: =IF($B10="","",INDEX(02_実験計画!$K$5:$K$38,$B10)) -> 20 | H10: =IF(OR(B10="",01_因子設定!$B$25=0),"",INDEX(D10:G10,01_因子設定!$B$25)) -> 55 | I10: 38.7
A11: 7 | B11: =IF(A11<=01_因子設定!$B$23,INDEX(02_実験計画!$A$5:$A$38,MATCH(A11,02_実験計画!$O$5:$O$38,0)),"") -> 23 | C11: =IF(B11="","",INDEX(02_実験計画!$B$5:$B$38,B11)) -> 軸点 | D11: =IF($B11="","",INDEX(02_実験計画!$H$5:$H$38,$B11)) -> 65 | E11: =IF($B11="","",INDEX(02_実験計画!$I$5:$I$38,$B11)) -> 30 | F11: =IF($B11="","",INDEX(02_実験計画!$J$5:$J$38,$B11)) -> 2 | G11: =IF($B11="","",INDEX(02_実験計画!$K$5:$K$38,$B11)) -> 20 | H11: =IF(OR(B11="",01_因子設定!$B$25=0),"",INDEX(D11:G11,01_因子設定!$B$25)) -> 65 | I11: 46.7
A12: 8 | B12: =IF(A12<=01_因子設定!$B$23,INDEX(02_実験計画!$A$5:$A$38,MATCH(A12,02_実験計画!$O$5:$O$38,0)),"") -> 22 | C12: =IF(B12="","",INDEX(02_実験計画!$B$5:$B$38,B12)) -> 軸点 | D12: =IF($B12="","",INDEX(02_実験計画!$H$5:$H$38,$B12)) -> 65 | E12: =IF($B12="","",INDEX(02_実験計画!$I$5:$I$38,$B12)) -> 30 | F12: =IF($B12="","",INDEX(02_実験計画!$J$5:$J$38,$B12)) -> 3 | G12: =IF($B12="","",INDEX(02_実験計画!$K$5:$K$38,$B12)) -> 40 | H12: =IF(OR(B12="",01_因子設定!$B$25=0),"",INDEX(D12:G12,01_因子設定!$B$25)) -> 65 | I12: 48.3
A13: 9 | B13: =IF(A13<=01_因子設定!$B$23,INDEX(02_実験計画!$A$5:$A$38,MATCH(A13,02_実験計画!$O$5:$O$38,0)),"") -> 13 | C13: =IF(B13="","",INDEX(02_実験計画!$B$5:$B$38,B13)) -> 要因点 | D13: =IF($B13="","",INDEX(02_実験計画!$H$5:$H$38,$B13)) -> 55 | E13: =IF($B13="","",INDEX(02_実験計画!$I$5:$I$38,$B13)) -> 20 | F13: =IF($B13="","",INDEX(02_実験計画!$J$5:$J$38,$B13)) -> 3 | G13: =IF($B13="","",INDEX(02_実験計画!$K$5:$K$38,$B13)) -> 60 | H13: =IF(OR(B13="",01_因子設定!$B$25=0),"",INDEX(D13:G13,01_因子設定!$B$25)) -> 55 | I13: 40.7
A14: 10 | B14: =IF(A14<=01_因子設定!$B$23,INDEX(02_実験計画!$A$5:$A$38,MATCH(A14,02_実験計画!$O$5:$O$38,0)),"") -> 17 | C14: =IF(B14="","",INDEX(02_実験計画!$B$5:$B$38,B14)) -> 軸点 | D14: =IF($B14="","",INDEX(02_実験計画!$H$5:$H$38,$B14)) -> 55 | E14: =IF($B14="","",INDEX(02_実験計画!$I$5:$I$38,$B14)) -> 30 | F14: =IF($B14="","",INDEX(02_実験計画!$J$5:$J$38,$B14)) -> 2 | G14: =IF($B14="","",INDEX(02_実験計画!$K$5:$K$38,$B14)) -> 40 | H14: =IF(OR(B14="",01_因子設定!$B$25=0),"",INDEX(D14:G14,01_因子設定!$B$25)) -> 55 | I14: 43.6
A15: 11 | B15: =IF(A15<=01_因子設定!$B$23,INDEX(02_実験計画!$A$5:$A$38,MATCH(A15,02_実験計画!$O$5:$O$38,0)),"") -> 18 | C15: =IF(B15="","",INDEX(02_実験計画!$B$5:$B$38,B15)) -> 軸点 | D15: =IF($B15="","",INDEX(02_実験計画!$H$5:$H$38,$B15)) -> 75 | E15: =IF($B15="","",INDEX(02_実験計画!$I$5:$I$38,$B15)) -> 30 | F15: =IF($B15="","",INDEX(02_実験計画!$J$5:$J$38,$B15)) -> 2 | G15: =IF($B15="","",INDEX(02_実験計画!$K$5:$K$38,$B15)) -> 40 | H15: =IF(OR(B15="",01_因子設定!$B$25=0),"",INDEX(D15:G15,01_因子設定!$B$25)) -> 75 | I15: 47.7
A16: 12 | B16: =IF(A16<=01_因子設定!$B$23,INDEX(02_実験計画!$A$5:$A$38,MATCH(A16,02_実験計画!$O$5:$O$38,0)),"") -> 10 | C16: =IF(B16="","",INDEX(02_実験計画!$B$5:$B$38,B16)) -> 要因点 | D16: =IF($B16="","",INDEX(02_実験計画!$H$5:$H$38,$B16)) -> 75 | E16: =IF($B16="","",INDEX(02_実験計画!$I$5:$I$38,$B16)) -> 20 | F16: =IF($B16="","",INDEX(02_実験計画!$J$5:$J$38,$B16)) -> 1 | G16: =IF($B16="","",INDEX(02_実験計画!$K$5:$K$38,$B16)) -> 60 | H16: =IF(OR(B16="",01_因子設定!$B$25=0),"",INDEX(D16:G16,01_因子設定!$B$25)) -> 75 | I16: 40.7
... A34: 30 | B34: =IF(A34<=01_因子設定!$B$23,INDEX(02_実験計画!$A$5:$A$38,MATCH(A34,02_実験計画!$O$5:$O$38,0)),"") -> 16 | C34: =IF(B34="","",INDEX(02_実験計画!$B$5:$B$38,B34)) -> 要因点 | D34: =IF($B34="","",INDEX(02_実験計画!$H$5:$H$38,$B34)) -> 75 | E34: =IF($B34="","",INDEX(02_実験計画!$I$5:$I$38,$B34)) -> 40 | F34: =IF($B34="","",INDEX(02_実験計画!$J$5:$J$38,$B34)) -> 3 | G34: =IF($B34="","",INDEX(02_実験計画!$K$5:$K$38,$B34)) -> 60 | H34: =IF(OR(B34="",01_因子設定!$B$25=0),"",INDEX(D34:G34,01_因子設定!$B$25)) -> 75 | I34: 47.9
A35: 31 | B35: =IF(A35<=01_因子設定!$B$23,INDEX(02_実験計画!$A$5:$A$38,MATCH(A35,02_実験計画!$O$5:$O$38,0)),"") | C35: =IF(B35="","",INDEX(02_実験計画!$B$5:$B$38,B35)) | D35: =IF($B35="","",INDEX(02_実験計画!$H$5:$H$38,$B35)) | E35: =IF($B35="","",INDEX(02_実験計画!$I$5:$I$38,$B35)) | F35: =IF($B35="","",INDEX(02_実験計画!$J$5:$J$38,$B35)) | G35: =IF($B35="","",INDEX(02_実験計画!$K$5:$K$38,$B35)) | H35: =IF(OR(B35="",01_因子設定!$B$25=0),"",INDEX(D35:G35,01_因子設定!$B$25))
A36: 32 | B36: =IF(A36<=01_因子設定!$B$23,INDEX(02_実験計画!$A$5:$A$38,MATCH(A36,02_実験計画!$O$5:$O$38,0)),"") | C36: =IF(B36="","",INDEX(02_実験計画!$B$5:$B$38,B36)) | D36: =IF($B36="","",INDEX(02_実験計画!$H$5:$H$38,$B36)) | E36: =IF($B36="","",INDEX(02_実験計画!$I$5:$I$38,$B36)) | F36: =IF($B36="","",INDEX(02_実験計画!$J$5:$J$38,$B36)) | G36: =IF($B36="","",INDEX(02_実験計画!$K$5:$K$38,$B36)) | H36: =IF(OR(B36="",01_因子設定!$B$25=0),"",INDEX(D36:G36,01_因子設定!$B$25))
A37: 33 | B37: =IF(A37<=01_因子設定!$B$23,INDEX(02_実験計画!$A$5:$A$38,MATCH(A37,02_実験計画!$O$5:$O$38,0)),"") | C37: =IF(B37="","",INDEX(02_実験計画!$B$5:$B$38,B37)) | D37: =IF($B37="","",INDEX(02_実験計画!$H$5:$H$38,$B37)) | E37: =IF($B37="","",INDEX(02_実験計画!$I$5:$I$38,$B37)) | F37: =IF($B37="","",INDEX(02_実験計画!$J$5:$J$38,$B37)) | G37: =IF($B37="","",INDEX(02_実験計画!$K$5:$K$38,$B37)) | H37: =IF(OR(B37="",01_因子設定!$B$25=0),"",INDEX(D37:G37,01_因子設定!$B$25))
A38: 34 | B38: =IF(A38<=01_因子設定!$B$23,INDEX(02_実験計画!$A$5:$A$38,MATCH(A38,02_実験計画!$O$5:$O$38,0)),"") | C38: =IF(B38="","",INDEX(02_実験計画!$B$5:$B$38,B38)) | D38: =IF($B38="","",INDEX(02_実験計画!$H$5:$H$38,$B38)) | E38: =IF($B38="","",INDEX(02_実験計画!$I$5:$I$38,$B38)) | F38: =IF($B38="","",INDEX(02_実験計画!$J$5:$J$38,$B38)) | G38: =IF($B38="","",INDEX(02_実験計画!$K$5:$K$38,$B38)) | H38: =IF(OR(B38="",01_因子設定!$B$25=0),"",INDEX(D38:G38,01_因子設定!$B$25))

Sheet 04_回帰ANOVA
A1: 04 2次回帰モデルとANOVA（コード化単位）
A2: B列を0にすると、その項を除外して再計算（モデル縮小）。切片は常に1。
A5: 項 | B5: 使用(1/0) | C5: 係数 | D5: 標準誤差 | E5: t値 | F5: p値 | G5: 有意 | H5: 階層性チェック | J5: 統計量 | K5: 値
A6: 切片 | B6: 1 | C6: =IF(B6=1,_XtX!R60,0) -> 47.907895 | D6: =IF(B6=1,SQRT($K$13*INDEX(_XtX!$B$78:$P$92,1,1)),"") -> 0.23096593 | E6: =IF(B6=1,C6/D6,"") -> 207.42408 | F6: =IF(B6=1,TDIST(ABS(E6),$K$8,2),"") -> 2.3625981e-27 | G6: =IF(F6="","",IF(F6<0.01,"**",IF(F6<0.05,"*",IF(F6<0.1,"△","")))) -> ** | J6: n（実験数） | K6: =SUM(_XtX!A5:A38) -> 30
A7: X1 | B7: 1 | C7: =IF(B7=1,_XtX!R61,0) -> 2.0055556 | D7: =IF(B7=1,SQRT($K$13*INDEX(_XtX!$B$78:$P$92,2,2)),"") -> 0.17525392 | E7: =IF(B7=1,C7/D7,"") -> 11.443713 | F7: =IF(B7=1,TDIST(ABS(E7),$K$8,2),"") -> 8.2468452e-09 | G7: =IF(F7="","",IF(F7<0.01,"**",IF(F7<0.05,"*",IF(F7<0.1,"△","")))) -> ** | J7: p（項数） | K7: =SUM($B$6:$B$20) -> 15
A8: X2 | B8: 1 | C8: =IF(B8=1,_XtX!R62,0) -> 2.0944444 | D8: =IF(B8=1,SQRT($K$13*INDEX(_XtX!$B$78:$P$92,3,3)),"") -> 0.17525392 | E8: =IF(B8=1,C8/D8,"") -> 11.950913 | F8: =IF(B8=1,TDIST(ABS(E8),$K$8,2),"") -> 4.5717192e-09 | G8: =IF(F8="","",IF(F8<0.01,"**",IF(F8<0.05,"*",IF(F8<0.1,"△","")))) -> ** | J8: 残差自由度 | K8: =K6-K7 -> 15
A9: X3 | B9: 1 | C9: =IF(B9=1,_XtX!R63,0) -> 0.98333333 | D9: =IF(B9=1,SQRT($K$13*INDEX(_XtX!$B$78:$P$92,4,4)),"") -> 0.17525392 | E9: =IF(B9=1,C9/D9,"") -> 5.6109062 | F9: =IF(B9=1,TDIST(ABS(E9),$K$8,2),"") -> 4.963678e-05 | G9: =IF(F9="","",IF(F9<0.01,"**",IF(F9<0.05,"*",IF(F9<0.1,"△","")))) -> ** | J9: SSE | K9: =SUMSQ(_XtX!U5:U38) -> 8.2927632
A10: X4 | B10: 1 | C10: =IF(B10=1,_XtX!R64,0) -> 0.40555556 | D10: =IF(B10=1,SQRT($K$13*INDEX(_XtX!$B$78:$P$92,5,5)),"") -> 0.17525392 | E10: =IF(B10=1,C10/D10,"") -> 2.3141026 | F10: =IF(B10=1,TDIST(ABS(E10),$K$8,2),"") -> 0.035249461 | G10: =IF(F10="","",IF(F10<0.01,"**",IF(F10<0.05,"*",IF(F10<0.1,"△","")))) -> * | J10: Yの平均 | K10: =SUMPRODUCT(_XtX!Q5:Q38,_XtX!A5:A38)/K6 -> 44.17
A11: X1·X2 | B11: 1 | C11: =IF(B11=1,_XtX!R65,0) -> 1.125 | D11: =IF(B11=1,SQRT($K$13*INDEX(_XtX!$B$78:$P$92,6,6)),"") -> 0.18588486 | E11: =IF(B11=1,C11/D11,"") -> 6.0521337 | F11: =IF(B11=1,TDIST(ABS(E11),$K$8,2),"") -> 2.21444e-05 | G11: =IF(F11="","",IF(F11<0.01,"**",IF(F11<0.05,"*",IF(F11<0.1,"△","")))) -> ** | H11: =IF(AND(B11=1,OR($B$7=0,$B$8=0)),"主効果が除外されています","") | J11: SST | K11: =SUMPRODUCT(_XtX!A5:A38,(_XtX!Q5:Q38-K10)^2) -> 440.603
A12: X1·X3 | B12: 1 | C12: =IF(B12=1,_XtX!R66,0) -> -0.65 | D12: =IF(B12=1,SQRT($K$13*INDEX(_XtX!$B$78:$P$92,7,7)),"") -> 0.18588486 | E12: =IF(B12=1,C12/D12,"") -> -3.4967883 | F12: =IF(B12=1,TDIST(ABS(E12),$K$8,2),"") -> 0.0032448451 | G12: =IF(F12="","",IF(F12<0.01,"**",IF(F12<0.05,"*",IF(F12<0.1,"△","")))) -> ** | H12: =IF(AND(B12=1,OR($B$7=0,$B$9=0)),"主効果が除外されています","") | J12: SSR | K12: =K11-K9 -> 432.31024
A13: X1·X4 | B13: 1 | C13: =IF(B13=1,_XtX!R67,0) -> 0.125 | D13: =IF(B13=1,SQRT($K$13*INDEX(_XtX!$B$78:$P$92,8,8)),"") -> 0.18588486 | E13: =IF(B13=1,C13/D13,"") -> 0.6724593 | F13: =IF(B13=1,TDIST(ABS(E13),$K$8,2),"") -> 0.51151794 | G13: =IF(F13="","",IF(F13<0.01,"**",IF(F13<0.05,"*",IF(F13<0.1,"△","")))) | H13: =IF(AND(B13=1,OR($B$7=0,$B$10=0)),"主効果が除外されています","") | J13: MSE | K13: =K9/K8 -> 0.55285088
A14: X2·X3 | B14: 1 | C14: =IF(B14=1,_XtX!R68,0) -> 0.3125 | D14: =IF(B14=1,SQRT($K$13*INDEX(_XtX!$B$78:$P$92,9,9)),"") -> 0.18588486 | E14: =IF(B14=1,C14/D14,"") -> 1.6811482 | F14: =IF(B14=1,TDIST(ABS(E14),$K$8,2),"") -> 0.11343168 | G14: =IF(F14="","",IF(F14<0.01,"**",IF(F14<0.05,"*",IF(F14<0.1,"△","")))) | H14: =IF(AND(B14=1,OR($B$8=0,$B$9=0)),"主効果が除外されています","") | J14: s（残差標準偏差） | K14: =SQRT(K13) -> 0.74353943
A15: X2·X4 | B15: 1 | C15: =IF(B15=1,_XtX!R69,0) -> -0.2125 | D15: =IF(B15=1,SQRT($K$13*INDEX(_XtX!$B$78:$P$92,10,10)),"") -> 0.18588486 | E15: =IF(B15=1,C15/D15,"") -> -1.1431808 | F15: =IF(B15=1,TDIST(ABS(E15),$K$8,2),"") -> 0.2708815 | G15: =IF(F15="","",IF(F15<0.01,"**",IF(F15<0.05,"*",IF(F15<0.1,"△","")))) | H15: =IF(AND(B15=1,OR($B$8=0,$B$10=0)),"主効果が除外されています","") | J15: R² | K15: =1-K9/K11 -> 0.9811786
A16: X3·X4 | B16: 1 | C16: =IF(B16=1,_XtX!R70,0) -> 0.2875 | D16: =IF(B16=1,SQRT($K$13*INDEX(_XtX!$B$78:$P$92,11,11)),"") -> 0.18588486 | E16: =IF(B16=1,C16/D16,"") -> 1.5466564 | F16: =IF(B16=1,TDIST(ABS(E16),$K$8,2),"") -> 0.14278127 | G16: =IF(F16="","",IF(F16<0.01,"**",IF(F16<0.05,"*",IF(F16<0.1,"△","")))) | H16: =IF(AND(B16=1,OR($B$9=0,$B$10=0)),"主効果が除外されています","") | J16: 調整済みR² | K16: =1-(K9/K8)/(K11/(K6-1)) -> 0.96361197
A17: X1² | B17: 1 | C17: =IF(B17=1,_XtX!R71,0) -> -2.5824561 | D17: =IF(B17=1,SQRT($K$13*INDEX(_XtX!$B$78:$P$92,12,12)),"") -> 0.46193186 | E17: =IF(B17=1,C17/D17,"") -> -5.5905565 | F17: =IF(B17=1,TDIST(ABS(E17),$K$8,2),"") -> 5.15522e-05 | G17: =IF(F17="","",IF(F17<0.01,"**",IF(F17<0.05,"*",IF(F17<0.1,"△","")))) -> ** | H17: =IF(AND(B17=1,OR($B$7=0)),"主効果が除外されています","") | J17: PRESS | K17: =SUMPRODUCT(_XtX!A5:A38,(_XtX!U5:U38/(1-_XtX!S5:S38))^2) -> 31.999986
A18: X2² | B18: 1 | C18: =IF(B18=1,_XtX!R72,0) -> -2.5824561 | D18: =IF(B18=1,SQRT($K$13*INDEX(_XtX!$B$78:$P$92,13,13)),"") -> 0.46193186 | E18: =IF(B18=1,C18/D18,"") -> -5.5905565 | F18: =IF(B18=1,TDIST(ABS(E18),$K$8,2),"") -> 5.15522e-05 | G18: =IF(F18="","",IF(F18<0.01,"**",IF(F18<0.05,"*",IF(F18<0.1,"△","")))) -> ** | H18: =IF(AND(B18=1,OR($B$8=0)),"主効果が除外されています","") | J18: 予測R² | K18: =1-K17/K11 -> 0.92737229
A19: X3² | B19: 1 | C19: =IF(B19=1,_XtX!R73,0) -> -0.68245614 | D19: =IF(B19=1,SQRT($K$13*INDEX(_XtX!$B$78:$P$92,14,14)),"") -> 0.46193186 | E19: =IF(B19=1,C19/D19,"") -> -1.4773957 | F19: =IF(B19=1,TDIST(ABS(E19),$K$8,2),"") -> 0.16025695 | G19: =IF(F19="","",IF(F19<0.01,"**",IF(F19<0.05,"*",IF(F19<0.1,"△","")))) | H19: =IF(AND(B19=1,OR($B$9=0)),"主効果が除外されています","") | J19: t値（工程窓・最適化用） | K19: =IF(01_因子設定!$B$13="目標値",TINV(1-01_因子設定!B17,K8),TINV(2*(1-01_因子設定!B17),K8)) -> 1.7530504
A20: X4² | B20: 1 | C20: =IF(B20=1,_XtX!R74,0) -> -0.38245614 | D20: =IF(B20=1,SQRT($K$13*INDEX(_XtX!$B$78:$P$92,15,15)),"") -> 0.46193186 | E20: =IF(B20=1,C20/D20,"") -> -0.82794926 | F20: =IF(B20=1,TDIST(ABS(E20),$K$8,2),"") -> 0.42067752 | G20: =IF(F20="","",IF(F20<0.01,"**",IF(F20<0.05,"*",IF(F20<0.1,"△","")))) | H20: =IF(AND(B20=1,OR($B$10=0)),"主効果が除外されています","") | J20: Y未入力数 | K20: =SUMPRODUCT((03_実験結果!$A$5:$A$38<=01_因子設定!$B$23)*(03_実験結果!$I$5:$I$38="")) -> 0
J21: 中心点の数 | K21: =COUNTIF(02_実験計画!B5:B38,"中心点") -> 6
A22: 有意：** p<0.01 * p<0.05 △ p<0.1。p値だけで機械的に削らず、技術的な意味と階層性を優先。 | J22: 中心点Yの平均 | K22: =IFERROR(AVERAGEIF(02_実験計画!B5:B38,"中心点",02_実験計画!$P$5:$P$38),0) -> 47.583333
J23: t値（両側・確認実験用） | K23: =TINV(1-01_因子設定!B17,K8) -> 2.1314495
J24: 工程窓用t：最大化・最小化＝片側（信頼水準95%なら t0.95）、目標値＝両側（t0.975）
A25: 要因 | B25: 自由度 | C25: 平方和 | D25: 平均平方 | E25: F値 | F25: p値 | G25: 判定
A26: 回帰 | B26: =K7-1 -> 14 | C26: =K12 -> 432.31024 | D26: =C26/B26 -> 30.879303 | E26: =D26/D27 -> 55.854669 | F26: =FDIST(E26,B26,B27) -> 2.3725649e-10 | G26: =IF(F26<0.05,"有意","有意でない") -> 有意
A27: 残差 | B27: =K8 -> 15 | C27: =K9 -> 8.2927632 | D27: =K13 -> 0.55285088
A28: 適合度の欠如 | B28: =B27-B29 -> 10 | C28: =C27-C29 -> 5.1044298 | D28: =IF(B28>0,C28/B28,"") -> 0.51044298 | E28: =IF(AND(B28>0,B29>0),D28/D29,"") -> 0.8004856 | F28: =IF(E28="","",FDIST(E28,B28,B29)) -> 0.64361875 | G28: =IF(F28="","検定不可",IF(F28<0.05,"有意（不適合）","有意でない（適合）")) -> 有意でない（適合）
A29: 純誤差 | B29: =MAX(K21-1,0) -> 5 | C29: =SUMPRODUCT((02_実験計画!$B$5:$B$38="中心点")*(02_実験計画!$P$5:$P$38-K22)^2) -> 3.1883333 | D29: =IF(B29>0,C29/B29,"") -> 0.63766667
A30: 合計 | B30: =K6-1 -> 29 | C30: =K11 -> 440.603
A33: 判断ゲート
A34: 計画の安全性 | B34: =IF(LEFT(01_因子設定!$B$33,1)="×","× 計画が安全限界を超過（01参照）→ 計画を変更してから実験する","○ 全実験点が安全限界内") -> ○ 全実験点が安全限界内
A35: ランダマイズ | B35: =IF(01_因子設定!$B$24="変更困難因子でグループ化",IF(01_因子設定!$B$25>0,"△ 分割区画の順序で実施。この解析は完全ランダムとみなした近似で、変更困難因子のp値は小さく（有意に）出やすい → 正式にはJMP/R等で分割区画解析","△ グループ化を選んでいるが変更困難因子に○がない（完全ランダムとして生成）"),IF(01_因子設定!$B$25>0,"△ 変更困難因子に○があるが完全ランダムで生成。現場で実施できるか確認（できなければグループ化＋正式解析はJMP/R等）","○ 完全ランダム")) -> △ 変更困難因子に○があるが完全ランダムで生成。現場で実施できるか確認（できなければグループ化＋正式解析はJMP/R等）
A36: データ | B36: =IF(K20>0,"× Yが"&K20&"件未入力 → 結果は無効","○ 全件入力済") -> ○ 全件入力済
A37: 回帰の有意性 | B37: =IF(F26<0.05,"○ 回帰は有意","× 有意でない → 因子・範囲の見直し。最適化に進まない") -> ○ 回帰は有意
A38: 適合度の欠如 | B38: =IF(F28="","－ 純誤差がないため検定不可（中心点を増やす）",IF(F28<0.05,"× 2次モデルで説明しきれない → 変換・領域縮小・因子追加を検討","○ 2次モデルで説明できている")) -> ○ 2次モデルで説明できている
A39: R²と予測R² | B39: =IF(K15-K18>0.2,"△ 差が0.2超 → 過学習の可能性。不要項の除外を検討","○ 差は0.2以内") -> ○ 差は0.2以内
A40: 残差 | B40: ="05_残差診断のグラフで、パターン・外れ値がないことを目視確認" -> 05_残差診断のグラフで、パターン・外れ値がないことを目視確認
A42: ×がなく、△の内容を理解・記録してから 06（正準解析）→07（最適化）→08（工程窓）へ進みます。

Sheet 05_残差診断
A1: 05 残差診断
A2: スチューデント化残差の絶対値が3超は要確認（測定ミス・異常の可能性）。消す前に原因を調べる。
A4: 標準順 | B4: 実験順 | C4: 使用 | D4: Y実測 | E4: 予測 | F4: 残差 | G4: 標準化残差 | H4: てこ比h | I4: スチューデント化残差 | J4: 判定 | L4: k | M4: 採用k | N4: 標準順 | O4: 予測 | P4: 残差 | Q4: 実験順 | R4: 残差(昇順) | S4: 理論分位点 | T4: 実測
A5: 1 | B5: =02_実験計画!O5 -> 5 | C5: =02_実験計画!C5 -> 1 | D5: =IF(C5=1,_XtX!Q5,"") -> 37.7 | E5: =IF(C5=1,_XtX!T5,"") -> 37.176681 | F5: =IF(C5=1,D5-E5,"") -> 0.52331871 | G5: =IF(C5=1,F5/04_回帰ANOVA!$K$14,"") -> 0.70382107 | H5: =IF(C5=1,_XtX!S5,"") -> 0.65862573 | I5: =IF(C5=1,IF(H5<0.9999,F5/(04_回帰ANOVA!$K$14*SQRT(1-H5)),0),"") -> 1.2046111 | J5: =IF(C5=1,IF(ABS(I5)>3,"要確認",IF(ABS(I5)>2,"注意","")),"") | L5: 1 | M5: =MIN(L5,04_回帰ANOVA!$K$6) -> 1 | N5: =MATCH(M5,$B$5:$B$38,0) -> 30 | O5: =INDEX($E$5:$E$38,N5) -> 47.907895 | P5: =INDEX($F$5:$F$38,N5) -> -0.20789474 | Q5: =M5 -> 1 | R5: =SMALL($F$5:$F$38,M5) -> -1.5078947 | S5: =NORMSINV((M5-0.375)/(04_回帰ANOVA!$K$6+0.25)) -> -2.0402813 | T5: =INDEX($D$5:$D$38,N5) -> 47.7
A6: 2 | B6: =02_実験計画!O6 -> 3 | C6: =02_実験計画!C6 -> 1 | D6: =IF(C6=1,_XtX!Q6,"") -> 39.4 | E6: =IF(C6=1,_XtX!T6,"") -> 39.987792 | F6: =IF(C6=1,D6-E6,"") -> -0.5877924 | G6: =IF(C6=1,F6/04_回帰ANOVA!$K$14,"") -> -0.79053293 | H6: =IF(C6=1,_XtX!S6,"") -> 0.65862573 | I6: =IF(C6=1,IF(H6<0.9999,F6/(04_回帰ANOVA!$K$14*SQRT(1-H6)),0),"") -> -1.3530211 | J6: =IF(C6=1,IF(ABS(I6)>3,"要確認",IF(ABS(I6)>2,"注意","")),"") | L6: 2 | M6: =MIN(L6,04_回帰ANOVA!$K$6) -> 2 | N6: =MATCH(M6,$B$5:$B$38,0) -> 27 | O6: =INDEX($E$5:$E$38,N6) -> 47.907895 | P6: =INDEX($F$5:$F$38,N6) -> -0.20789474 | Q6: =M6 -> 2 | R6: =SMALL($F$5:$F$38,M6) -> -0.90789474 | S6: =NORMSINV((M6-0.375)/(04_回帰ANOVA!$K$6+0.25)) -> -1.6098161 | T6: =INDEX($D$5:$D$38,N6) -> 47.7
A7: 3 | B7: =02_実験計画!O7 -> 23 | C7: =02_実験計画!C7 -> 1 | D7: =IF(C7=1,_XtX!Q7,"") -> 38.7 | E7: =IF(C7=1,_XtX!T7,"") -> 38.91557 | F7: =IF(C7=1,D7-E7,"") -> -0.21557018 | G7: =IF(C7=1,F7/04_回帰ANOVA!$K$14,"") -> -0.28992434 | H7: =IF(C7=1,_XtX!S7,"") -> 0.65862573 | I7: =IF(C7=1,IF(H7<0.9999,F7/(04_回帰ANOVA!$K$14*SQRT(1-H7)),0),"") -> -0.49621431 | J7: =IF(C7=1,IF(ABS(I7)>3,"要確認",IF(ABS(I7)>2,"注意","")),"") | L7: 3 | M7: =MIN(L7,04_回帰ANOVA!$K$6) -> 3 | N7: =MATCH(M7,$B$5:$B$38,0) -> 2 | O7: =INDEX($E$5:$E$38,N7) -> 39.987792 | P7: =INDEX($F$5:$F$38,N7) -> -0.5877924 | Q7: =M7 -> 3 | R7: =SMALL($F$5:$F$38,M7) -> -0.5877924 | S7: =NORMSINV((M7-0.375)/(04_回帰ANOVA!$K$6+0.25)) -> -1.3608733 | T7: =INDEX($D$5:$D$38,N7) -> 39.4
A8: 4 | B8: =02_実験計画!O8 -> 17 | C8: =02_実験計画!C8 -> 1 | D8: =IF(C8=1,_XtX!Q8,"") -> 46.6 | E8: =IF(C8=1,_XtX!T8,"") -> 46.226681 | F8: =IF(C8=1,D8-E8,"") -> 0.37331871 | G8: =IF(C8=1,F8/04_回帰ANOVA!$K$14,"") -> 0.50208328 | H8: =IF(C8=1,_XtX!S8,"") -> 0.65862573 | I8: =IF(C8=1,IF(H8<0.9999,F8/(04_回帰ANOVA!$K$14*SQRT(1-H8)),0),"") -> 0.85933078 | J8: =IF(C8=1,IF(ABS(I8)>3,"要確認",IF(ABS(I8)>2,"注意","")),"") | L8: 4 | M8: =MIN(L8,04_回帰ANOVA!$K$6) -> 4 | N8: =MATCH(M8,$B$5:$B$38,0) -> 6 | O8: =INDEX($E$5:$E$38,N8) -> 39.454459 | P8: =INDEX($F$5:$F$38,N8) -> 0.64554094 | Q8: =M8 -> 4 | R8: =SMALL($F$5:$F$38,M8) -> -0.54334795 | S8: =NORMSINV((M8-0.375)/(04_回帰ANOVA!$K$6+0.25)) -> -1.1758135 | T8: =INDEX($D$5:$D$38,N8) -> 40.1
A9: 5 | B9: =02_実験計画!O9 -> 6 | C9: =02_実験計画!C9 -> 1 | D9: =IF(C9=1,_XtX!Q9,"") -> 38.7 | E9: =IF(C9=1,_XtX!T9,"") -> 39.243348 | F9: =IF(C9=1,D9-E9,"") -> -0.54334795 | G9: =IF(C9=1,F9/04_回帰ANOVA!$K$14,"") -> -0.73075877 | H9: =IF(C9=1,_XtX!S9,"") -> 0.65862573 | I9: =IF(C9=1,IF(H9<0.9999,F9/(04_回帰ANOVA!$K$14*SQRT(1-H9)),0),"") -> -1.2507158 | J9: =IF(C9=1,IF(ABS(I9)>3,"要確認",IF(ABS(I9)>2,"注意","")),"") | L9: 5 | M9: =MIN(L9,04_回帰ANOVA!$K$6) -> 5 | N9: =MATCH(M9,$B$5:$B$38,0) -> 1 | O9: =INDEX($E$5:$E$38,N9) -> 37.176681 | P9: =INDEX($F$5:$F$38,N9) -> 0.52331871 | Q9: =M9 -> 5 | R9: =SMALL($F$5:$F$38,M9) -> -0.41988304 | S9: =NORMSINV((M9-0.375)/(04_回帰ANOVA!$K$6+0.25)) -> -1.0241062 | T9: =INDEX($D$5:$D$38,N9) -> 37.7
A10: 6 | B10: =02_実験計画!O10 -> 4 | C10: =02_実験計画!C10 -> 1 | D10: =IF(C10=1,_XtX!Q10,"") -> 40.1 | E10: =IF(C10=1,_XtX!T10,"") -> 39.454459 | F10: =IF(C10=1,D10-E10,"") -> 0.64554094 | G10: =IF(C10=1,F10/04_回帰ANOVA!$K$14,"") -> 0.86820001 | H10: =IF(C10=1,_XtX!S10,"") -> 0.65862573 | I10: =IF(C10=1,IF(H10<0.9999,F10/(04_回帰ANOVA!$K$14*SQRT(1-H10)),0),"") -> 1.4859507 | J10: =IF(C10=1,IF(ABS(I10)>3,"要確認",IF(ABS(I10)>2,"注意","")),"") | L10: 6 | M10: =MIN(L10,04_回帰ANOVA!$K$6) -> 6 | N10: =MATCH(M10,$B$5:$B$38,0) -> 5 | O10: =INDEX($E$5:$E$38,N10) -> 39.243348 | P10: =INDEX($F$5:$F$38,N10) -> -0.54334795 | Q10: =M10 -> 6 | R10: =SMALL($F$5:$F$38,M10) -> -0.37668129 | S10: =NORMSINV((M10-0.375)/(04_回帰ANOVA!$K$6+0.25)) -> -0.89291849 | T10: =INDEX($D$5:$D$38,N10) -> 38.7
A11: 7 | B11: =02_実験計画!O11 -> 22 | C11: =02_実験計画!C11 -> 1 | D11: =IF(C11=1,_XtX!Q11,"") -> 42.7 | E11: =IF(C11=1,_XtX!T11,"") -> 42.232237 | F11: =IF(C11=1,D11-E11,"") -> 0.46776316 | G11: =IF(C11=1,F11/04_回帰ANOVA!$K$14,"") -> 0.62910337 | H11: =IF(C11=1,_XtX!S11,"") -> 0.65862573 | I11: =IF(C11=1,IF(H11<0.9999,F11/(04_回帰ANOVA!$K$14*SQRT(1-H11)),0),"") -> 1.0767295 | J11: =IF(C11=1,IF(ABS(I11)>3,"要確認",IF(ABS(I11)>2,"注意","")),"") | L11: 7 | M11: =MIN(L11,04_回帰ANOVA!$K$6) -> 7 | N11: =MATCH(M11,$B$5:$B$38,0) -> 23 | O11: =INDEX($E$5:$E$38,N11) -> 47.119883 | P11: =INDEX($F$5:$F$38,N11) -> -0.41988304 | Q11: =M11 -> 7 | R11: =SMALL($F$5:$F$38,M11) -> -0.25445906 | S11: =NORMSINV((M11-0.375)/(04_回帰ANOVA!$K$6+0.25)) -> -0.77554696 | T11: =INDEX($D$5:$D$38,N11) -> 46.7
A12: 8 | B12: =02_実験計画!O12 -> 18 | C12: =02_実験計画!C12 -> 1 | D12: =IF(C12=1,_XtX!Q12,"") -> 46.7 | E12: =IF(C12=1,_XtX!T12,"") -> 46.943348 | F12: =IF(C12=1,D12-E12,"") -> -0.24334795 | G12: =IF(C12=1,F12/04_回帰ANOVA!$K$14,"") -> -0.32728319 | H12: =IF(C12=1,_XtX!S12,"") -> 0.65862573 | I12: =IF(C12=1,IF(H12<0.9999,F12/(04_回帰ANOVA!$K$14*SQRT(1-H12)),0),"") -> -0.56015511 | J12: =IF(C12=1,IF(ABS(I12)>3,"要確認",IF(ABS(I12)>2,"注意","")),"") | L12: 8 | M12: =MIN(L12,04_回帰ANOVA!$K$6) -> 8 | N12: =MATCH(M12,$B$5:$B$38,0) -> 22 | O12: =INDEX($E$5:$E$38,N12) -> 48.208772 | P12: =INDEX($F$5:$F$38,N12) -> 0.09122807 | Q12: =M12 -> 8 | R12: =SMALL($F$5:$F$38,M12) -> -0.24334795 | S12: =NORMSINV((M12-0.375)/(04_回帰ANOVA!$K$6+0.25)) -> -0.66800213 | T12: =INDEX($D$5:$D$38,N12) -> 48.3
A13: 9 | B13: =02_実験計画!O13 -> 29 | C13: =02_実験計画!C13 -> 1 | D13: =IF(C13=1,_XtX!Q13,"") -> 37.4 | E13: =IF(C13=1,_XtX!T13,"") -> 37.587792 | F13: =IF(C13=1,D13-E13,"") -> -0.1877924 | G13: =IF(C13=1,F13/04_回帰ANOVA!$K$14,"") -> -0.25256549 | H13: =IF(C13=1,_XtX!S13,"") -> 0.65862573 | I13: =IF(C13=1,IF(H13<0.9999,F13/(04_回帰ANOVA!$K$14*SQRT(1-H13)),0),"") -> -0.4322735 | J13: =IF(C13=1,IF(ABS(I13)>3,"要確認",IF(ABS(I13)>2,"注意","")),"") | L13: 9 | M13: =MIN(L13,04_回帰ANOVA!$K$6) -> 9 | N13: =MATCH(M13,$B$5:$B$38,0) -> 13 | O13: =INDEX($E$5:$E$38,N13) -> 40.804459 | P13: =INDEX($F$5:$F$38,N13) -> -0.10445906 | Q13: =M13 -> 9 | R13: =SMALL($F$5:$F$38,M13) -> -0.21557018 | S13: =NORMSINV((M13-0.375)/(04_回帰ANOVA!$K$6+0.25)) -> -0.56768639 | T13: =INDEX($D$5:$D$38,N13) -> 40.7
