Workbook

Sheet 00_使い方
A1: 応答曲面法（RSM）ツール v1.1 ── 3因子・2次モデル
A2: 作成日 2026-09-30 ／ 同梱データは架空の乾燥炉データ（検証用） ／ 2因子版・3因子版・4因子版は別ファイル
A4: この版でできること
B5: 3因子の中心複合計画（面心／回転可能）・Box-Behnken計画の生成、安全限界チェック、ランダマイズ（完全ランダム／変更困難因子でグループ化した順序生成）、2次回帰・ANOVA・適合度の欠如・残差診断・モデル縮小、正準解析（停留点・固有値）、領域内の最適化（点予測／予測限界ベース）、工程窓の可視化と組合せチェック、確認実験の判定
A6: 手順と判断ゲート
A7: ① 01_因子設定 | B7: 因子名・単位・範囲（±1）・安全限界、Yの方向と規格、計画の種類、中心点数を入力。『安全限界チェック』が×の計画は実行不可。
A8: ② 02_実験計画 | B8: 標準順の計画と実験順序を確認（通常は触らない）。順序を変えたいときは乱数キーを入れ替え。
A9: ③ 03_実験結果 | B9: 実験順に実施し、Yを入力。異常があればメモ欄へ。
A10: ④ 04_回帰ANOVA | B10: 判断ゲートに×がないことを確認し、△は内容を理解して記録。不要項はB列を0にして除外（階層性に注意）。
A11: ⑤ 05_残差診断 | B11: グラフでパターン・外れ値を目視確認。外れ値は消す前に原因を調査。
A12: ⑥ 06_正準解析 | B12: 停留点が最大／最小／鞍点か、領域内か外かを確認。鞍点・領域外なら07の探索結果を採用。
A13: ⑦ 07_最適化 | B13: ロバスト最適（規格側の予測限界と規格の差が最大）を推奨条件とする。必要ならSolverで精密化。
A14: ⑧ 08_工程窓 | B14: 2因子断面の緑領域が工程窓。③の1因子窓は楽観的なので、④で運用範囲の全組合せを必ず確認。
A15: ⑨ 09_確認実験 | B15: 推奨条件で確認実験。両側予測区間内なら採用、外れたら計画・モデルを見直す。
A16: セルの色
A17: 黄色・青字 | B17: 入力セル。ほかは計算式なので編集しない。
A18: 『_』で始まるシート | B18: 計算用（編集不要）。_XtX＝回帰の行列計算、_grid＝4913点の探索、_eig＝固有値、_slice＝断面、_win＝工程窓。
A19: 前提と限界（重要）
A20: コード化単位 | B20: 回帰係数は −1〜+1 に正規化した単位。係数の大小がそのまま効果の大きさ比較になる。
A21: 予測限界の片側／両側 | B21: 工程窓・ロバスト最適は、最大化・最小化では片側の予測限界（信頼水準95%なら下側95%限界＝t0.95）、目標値では両側予測区間（t0.975）で判定。確認実験の判定は常に両側予測区間。
A22: 予測区間と許容区間 | B22: 予測区間が保証するのは『将来の1回の測定値』。量産で『ロットの大部分（例：99%）が規格内』と言うには許容区間（Tolerance Interval）が本来の指標で、予測区間より広くなる。この工程窓は量産の工程能力保証ではなく、条件設定の目安として使う。量産移行時は工程能力調査（Cpk）で確認。
A23: 探索範囲 | B23: 最適化・工程窓は ±1（要因点の範囲）内のみ。外挿はしない。BBDは頂点付近にデータがないため半径√2の球内に限定。
A24: 分割区画（Split-Plot） | B24: v1は分割区画の解析に対応していない。『変更困難因子でグループ化』は実験順序を作るだけで、解析は完全ランダムとみなした近似（変更困難因子のp値は小さく出やすい）。04の判断ゲートに△を表示。正式な解析はJMP・R（lme4等）で。
A25: 固有値 | B25: Jacobi法の数値計算（24回転）。3×3行列では十分収束する。
A26: この版にないもの | B26: スクリーニング（Plackett-Burman）・曲率判定・最急上昇法（v2予定）、多目的最適化（望ましさ関数）・モンテカルロ・分割区画の正式解析（v3予定）。
A27: 動作環境 | B27: Excel 2019以降または Microsoft 365（1因子窓で MAXIFS/MINIFS を使用）。マクロなし。
A28: 架空データについて | B28: 炉温55〜75℃・乾燥時間20〜40min・循環風速1〜3m/s、Y＝剥離強度（最大化、LSL=48.5）。数値はツール検証用の作り物。安全上限（炉温80℃等）も仮値なので、実案件では必ず再設定。

Sheet 01_因子設定
A1: 01 因子と目的変数の設定（3因子）
A2: 黄色セル（青字）が入力欄。架空の乾燥炉データ（接着剤塗布後の溶剤乾燥・バッチ式）を例として入れてあります。
A4: No | B4: 因子名 | C4: 記号 | D4: 単位 | E4: 下限(-1) | F4: 上限(+1) | G4: 中心(0) | H4: 半幅 | I4: 安全下限 | J4: 安全上限 | K4: 変更困難 | L4: 安全下限(コード) | M4: 安全上限(コード) | N4: 備考
A5: 1 | B5: 炉温 | C5: X1 | D5: ℃ | E5: 55 | F5: 75 | G5: =(E5+F5)/2 -> 65 | H5: =(F5-E5)/2 -> 10 | J5: 80 | K5: ○ | L5: =IF(I5="",-99,(I5-G5)/H5) -> -99 | M5: =IF(J5="",99,(J5-G5)/H5) -> 1.5 | N5: 安全上限80℃は仮値。溶剤の引火点・防爆の温度等級から必ず再設定
A6: 2 | B6: 乾燥時間 | C6: X2 | D6: min | E6: 20 | F6: 40 | G6: =(E6+F6)/2 -> 30 | H6: =(F6-E6)/2 -> 10 | I6: 10 | L6: =IF(I6="",-99,(I6-G6)/H6) -> -2 | M6: =IF(J6="",99,(J6-G6)/H6) -> 99
A7: 3 | B7: 循環風速 | C7: X3 | D7: m/s | E7: 1 | F7: 3 | G7: =(E7+F7)/2 -> 2 | H7: =(F7-E7)/2 -> 1 | I7: 0.5 | J7: 4 | L7: =IF(I7="",-99,(I7-G7)/H7) -> -1.5 | M7: =IF(J7="",99,(J7-G7)/H7) -> 2 | N7: ファン能力の範囲
A10: 目的変数（Y）
A11: 名称 | B11: 剥離強度
A12: 単位 | B12: N/25mm
A13: 最適化の方向 | B13: 最大化 | C13: 最大化→LSLのみ使用 / 最小化→USLのみ / 目標値→LSL・USL・T を使用
A14: 下限規格 LSL | B14: 48.5
A15: 上限規格 USL
A16: 目標値 T
A17: 予測区間の信頼水準 | B17: 0.95 | C17: 最大化・最小化は片側の予測限界（例：95%なら下側95%限界）、目標値は両側の予測区間で工程窓を判定
A19: 実験計画
A20: 計画の種類 | B20: 面心CCD(α=1) | C20: 3因子: CCD=要因8+軸6+中心、BBD=12+中心。BBDは全因子同時の極端条件（立方体の頂点）を含まない
A21: 中心点の数 | B21: 6 | C21: 純誤差（適合度の欠如の検定）に使うため3以上。推奨5〜6
A22: α（軸点距離） | B22: =IF(B20="回転可能CCD(α=1.682)",1.68179283050743,1) -> 1
A23: 総実験数 N | B23: =B26+B21 -> 20
A24: ランダマイズ方式 | B24: 完全ランダム | C24: グループ化＝変更困難因子の水準ごとに実験をまとめる順序生成のみ。解析は分割区画に対応していない（04に警告表示）
A25: 変更困難因子 No | B25: =IFERROR(MATCH("○",K5:K7,0),0) -> 1
A26: 計画点数（中心点除く） | B26: =IF(B20="Box-Behnken",12,14) -> 14
A27: 安全限界チェック（計画上の最小・最大の実値）
A28: 因子 | B28: 計画の最小 | C28: 計画の最大 | D28: 安全下限 | E28: 安全上限 | F28: 判定
A29: =B5 -> 炉温 | B29: =G5-$B$22*H5 -> 55 | C29: =G5+$B$22*H5 -> 75 | D29: =IF(I5="","―",I5) -> ― | E29: =IF(J5="","―",J5) -> 80 | F29: =IF(AND(OR(I5="",B29>=I5),OR(J5="",C29<=J5)),"OK","安全限界超過") -> OK
A30: =B6 -> 乾燥時間 | B30: =G6-$B$22*H6 -> 20 | C30: =G6+$B$22*H6 -> 40 | D30: =IF(I6="","―",I6) -> 10 | E30: =IF(J6="","―",J6) -> ― | F30: =IF(AND(OR(I6="",B30>=I6),OR(J6="",C30<=J6)),"OK","安全限界超過") -> OK
A31: =B7 -> 循環風速 | B31: =G7-$B$22*H7 -> 1 | C31: =G7+$B$22*H7 -> 3 | D31: =IF(I7="","―",I7) -> 0.5 | E31: =IF(J7="","―",J7) -> 4 | F31: =IF(AND(OR(I7="",B31>=I7),OR(J7="",C31<=J7)),"OK","安全限界超過") -> OK
A32: 総合判定 | B32: =IF(COUNTIF(F29:F31,"安全限界超過")>0,"× 安全限界を超える実験点あり → この計画は実行不可。面心CCDかBox-Behnkenへ変更、または範囲を縮小","○ 全実験点が安全限界内") -> ○ 全実験点が安全限界内

Sheet 02_実験計画
A1: 02 実験計画（標準順）とランダマイズ
A2: 計画の種類・中心点数は01で選択。乱数キーを入れ替えると実験順序が変わります（=RAND()を入れ→コピー→値貼り付け）。
A4: 標準順 | B4: 区分 | C4: 使用 | D4: X1(コード) | E4: X2(コード) | F4: X3(コード) | G4: ="X1 "&01_因子設定!B5&"["&01_因子設定!D5&"]" -> X1 炉温[℃] | H4: ="X2 "&01_因子設定!B6&"["&01_因子設定!D6&"]" -> X2 乾燥時間[min] | I4: ="X3 "&01_因子設定!B7&"["&01_因子設定!D7&"]" -> X3 循環風速[m/s] | J4: 安全判定 | K4: 乱数キー | L4: 並べ替えキー | M4: 実験順序 | N4: Y（03から） | P4: CCD1 | Q4: CCD2 | R4: CCD3 | S4: BBD1 | T4: BBD2 | U4: BBD3 | W4: 水準(コード) | X4: グループ順位
A5: 1 | B5: =IF(A5>01_因子設定!$B$23,"未使用",IF(A5>01_因子設定!$B$26,"中心点",IF(01_因子設定!$B$20="Box-Behnken","BBD点",IF(A5<=8,"要因点","軸点")))) -> 要因点 | C5: =IF(A5<=01_因子設定!$B$23,1,0) -> 1 | D5: =IF($C5=0,0,IF(01_因子設定!$B$20="Box-Behnken",S5,P5*IF($A5>8,01_因子設定!$B$22,1))) -> -1 | E5: =IF($C5=0,0,IF(01_因子設定!$B$20="Box-Behnken",T5,Q5*IF($A5>8,01_因子設定!$B$22,1))) -> -1 | F5: =IF($C5=0,0,IF(01_因子設定!$B$20="Box-Behnken",U5,R5*IF($A5>8,01_因子設定!$B$22,1))) -> -1 | G5: =IF($C5=1,01_因子設定!$G$5+D5*01_因子設定!$H$5,"") -> 55 | H5: =IF($C5=1,01_因子設定!$G$6+E5*01_因子設定!$H$6,"") -> 20 | I5: =IF($C5=1,01_因子設定!$G$7+F5*01_因子設定!$H$7,"") -> 1 | J5: =IF(C5=0,"",IF(AND(OR(01_因子設定!$I$5="",G5>=01_因子設定!$I$5),OR(01_因子設定!$J$5="",G5<=01_因子設定!$J$5),OR(01_因子設定!$I$6="",H5>=01_因子設定!$I$6),OR(01_因子設定!$J$6="",H5<=01_因子設定!$J$6),OR(01_因子設定!$I$7="",I5>=01_因子設定!$I$7),OR(01_因子設定!$J$7="",I5<=01_因子設定!$J$7)),"OK","安全限界超過")) -> OK | K5: 0.085744 | L5: =IF(C5=0,99,IF(AND(01_因子設定!$B$24="変更困難因子でグループ化",01_因子設定!$B$25>0),VLOOKUP(ROUND(INDEX(D5:F5,01_因子設定!$B$25),6),$W$5:$X$9,2,FALSE())+K5*0.9,K5)) -> 0.085744 | M5: =IF(C5=1,SUMPRODUCT(($C$5:$C$28=1)*($L$5:$L$28<L5))+1,"") -> 3 | N5: =IF(C5=1,INDEX(03_実験結果!$H$5:$H$28,M5),0) -> 38.4 | P5: -1 | Q5: -1 | R5: -1 | S5: -1 | T5: -1 | U5: 0 | W5: -1.681793 | X5: 3
A6: 2 | B6: =IF(A6>01_因子設定!$B$23,"未使用",IF(A6>01_因子設定!$B$26,"中心点",IF(01_因子設定!$B$20="Box-Behnken","BBD点",IF(A6<=8,"要因点","軸点")))) -> 要因点 | C6: =IF(A6<=01_因子設定!$B$23,1,0) -> 1 | D6: =IF($C6=0,0,IF(01_因子設定!$B$20="Box-Behnken",S6,P6*IF($A6>8,01_因子設定!$B$22,1))) -> 1 | E6: =IF($C6=0,0,IF(01_因子設定!$B$20="Box-Behnken",T6,Q6*IF($A6>8,01_因子設定!$B$22,1))) -> -1 | F6: =IF($C6=0,0,IF(01_因子設定!$B$20="Box-Behnken",U6,R6*IF($A6>8,01_因子設定!$B$22,1))) -> -1 | G6: =IF($C6=1,01_因子設定!$G$5+D6*01_因子設定!$H$5,"") -> 75 | H6: =IF($C6=1,01_因子設定!$G$6+E6*01_因子設定!$H$6,"") -> 20 | I6: =IF($C6=1,01_因子設定!$G$7+F6*01_因子設定!$H$7,"") -> 1 | J6: =IF(C6=0,"",IF(AND(OR(01_因子設定!$I$5="",G6>=01_因子設定!$I$5),OR(01_因子設定!$J$5="",G6<=01_因子設定!$J$5),OR(01_因子設定!$I$6="",H6>=01_因子設定!$I$6),OR(01_因子設定!$J$6="",H6<=01_因子設定!$J$6),OR(01_因子設定!$I$7="",I6>=01_因子設定!$I$7),OR(01_因子設定!$J$7="",I6<=01_因子設定!$J$7)),"OK","安全限界超過")) -> OK | K6: 0.317704 | L6: =IF(C6=0,99,IF(AND(01_因子設定!$B$24="変更困難因子でグループ化",01_因子設定!$B$25>0),VLOOKUP(ROUND(INDEX(D6:F6,01_因子設定!$B$25),6),$W$5:$X$9,2,FALSE())+K6*0.9,K6)) -> 0.317704 | M6: =IF(C6=1,SUMPRODUCT(($C$5:$C$28=1)*($L$5:$L$28<L6))+1,"") -> 5 | N6: =IF(C6=1,INDEX(03_実験結果!$H$5:$H$28,M6),0) -> 41.2 | P6: 1 | Q6: -1 | R6: -1 | S6: 1 | T6: -1 | U6: 0 | W6: -1 | X6: 1
A7: 3 | B7: =IF(A7>01_因子設定!$B$23,"未使用",IF(A7>01_因子設定!$B$26,"中心点",IF(01_因子設定!$B$20="Box-Behnken","BBD点",IF(A7<=8,"要因点","軸点")))) -> 要因点 | C7: =IF(A7<=01_因子設定!$B$23,1,0) -> 1 | D7: =IF($C7=0,0,IF(01_因子設定!$B$20="Box-Behnken",S7,P7*IF($A7>8,01_因子設定!$B$22,1))) -> -1 | E7: =IF($C7=0,0,IF(01_因子設定!$B$20="Box-Behnken",T7,Q7*IF($A7>8,01_因子設定!$B$22,1))) -> 1 | F7: =IF($C7=0,0,IF(01_因子設定!$B$20="Box-Behnken",U7,R7*IF($A7>8,01_因子設定!$B$22,1))) -> -1 | G7: =IF($C7=1,01_因子設定!$G$5+D7*01_因子設定!$H$5,"") -> 55 | H7: =IF($C7=1,01_因子設定!$G$6+E7*01_因子設定!$H$6,"") -> 40 | I7: =IF($C7=1,01_因子設定!$G$7+F7*01_因子設定!$H$7,"") -> 1 | J7: =IF(C7=0,"",IF(AND(OR(01_因子設定!$I$5="",G7>=01_因子設定!$I$5),OR(01_因子設定!$J$5="",G7<=01_因子設定!$J$5),OR(01_因子設定!$I$6="",H7>=01_因子設定!$I$6),OR(01_因子設定!$J$6="",H7<=01_因子設定!$J$6),OR(01_因子設定!$I$7="",I7>=01_因子設定!$I$7),OR(01_因子設定!$J$7="",I7<=01_因子設定!$J$7)),"OK","安全限界超過")) -> OK | K7: 0.345364 | L7: =IF(C7=0,99,IF(AND(01_因子設定!$B$24="変更困難因子でグループ化",01_因子設定!$B$25>0),VLOOKUP(ROUND(INDEX(D7:F7,01_因子設定!$B$25),6),$W$5:$X$9,2,FALSE())+K7*0.9,K7)) -> 0.345364 | M7: =IF(C7=1,SUMPRODUCT(($C$5:$C$28=1)*($L$5:$L$28<L7))+1,"") -> 7 | N7: =IF(C7=1,INDEX(03_実験結果!$H$5:$H$28,M7),0) -> 38.6 | P7: -1 | Q7: 1 | R7: -1 | S7: -1 | T7: 1 | U7: 0 | W7: 0 | X7: 5
A8: 4 | B8: =IF(A8>01_因子設定!$B$23,"未使用",IF(A8>01_因子設定!$B$26,"中心点",IF(01_因子設定!$B$20="Box-Behnken","BBD点",IF(A8<=8,"要因点","軸点")))) -> 要因点 | C8: =IF(A8<=01_因子設定!$B$23,1,0) -> 1 | D8: =IF($C8=0,0,IF(01_因子設定!$B$20="Box-Behnken",S8,P8*IF($A8>8,01_因子設定!$B$22,1))) -> 1 | E8: =IF($C8=0,0,IF(01_因子設定!$B$20="Box-Behnken",T8,Q8*IF($A8>8,01_因子設定!$B$22,1))) -> 1 | F8: =IF($C8=0,0,IF(01_因子設定!$B$20="Box-Behnken",U8,R8*IF($A8>8,01_因子設定!$B$22,1))) -> -1 | G8: =IF($C8=1,01_因子設定!$G$5+D8*01_因子設定!$H$5,"") -> 75 | H8: =IF($C8=1,01_因子設定!$G$6+E8*01_因子設定!$H$6,"") -> 40 | I8: =IF($C8=1,01_因子設定!$G$7+F8*01_因子設定!$H$7,"") -> 1 | J8: =IF(C8=0,"",IF(AND(OR(01_因子設定!$I$5="",G8>=01_因子設定!$I$5),OR(01_因子設定!$J$5="",G8<=01_因子設定!$J$5),OR(01_因子設定!$I$6="",H8>=01_因子設定!$I$6),OR(01_因子設定!$J$6="",H8<=01_因子設定!$J$6),OR(01_因子設定!$I$7="",I8>=01_因子設定!$I$7),OR(01_因子設定!$J$7="",I8<=01_因子設定!$J$7)),"OK","安全限界超過")) -> OK | K8: 0.508758 | L8: =IF(C8=0,99,IF(AND(01_因子設定!$B$24="変更困難因子でグループ化",01_因子設定!$B$25>0),VLOOKUP(ROUND(INDEX(D8:F8,01_因子設定!$B$25),6),$W$5:$X$9,2,FALSE())+K8*0.9,K8)) -> 0.508758 | M8: =IF(C8=1,SUMPRODUCT(($C$5:$C$28=1)*($L$5:$L$28<L8))+1,"") -> 11 | N8: =IF(C8=1,INDEX(03_実験結果!$H$5:$H$28,M8),0) -> 47 | P8: 1 | Q8: 1 | R8: -1 | S8: 1 | T8: 1 | U8: 0 | W8: 1 | X8: 2
A9: 5 | B9: =IF(A9>01_因子設定!$B$23,"未使用",IF(A9>01_因子設定!$B$26,"中心点",IF(01_因子設定!$B$20="Box-Behnken","BBD点",IF(A9<=8,"要因点","軸点")))) -> 要因点 | C9: =IF(A9<=01_因子設定!$B$23,1,0) -> 1 | D9: =IF($C9=0,0,IF(01_因子設定!$B$20="Box-Behnken",S9,P9*IF($A9>8,01_因子設定!$B$22,1))) -> -1 | E9: =IF($C9=0,0,IF(01_因子設定!$B$20="Box-Behnken",T9,Q9*IF($A9>8,01_因子設定!$B$22,1))) -> -1 | F9: =IF($C9=0,0,IF(01_因子設定!$B$20="Box-Behnken",U9,R9*IF($A9>8,01_因子設定!$B$22,1))) -> 1 | G9: =IF($C9=1,01_因子設定!$G$5+D9*01_因子設定!$H$5,"") -> 55 | H9: =IF($C9=1,01_因子設定!$G$6+E9*01_因子設定!$H$6,"") -> 20 | I9: =IF($C9=1,01_因子設定!$G$7+F9*01_因子設定!$H$7,"") -> 3 | J9: =IF(C9=0,"",IF(AND(OR(01_因子設定!$I$5="",G9>=01_因子設定!$I$5),OR(01_因子設定!$J$5="",G9<=01_因子設定!$J$5),OR(01_因子設定!$I$6="",H9>=01_因子設定!$I$6),OR(01_因子設定!$J$6="",H9<=01_因子設定!$J$6),OR(01_因子設定!$I$7="",I9>=01_因子設定!$I$7),OR(01_因子設定!$J$7="",I9<=01_因子設定!$J$7)),"OK","安全限界超過")) -> OK | K9: 0.972097 | L9: =IF(C9=0,99,IF(AND(01_因子設定!$B$24="変更困難因子でグループ化",01_因子設定!$B$25>0),VLOOKUP(ROUND(INDEX(D9:F9,01_因子設定!$B$25),6),$W$5:$X$9,2,FALSE())+K9*0.9,K9)) -> 0.972097 | M9: =IF(C9=1,SUMPRODUCT(($C$5:$C$28=1)*($L$5:$L$28<L9))+1,"") -> 20 | N9: =IF(C9=1,INDEX(03_実験結果!$H$5:$H$28,M9),0) -> 40.3 | P9: -1 | Q9: -1 | R9: 1 | S9: -1 | T9: 0 | U9: -1 | W9: 1.681793 | X9: 4
A10: 6 | B10: =IF(A10>01_因子設定!$B$23,"未使用",IF(A10>01_因子設定!$B$26,"中心点",IF(01_因子設定!$B$20="Box-Behnken","BBD点",IF(A10<=8,"要因点","軸点")))) -> 要因点 | C10: =IF(A10<=01_因子設定!$B$23,1,0) -> 1 | D10: =IF($C10=0,0,IF(01_因子設定!$B$20="Box-Behnken",S10,P10*IF($A10>8,01_因子設定!$B$22,1))) -> 1 | E10: =IF($C10=0,0,IF(01_因子設定!$B$20="Box-Behnken",T10,Q10*IF($A10>8,01_因子設定!$B$22,1))) -> -1 | F10: =IF($C10=0,0,IF(01_因子設定!$B$20="Box-Behnken",U10,R10*IF($A10>8,01_因子設定!$B$22,1))) -> 1 | G10: =IF($C10=1,01_因子設定!$G$5+D10*01_因子設定!$H$5,"") -> 75 | H10: =IF($C10=1,01_因子設定!$G$6+E10*01_因子設定!$H$6,"") -> 20 | I10: =IF($C10=1,01_因子設定!$G$7+F10*01_因子設定!$H$7,"") -> 3 | J10: =IF(C10=0,"",IF(AND(OR(01_因子設定!$I$5="",G10>=01_因子設定!$I$5),OR(01_因子設定!$J$5="",G10<=01_因子設定!$J$5),OR(01_因子設定!$I$6="",H10>=01_因子設定!$I$6),OR(01_因子設定!$J$6="",H10<=01_因子設定!$J$6),OR(01_因子設定!$I$7="",I10>=01_因子設定!$I$7),OR(01_因子設定!$J$7="",I10<=01_因子設定!$J$7)),"OK","安全限界超過")) -> OK | K10: 0.567553 | L10: =IF(C10=0,99,IF(AND(01_因子設定!$B$24="変更困難因子でグループ化",01_因子設定!$B$25>0),VLOOKUP(ROUND(INDEX(D10:F10,01_因子設定!$B$25),6),$W$5:$X$9,2,FALSE())+K10*0.9,K10)) -> 0.567553 | M10: =IF(C10=1,SUMPRODUCT(($C$5:$C$28=1)*($L$5:$L$28<L10))+1,"") -> 13 | N10: =IF(C10=1,INDEX(03_実験結果!$H$5:$H$28,M10),0) -> 43.2 | P10: 1 | Q10: -1 | R10: 1 | S10: 1 | T10: 0 | U10: -1
A11: 7 | B11: =IF(A11>01_因子設定!$B$23,"未使用",IF(A11>01_因子設定!$B$26,"中心点",IF(01_因子設定!$B$20="Box-Behnken","BBD点",IF(A11<=8,"要因点","軸点")))) -> 要因点 | C11: =IF(A11<=01_因子設定!$B$23,1,0) -> 1 | D11: =IF($C11=0,0,IF(01_因子設定!$B$20="Box-Behnken",S11,P11*IF($A11>8,01_因子設定!$B$22,1))) -> -1 | E11: =IF($C11=0,0,IF(01_因子設定!$B$20="Box-Behnken",T11,Q11*IF($A11>8,01_因子設定!$B$22,1))) -> 1 | F11: =IF($C11=0,0,IF(01_因子設定!$B$20="Box-Behnken",U11,R11*IF($A11>8,01_因子設定!$B$22,1))) -> 1 | G11: =IF($C11=1,01_因子設定!$G$5+D11*01_因子設定!$H$5,"") -> 55 | H11: =IF($C11=1,01_因子設定!$G$6+E11*01_因子設定!$H$6,"") -> 40 | I11: =IF($C11=1,01_因子設定!$G$7+F11*01_因子設定!$H$7,"") -> 3 | J11: =IF(C11=0,"",IF(AND(OR(01_因子設定!$I$5="",G11>=01_因子設定!$I$5),OR(01_因子設定!$J$5="",G11<=01_因子設定!$J$5),OR(01_因子設定!$I$6="",H11>=01_因子設定!$I$6),OR(01_因子設定!$J$6="",H11<=01_因子設定!$J$6),OR(01_因子設定!$I$7="",I11>=01_因子設定!$I$7),OR(01_因子設定!$J$7="",I11<=01_因子設定!$J$7)),"OK","安全限界超過")) -> OK | K11: 0.314194 | L11: =IF(C11=0,99,IF(AND(01_因子設定!$B$24="変更困難因子でグループ化",01_因子設定!$B$25>0),VLOOKUP(ROUND(INDEX(D11:F11,01_因子設定!$B$25),6),$W$5:$X$9,2,FALSE())+K11*0.9,K11)) -> 0.314194 | M11: =IF(C11=1,SUMPRODUCT(($C$5:$C$28=1)*($L$5:$L$28<L11))+1,"") -> 4 | N11: =IF(C11=1,INDEX(03_実験結果!$H$5:$H$28,M11),0) -> 43 | P11: -1 | Q11: 1 | R11: 1 | S11: -1 | T11: 0 | U11: 1 | W11: グループ順位＝変更困難因子の水準を実施する順番（1が最初）。入れ替え可
A12: 8 | B12: =IF(A12>01_因子設定!$B$23,"未使用",IF(A12>01_因子設定!$B$26,"中心点",IF(01_因子設定!$B$20="Box-Behnken","BBD点",IF(A12<=8,"要因点","軸点")))) -> 要因点 | C12: =IF(A12<=01_因子設定!$B$23,1,0) -> 1 | D12: =IF($C12=0,0,IF(01_因子設定!$B$20="Box-Behnken",S12,P12*IF($A12>8,01_因子設定!$B$22,1))) -> 1 | E12: =IF($C12=0,0,IF(01_因子設定!$B$20="Box-Behnken",T12,Q12*IF($A12>8,01_因子設定!$B$22,1))) -> 1 | F12: =IF($C12=0,0,IF(01_因子設定!$B$20="Box-Behnken",U12,R12*IF($A12>8,01_因子設定!$B$22,1))) -> 1 | G12: =IF($C12=1,01_因子設定!$G$5+D12*01_因子設定!$H$5,"") -> 75 | H12: =IF($C12=1,01_因子設定!$G$6+E12*01_因子設定!$H$6,"") -> 40 | I12: =IF($C12=1,01_因子設定!$G$7+F12*01_因子設定!$H$7,"") -> 3 | J12: =IF(C12=0,"",IF(AND(OR(01_因子設定!$I$5="",G12>=01_因子設定!$I$5),OR(01_因子設定!$J$5="",G12<=01_因子設定!$J$5),OR(01_因子設定!$I$6="",H12>=01_因子設定!$I$6),OR(01_因子設定!$J$6="",H12<=01_因子設定!$J$6),OR(01_因子設定!$I$7="",I12>=01_因子設定!$I$7),OR(01_因子設定!$J$7="",I12<=01_因子設定!$J$7)),"OK","安全限界超過")) -> OK | K12: 0.657406 | L12: =IF(C12=0,99,IF(AND(01_因子設定!$B$24="変更困難因子でグループ化",01_因子設定!$B$25>0),VLOOKUP(ROUND(INDEX(D12:F12,01_因子設定!$B$25),6),$W$5:$X$9,2,FALSE())+K12*0.9,K12)) -> 0.657406 | M12: =IF(C12=1,SUMPRODUCT(($C$5:$C$28=1)*($L$5:$L$28<L12))+1,"") -> 15 | N12: =IF(C12=1,INDEX(03_実験結果!$H$5:$H$28,M12),0) -> 50.1 | P12: 1 | Q12: 1 | R12: 1 | S12: 1 | T12: 0 | U12: 1
A13: 9 | B13: =IF(A13>01_因子設定!$B$23,"未使用",IF(A13>01_因子設定!$B$26,"中心点",IF(01_因子設定!$B$20="Box-Behnken","BBD点",IF(A13<=8,"要因点","軸点")))) -> 軸点 | C13: =IF(A13<=01_因子設定!$B$23,1,0) -> 1 | D13: =IF($C13=0,0,IF(01_因子設定!$B$20="Box-Behnken",S13,P13*IF($A13>8,01_因子設定!$B$22,1))) -> -1 | E13: =IF($C13=0,0,IF(01_因子設定!$B$20="Box-Behnken",T13,Q13*IF($A13>8,01_因子設定!$B$22,1))) -> 0 | F13: =IF($C13=0,0,IF(01_因子設定!$B$20="Box-Behnken",U13,R13*IF($A13>8,01_因子設定!$B$22,1))) -> 0 | G13: =IF($C13=1,01_因子設定!$G$5+D13*01_因子設定!$H$5,"") -> 55 | H13: =IF($C13=1,01_因子設定!$G$6+E13*01_因子設定!$H$6,"") -> 30 | I13: =IF($C13=1,01_因子設定!$G$7+F13*01_因子設定!$H$7,"") -> 2 | J13: =IF(C13=0,"",IF(AND(OR(01_因子設定!$I$5="",G13>=01_因子設定!$I$5),OR(01_因子設定!$J$5="",G13<=01_因子設定!$J$5),OR(01_因子設定!$I$6="",H13>=01_因子設定!$I$6),OR(01_因子設定!$J$6="",H13<=01_因子設定!$J$6),OR(01_因子設定!$I$7="",I13>=01_因子設定!$I$7),OR(01_因子設定!$J$7="",I13<=01_因子設定!$J$7)),"OK","安全限界超過")) -> OK | K13: 0.350569 | L13: =IF(C13=0,99,IF(AND(01_因子設定!$B$24="変更困難因子でグループ化",01_因子設定!$B$25>0),VLOOKUP(ROUND(INDEX(D13:F13,01_因子設定!$B$25),6),$W$5:$X$9,2,FALSE())+K13*0.9,K13)) -> 0.350569 | M13: =IF(C13=1,SUMPRODUCT(($C$5:$C$28=1)*($L$5:$L$28<L13))+1,"") -> 8 | N13: =IF(C13=1,INDEX(03_実験結果!$H$5:$H$28,M13),0) -> 43.3 | P13: -1 | Q13: 0 | R13: 0 | S13: 0 | T13: -1 | U13: -1
A14: 10 | B14: =IF(A14>01_因子設定!$B$23,"未使用",IF(A14>01_因子設定!$B$26,"中心点",IF(01_因子設定!$B$20="Box-Behnken","BBD点",IF(A14<=8,"要因点","軸点")))) -> 軸点 | C14: =IF(A14<=01_因子設定!$B$23,1,0) -> 1 | D14: =IF($C14=0,0,IF(01_因子設定!$B$20="Box-Behnken",S14,P14*IF($A14>8,01_因子設定!$B$22,1))) -> 1 | E14: =IF($C14=0,0,IF(01_因子設定!$B$20="Box-Behnken",T14,Q14*IF($A14>8,01_因子設定!$B$22,1))) -> 0 | F14: =IF($C14=0,0,IF(01_因子設定!$B$20="Box-Behnken",U14,R14*IF($A14>8,01_因子設定!$B$22,1))) -> 0 | G14: =IF($C14=1,01_因子設定!$G$5+D14*01_因子設定!$H$5,"") -> 75 | H14: =IF($C14=1,01_因子設定!$G$6+E14*01_因子設定!$H$6,"") -> 30 | I14: =IF($C14=1,01_因子設定!$G$7+F14*01_因子設定!$H$7,"") -> 2 | J14: =IF(C14=0,"",IF(AND(OR(01_因子設定!$I$5="",G14>=01_因子設定!$I$5),OR(01_因子設定!$J$5="",G14<=01_因子設定!$J$5),OR(01_因子設定!$I$6="",H14>=01_因子設定!$I$6),OR(01_因子設定!$J$6="",H14<=01_因子設定!$J$6),OR(01_因子設定!$I$7="",I14>=01_因子設定!$I$7),OR(01_因子設定!$J$7="",I14<=01_因子設定!$J$7)),"OK","安全限界超過")) -> OK | K14: 0.559888 | L14: =IF(C14=0,99,IF(AND(01_因子設定!$B$24="変更困難因子でグループ化",01_因子設定!$B$25>0),VLOOKUP(ROUND(INDEX(D14:F14,01_因子設定!$B$25),6),$W$5:$X$9,2,FALSE())+K14*0.9,K14)) -> 0.559888 | M14: =IF(C14=1,SUMPRODUCT(($C$5:$C$28=1)*($L$5:$L$28<L14))+1,"") -> 12 | N14: =IF(C14=1,INDEX(03_実験結果!$H$5:$H$28,M14),0) -> 48.3 | P14: 1 | Q14: 0 | R14: 0 | S14: 0 | T14: 1 | U14: -1
A15: 11 | B15: =IF(A15>01_因子設定!$B$23,"未使用",IF(A15>01_因子設定!$B$26,"中心点",IF(01_因子設定!$B$20="Box-Behnken","BBD点",IF(A15<=8,"要因点","軸点")))) -> 軸点 | C15: =IF(A15<=01_因子設定!$B$23,1,0) -> 1 | D15: =IF($C15=0,0,IF(01_因子設定!$B$20="Box-Behnken",S15,P15*IF($A15>8,01_因子設定!$B$22,1))) -> 0 | E15: =IF($C15=0,0,IF(01_因子設定!$B$20="Box-Behnken",T15,Q15*IF($A15>8,01_因子設定!$B$22,1))) -> -1 | F15: =IF($C15=0,0,IF(01_因子設定!$B$20="Box-Behnken",U15,R15*IF($A15>8,01_因子設定!$B$22,1))) -> 0 | G15: =IF($C15=1,01_因子設定!$G$5+D15*01_因子設定!$H$5,"") -> 65 | H15: =IF($C15=1,01_因子設定!$G$6+E15*01_因子設定!$H$6,"") -> 20 | I15: =IF($C15=1,01_因子設定!$G$7+F15*01_因子設定!$H$7,"") -> 2 | J15: =IF(C15=0,"",IF(AND(OR(01_因子設定!$I$5="",G15>=01_因子設定!$I$5),OR(01_因子設定!$J$5="",G15<=01_因子設定!$J$5),OR(01_因子設定!$I$6="",H15>=01_因子設定!$I$6),OR(01_因子設定!$J$6="",H15<=01_因子設定!$J$6),OR(01_因子設定!$I$7="",I15>=01_因子設定!$I$7),OR(01_因子設定!$J$7="",I15<=01_因子設定!$J$7)),"OK","安全限界超過")) -> OK | K15: 0.681928 | L15: =IF(C15=0,99,IF(AND(01_因子設定!$B$24="変更困難因子でグループ化",01_因子設定!$B$25>0),VLOOKUP(ROUND(INDEX(D15:F15,01_因子設定!$B$25),6),$W$5:$X$9,2,FALSE())+K15*0.9,K15)) -> 0.681928 | M15: =IF(C15=1,SUMPRODUCT(($C$5:$C$28=1)*($L$5:$L$28<L15))+1,"") -> 16 | N15: =IF(C15=1,INDEX(03_実験結果!$H$5:$H$28,M15),0) -> 43.7 | P15: 0 | Q15: -1 | R15: 0 | S15: 0 | T15: -1 | U15: 1
A16: 12 | B16: =IF(A16>01_因子設定!$B$23,"未使用",IF(A16>01_因子設定!$B$26,"中心点",IF(01_因子設定!$B$20="Box-Behnken","BBD点",IF(A16<=8,"要因点","軸点")))) -> 軸点 | C16: =IF(A16<=01_因子設定!$B$23,1,0) -> 1 | D16: =IF($C16=0,0,IF(01_因子設定!$B$20="Box-Behnken",S16,P16*IF($A16>8,01_因子設定!$B$22,1))) -> 0 | E16: =IF($C16=0,0,IF(01_因子設定!$B$20="Box-Behnken",T16,Q16*IF($A16>8,01_因子設定!$B$22,1))) -> 1 | F16: =IF($C16=0,0,IF(01_因子設定!$B$20="Box-Behnken",U16,R16*IF($A16>8,01_因子設定!$B$22,1))) -> 0 | G16: =IF($C16=1,01_因子設定!$G$5+D16*01_因子設定!$H$5,"") -> 65 | H16: =IF($C16=1,01_因子設定!$G$6+E16*01_因子設定!$H$6,"") -> 40 | I16: =IF($C16=1,01_因子設定!$G$7+F16*01_因子設定!$H$7,"") -> 2 | J16: =IF(C16=0,"",IF(AND(OR(01_因子設定!$I$5="",G16>=01_因子設定!$I$5),OR(01_因子設定!$J$5="",G16<=01_因子設定!$J$5),OR(01_因子設定!$I$6="",H16>=01_因子設定!$I$6),OR(01_因子設定!$J$6="",H16<=01_因子設定!$J$6),OR(01_因子設定!$I$7="",I16>=01_因子設定!$I$7),OR(01_因子設定!$J$7="",I16<=01_因子設定!$J$7)),"OK","安全限界超過")) -> OK | K16: 0.920446 | L16: =IF(C16=0,99,IF(AND(01_因子設定!$B$24="変更困難因子でグループ化",01_因子設定!$B$25>0),VLOOKUP(ROUND(INDEX(D16:F16,01_因子設定!$B$25),6),$W$5:$X$9,2,FALSE())+K16*0.9,K16)) -> 0.920446 | M16: =IF(C16=1,SUMPRODUCT(($C$5:$C$28=1)*($L$5:$L$28<L16))+1,"") -> 19 | N16: =IF(C16=1,INDEX(03_実験結果!$H$5:$H$28,M16),0) -> 48.8 | P16: 0 | Q16: 1 | R16: 0 | S16: 0 | T16: 1 | U16: 1
A17: 13 | B17: =IF(A17>01_因子設定!$B$23,"未使用",IF(A17>01_因子設定!$B$26,"中心点",IF(01_因子設定!$B$20="Box-Behnken","BBD点",IF(A17<=8,"要因点","軸点")))) -> 軸点 | C17: =IF(A17<=01_因子設定!$B$23,1,0) -> 1 | D17: =IF($C17=0,0,IF(01_因子設定!$B$20="Box-Behnken",S17,P17*IF($A17>8,01_因子設定!$B$22,1))) -> 0 | E17: =IF($C17=0,0,IF(01_因子設定!$B$20="Box-Behnken",T17,Q17*IF($A17>8,01_因子設定!$B$22,1))) -> 0 | F17: =IF($C17=0,0,IF(01_因子設定!$B$20="Box-Behnken",U17,R17*IF($A17>8,01_因子設定!$B$22,1))) -> -1 | G17: =IF($C17=1,01_因子設定!$G$5+D17*01_因子設定!$H$5,"") -> 65 | H17: =IF($C17=1,01_因子設定!$G$6+E17*01_因子設定!$H$6,"") -> 30 | I17: =IF($C17=1,01_因子設定!$G$7+F17*01_因子設定!$H$7,"") -> 1 | J17: =IF(C17=0,"",IF(AND(OR(01_因子設定!$I$5="",G17>=01_因子設定!$I$5),OR(01_因子設定!$J$5="",G17<=01_因子設定!$J$5),OR(01_因子設定!$I$6="",H17>=01_因子設定!$I$6),OR(01_因子設定!$J$6="",H17<=01_因子設定!$J$6),OR(01_因子設定!$I$7="",I17>=01_因子設定!$I$7),OR(01_因子設定!$J$7="",I17<=01_因子設定!$J$7)),"OK","安全限界超過")) -> OK | K17: 0.467942 | L17: =IF(C17=0,99,IF(AND(01_因子設定!$B$24="変更困難因子でグループ化",01_因子設定!$B$25>0),VLOOKUP(ROUND(INDEX(D17:F17,01_因子設定!$B$25),6),$W$5:$X$9,2,FALSE())+K17*0.9,K17)) -> 0.467942 | M17: =IF(C17=1,SUMPRODUCT(($C$5:$C$28=1)*($L$5:$L$28<L17))+1,"") -> 10 | N17: =IF(C17=1,INDEX(03_実験結果!$H$5:$H$28,M17),0) -> 45.9 | P17: 0 | Q17: 0 | R17: -1 | S17: 0 | T17: 0 | U17: 0
A18: 14 | B18: =IF(A18>01_因子設定!$B$23,"未使用",IF(A18>01_因子設定!$B$26,"中心点",IF(01_因子設定!$B$20="Box-Behnken","BBD点",IF(A18<=8,"要因点","軸点")))) -> 軸点 | C18: =IF(A18<=01_因子設定!$B$23,1,0) -> 1 | D18: =IF($C18=0,0,IF(01_因子設定!$B$20="Box-Behnken",S18,P18*IF($A18>8,01_因子設定!$B$22,1))) -> 0 | E18: =IF($C18=0,0,IF(01_因子設定!$B$20="Box-Behnken",T18,Q18*IF($A18>8,01_因子設定!$B$22,1))) -> 0 | F18: =IF($C18=0,0,IF(01_因子設定!$B$20="Box-Behnken",U18,R18*IF($A18>8,01_因子設定!$B$22,1))) -> 1 | G18: =IF($C18=1,01_因子設定!$G$5+D18*01_因子設定!$H$5,"") -> 65 | H18: =IF($C18=1,01_因子設定!$G$6+E18*01_因子設定!$H$6,"") -> 30 | I18: =IF($C18=1,01_因子設定!$G$7+F18*01_因子設定!$H$7,"") -> 3 | J18: =IF(C18=0,"",IF(AND(OR(01_因子設定!$I$5="",G18>=01_因子設定!$I$5),OR(01_因子設定!$J$5="",G18<=01_因子設定!$J$5),OR(01_因子設定!$I$6="",H18>=01_因子設定!$I$6),OR(01_因子設定!$J$6="",H18<=01_因子設定!$J$6),OR(01_因子設定!$I$7="",I18>=01_因子設定!$I$7),OR(01_因子設定!$J$7="",I18<=01_因子設定!$J$7)),"OK","安全限界超過")) -> OK | K18: 0.015268 | L18: =IF(C18=0,99,IF(AND(01_因子設定!$B$24="変更困難因子でグループ化",01_因子設定!$B$25>0),VLOOKUP(ROUND(INDEX(D18:F18,01_因子設定!$B$25),6),$W$5:$X$9,2,FALSE())+K18*0.9,K18)) -> 0.015268 | M18: =IF(C18=1,SUMPRODUCT(($C$5:$C$28=1)*($L$5:$L$28<L18))+1,"") -> 1 | N18: =IF(C18=1,INDEX(03_実験結果!$H$5:$H$28,M18),0) -> 48.3 | P18: 0 | Q18: 0 | R18: 1 | S18: 0 | T18: 0 | U18: 0
A19: 15 | B19: =IF(A19>01_因子設定!$B$23,"未使用",IF(A19>01_因子設定!$B$26,"中心点",IF(01_因子設定!$B$20="Box-Behnken","BBD点",IF(A19<=8,"要因点","軸点")))) -> 中心点 | C19: =IF(A19<=01_因子設定!$B$23,1,0) -> 1 | D19: =IF($C19=0,0,IF(01_因子設定!$B$20="Box-Behnken",S19,P19*IF($A19>8,01_因子設定!$B$22,1))) -> 0 | E19: =IF($C19=0,0,IF(01_因子設定!$B$20="Box-Behnken",T19,Q19*IF($A19>8,01_因子設定!$B$22,1))) -> 0 | F19: =IF($C19=0,0,IF(01_因子設定!$B$20="Box-Behnken",U19,R19*IF($A19>8,01_因子設定!$B$22,1))) -> 0 | G19: =IF($C19=1,01_因子設定!$G$5+D19*01_因子設定!$H$5,"") -> 65 | H19: =IF($C19=1,01_因子設定!$G$6+E19*01_因子設定!$H$6,"") -> 30 | I19: =IF($C19=1,01_因子設定!$G$7+F19*01_因子設定!$H$7,"") -> 2 | J19: =IF(C19=0,"",IF(AND(OR(01_因子設定!$I$5="",G19>=01_因子設定!$I$5),OR(01_因子設定!$J$5="",G19<=01_因子設定!$J$5),OR(01_因子設定!$I$6="",H19>=01_因子設定!$I$6),OR(01_因子設定!$J$6="",H19<=01_因子設定!$J$6),OR(01_因子設定!$I$7="",I19>=01_因子設定!$I$7),OR(01_因子設定!$J$7="",I19<=01_因子設定!$J$7)),"OK","安全限界超過")) -> OK | K19: 0.030983 | L19: =IF(C19=0,99,IF(AND(01_因子設定!$B$24="変更困難因子でグループ化",01_因子設定!$B$25>0),VLOOKUP(ROUND(INDEX(D19:F19,01_因子設定!$B$25),6),$W$5:$X$9,2,FALSE())+K19*0.9,K19)) -> 0.030983 | M19: =IF(C19=1,SUMPRODUCT(($C$5:$C$28=1)*($L$5:$L$28<L19))+1,"") -> 2 | N19: =IF(C19=1,INDEX(03_実験結果!$H$5:$H$28,M19),0) -> 48.5 | P19: 0 | Q19: 0 | R19: 0 | S19: 0 | T19: 0 | U19: 0
A20: 16 | B20: =IF(A20>01_因子設定!$B$23,"未使用",IF(A20>01_因子設定!$B$26,"中心点",IF(01_因子設定!$B$20="Box-Behnken","BBD点",IF(A20<=8,"要因点","軸点")))) -> 中心点 | C20: =IF(A20<=01_因子設定!$B$23,1,0) -> 1 | D20: =IF($C20=0,0,IF(01_因子設定!$B$20="Box-Behnken",S20,P20*IF($A20>8,01_因子設定!$B$22,1))) -> 0 | E20: =IF($C20=0,0,IF(01_因子設定!$B$20="Box-Behnken",T20,Q20*IF($A20>8,01_因子設定!$B$22,1))) -> 0 | F20: =IF($C20=0,0,IF(01_因子設定!$B$20="Box-Behnken",U20,R20*IF($A20>8,01_因子設定!$B$22,1))) -> 0 | G20: =IF($C20=1,01_因子設定!$G$5+D20*01_因子設定!$H$5,"") -> 65 | H20: =IF($C20=1,01_因子設定!$G$6+E20*01_因子設定!$H$6,"") -> 30 | I20: =IF($C20=1,01_因子設定!$G$7+F20*01_因子設定!$H$7,"") -> 2 | J20: =IF(C20=0,"",IF(AND(OR(01_因子設定!$I$5="",G20>=01_因子設定!$I$5),OR(01_因子設定!$J$5="",G20<=01_因子設定!$J$5),OR(01_因子設定!$I$6="",H20>=01_因子設定!$I$6),OR(01_因子設定!$J$6="",H20<=01_因子設定!$J$6),OR(01_因子設定!$I$7="",I20>=01_因子設定!$I$7),OR(01_因子設定!$J$7="",I20<=01_因子設定!$J$7)),"OK","安全限界超過")) -> OK | K20: 0.341024 | L20: =IF(C20=0,99,IF(AND(01_因子設定!$B$24="変更困難因子でグループ化",01_因子設定!$B$25>0),VLOOKUP(ROUND(INDEX(D20:F20,01_因子設定!$B$25),6),$W$5:$X$9,2,FALSE())+K20*0.9,K20)) -> 0.341024 | M20: =IF(C20=1,SUMPRODUCT(($C$5:$C$28=1)*($L$5:$L$28<L20))+1,"") -> 6 | N20: =IF(C20=1,INDEX(03_実験結果!$H$5:$H$28,M20),0) -> 48.2 | P20: 0 | Q20: 0 | R20: 0 | S20: 0 | T20: 0 | U20: 0
A21: 17 | B21: =IF(A21>01_因子設定!$B$23,"未使用",IF(A21>01_因子設定!$B$26,"中心点",IF(01_因子設定!$B$20="Box-Behnken","BBD点",IF(A21<=8,"要因点","軸点")))) -> 中心点 | C21: =IF(A21<=01_因子設定!$B$23,1,0) -> 1 | D21: =IF($C21=0,0,IF(01_因子設定!$B$20="Box-Behnken",S21,P21*IF($A21>8,01_因子設定!$B$22,1))) -> 0 | E21: =IF($C21=0,0,IF(01_因子設定!$B$20="Box-Behnken",T21,Q21*IF($A21>8,01_因子設定!$B$22,1))) -> 0 | F21: =IF($C21=0,0,IF(01_因子設定!$B$20="Box-Behnken",U21,R21*IF($A21>8,01_因子設定!$B$22,1))) -> 0 | G21: =IF($C21=1,01_因子設定!$G$5+D21*01_因子設定!$H$5,"") -> 65 | H21: =IF($C21=1,01_因子設定!$G$6+E21*01_因子設定!$H$6,"") -> 30 | I21: =IF($C21=1,01_因子設定!$G$7+F21*01_因子設定!$H$7,"") -> 2 | J21: =IF(C21=0,"",IF(AND(OR(01_因子設定!$I$5="",G21>=01_因子設定!$I$5),OR(01_因子設定!$J$5="",G21<=01_因子設定!$J$5),OR(01_因子設定!$I$6="",H21>=01_因子設定!$I$6),OR(01_因子設定!$J$6="",H21<=01_因子設定!$J$6),OR(01_因子設定!$I$7="",I21>=01_因子設定!$I$7),OR(01_因子設定!$J$7="",I21<=01_因子設定!$J$7)),"OK","安全限界超過")) -> OK | K21: 0.833281 | L21: =IF(C21=0,99,IF(AND(01_因子設定!$B$24="変更困難因子でグループ化",01_因子設定!$B$25>0),VLOOKUP(ROUND(INDEX(D21:F21,01_因子設定!$B$25),6),$W$5:$X$9,2,FALSE())+K21*0.9,K21)) -> 0.833281 | M21: =IF(C21=1,SUMPRODUCT(($C$5:$C$28=1)*($L$5:$L$28<L21))+1,"") -> 18 | N21: =IF(C21=1,INDEX(03_実験結果!$H$5:$H$28,M21),0) -> 48.9 | P21: 0 | Q21: 0 | R21: 0 | S21: 0 | T21: 0 | U21: 0
A22: 18 | B22: =IF(A22>01_因子設定!$B$23,"未使用",IF(A22>01_因子設定!$B$26,"中心点",IF(01_因子設定!$B$20="Box-Behnken","BBD点",IF(A22<=8,"要因点","軸点")))) -> 中心点 | C22: =IF(A22<=01_因子設定!$B$23,1,0) -> 1 | D22: =IF($C22=0,0,IF(01_因子設定!$B$20="Box-Behnken",S22,P22*IF($A22>8,01_因子設定!$B$22,1))) -> 0 | E22: =IF($C22=0,0,IF(01_因子設定!$B$20="Box-Behnken",T22,Q22*IF($A22>8,01_因子設定!$B$22,1))) -> 0 | F22: =IF($C22=0,0,IF(01_因子設定!$B$20="Box-Behnken",U22,R22*IF($A22>8,01_因子設定!$B$22,1))) -> 0 | G22: =IF($C22=1,01_因子設定!$G$5+D22*01_因子設定!$H$5,"") -> 65 | H22: =IF($C22=1,01_因子設定!$G$6+E22*01_因子設定!$H$6,"") -> 30 | I22: =IF($C22=1,01_因子設定!$G$7+F22*01_因子設定!$H$7,"") -> 2 | J22: =IF(C22=0,"",IF(AND(OR(01_因子設定!$I$5="",G22>=01_因子設定!$I$5),OR(01_因子設定!$J$5="",G22<=01_因子設定!$J$5),OR(01_因子設定!$I$6="",H22>=01_因子設定!$I$6),OR(01_因子設定!$J$6="",H22<=01_因子設定!$J$6),OR(01_因子設定!$I$7="",I22>=01_因子設定!$I$7),OR(01_因子設定!$J$7="",I22<=01_因子設定!$J$7)),"OK","安全限界超過")) -> OK | K22: 0.76611 | L22: =IF(C22=0,99,IF(AND(01_因子設定!$B$24="変更困難因子でグループ化",01_因子設定!$B$25>0),VLOOKUP(ROUND(INDEX(D22:F22,01_因子設定!$B$25),6),$W$5:$X$9,2,FALSE())+K22*0.9,K22)) -> 0.76611 | M22: =IF(C22=1,SUMPRODUCT(($C$5:$C$28=1)*($L$5:$L$28<L22))+1,"") -> 17 | N22: =IF(C22=1,INDEX(03_実験結果!$H$5:$H$28,M22),0) -> 49.3 | P22: 0 | Q22: 0 | R22: 0 | S22: 0 | T22: 0 | U22: 0
A23: 19 | B23: =IF(A23>01_因子設定!$B$23,"未使用",IF(A23>01_因子設定!$B$26,"中心点",IF(01_因子設定!$B$20="Box-Behnken","BBD点",IF(A23<=8,"要因点","軸点")))) -> 中心点 | C23: =IF(A23<=01_因子設定!$B$23,1,0) -> 1 | D23: =IF($C23=0,0,IF(01_因子設定!$B$20="Box-Behnken",S23,P23*IF($A23>8,01_因子設定!$B$22,1))) -> 0 | E23: =IF($C23=0,0,IF(01_因子設定!$B$20="Box-Behnken",T23,Q23*IF($A23>8,01_因子設定!$B$22,1))) -> 0 | F23: =IF($C23=0,0,IF(01_因子設定!$B$20="Box-Behnken",U23,R23*IF($A23>8,01_因子設定!$B$22,1))) -> 0 | G23: =IF($C23=1,01_因子設定!$G$5+D23*01_因子設定!$H$5,"") -> 65 | H23: =IF($C23=1,01_因子設定!$G$6+E23*01_因子設定!$H$6,"") -> 30 | I23: =IF($C23=1,01_因子設定!$G$7+F23*01_因子設定!$H$7,"") -> 2 | J23: =IF(C23=0,"",IF(AND(OR(01_因子設定!$I$5="",G23>=01_因子設定!$I$5),OR(01_因子設定!$J$5="",G23<=01_因子設定!$J$5),OR(01_因子設定!$I$6="",H23>=01_因子設定!$I$6),OR(01_因子設定!$J$6="",H23<=01_因子設定!$J$6),OR(01_因子設定!$I$7="",I23>=01_因子設定!$I$7),OR(01_因子設定!$J$7="",I23<=01_因子設定!$J$7)),"OK","安全限界超過")) -> OK | K23: 0.573266 | L23: =IF(C23=0,99,IF(AND(01_因子設定!$B$24="変更困難因子でグループ化",01_因子設定!$B$25>0),VLOOKUP(ROUND(INDEX(D23:F23,01_因子設定!$B$25),6),$W$5:$X$9,2,FALSE())+K23*0.9,K23)) -> 0.573266 | M23: =IF(C23=1,SUMPRODUCT(($C$5:$C$28=1)*($L$5:$L$28<L23))+1,"") -> 14 | N23: =IF(C23=1,INDEX(03_実験結果!$H$5:$H$28,M23),0) -> 47.9 | P23: 0 | Q23: 0 | R23: 0 | S23: 0 | T23: 0 | U23: 0
... A28: 24 | B28: =IF(A28>01_因子設定!$B$23,"未使用",IF(A28>01_因子設定!$B$26,"中心点",IF(01_因子設定!$B$20="Box-Behnken","BBD点",IF(A28<=8,"要因点","軸点")))) -> 未使用 | C28: =IF(A28<=01_因子設定!$B$23,1,0) -> 0 | D28: =IF($C28=0,0,IF(01_因子設定!$B$20="Box-Behnken",S28,P28*IF($A28>8,01_因子設定!$B$22,1))) -> 0 | E28: =IF($C28=0,0,IF(01_因子設定!$B$20="Box-Behnken",T28,Q28*IF($A28>8,01_因子設定!$B$22,1))) -> 0 | F28: =IF($C28=0,0,IF(01_因子設定!$B$20="Box-Behnken",U28,R28*IF($A28>8,01_因子設定!$B$22,1))) -> 0 | G28: =IF($C28=1,01_因子設定!$G$5+D28*01_因子設定!$H$5,"") | H28: =IF($C28=1,01_因子設定!$G$6+E28*01_因子設定!$H$6,"") | I28: =IF($C28=1,01_因子設定!$G$7+F28*01_因子設定!$H$7,"") | J28: =IF(C28=0,"",IF(AND(OR(01_因子設定!$I$5="",G28>=01_因子設定!$I$5),OR(01_因子設定!$J$5="",G28<=01_因子設定!$J$5),OR(01_因子設定!$I$6="",H28>=01_因子設定!$I$6),OR(01_因子設定!$J$6="",H28<=01_因子設定!$J$6),OR(01_因子設定!$I$7="",I28>=01_因子設定!$I$7),OR(01_因子設定!$J$7="",I28<=01_因子設定!$J$7)),"OK","安全限界超過")) | K28: 0.152997 | L28: =IF(C28=0,99,IF(AND(01_因子設定!$B$24="変更困難因子でグループ化",01_因子設定!$B$25>0),VLOOKUP(ROUND(INDEX(D28:F28,01_因子設定!$B$25),6),$W$5:$X$9,2,FALSE())+K28*0.9,K28)) -> 99 | M28: =IF(C28=1,SUMPRODUCT(($C$5:$C$28=1)*($L$5:$L$28<L28))+1,"") | N28: =IF(C28=1,INDEX(03_実験結果!$H$5:$H$28,M28),0) -> 0 | P28: 0 | Q28: 0 | R28: 0 | S28: 0 | T28: 0 | U28: 0
P30: 右側のパターン列：CCD／BBDの基本パターン（編集不要）

Sheet 03_実験結果
A1: 03 実験指示書・結果入力（実験順）
A2: この順番で実験し、Yを入力。現在のYは検証用の架空データ。計画を変えたら入れ直してください。
A4: 実験順序 | B4: 標準順 | C4: 区分 | D4: =01_因子設定!B5&"["&01_因子設定!D5&"]" -> 炉温[℃] | E4: =01_因子設定!B6&"["&01_因子設定!D6&"]" -> 乾燥時間[min] | F4: =01_因子設定!B7&"["&01_因子設定!D7&"]" -> 循環風速[m/s] | G4: 変更困難因子の水準 | H4: ="Y："&01_因子設定!B11&"["&01_因子設定!B12&"]" -> Y：剥離強度[N/25mm] | I4: メモ（異常・気付き）
A5: 1 | B5: =IF(A5<=01_因子設定!$B$23,INDEX(02_実験計画!$A$5:$A$28,MATCH(A5,02_実験計画!$M$5:$M$28,0)),"") -> 14 | C5: =IF(B5="","",INDEX(02_実験計画!$B$5:$B$28,B5)) -> 軸点 | D5: =IF($B5="","",INDEX(02_実験計画!$G$5:$G$28,$B5)) -> 65 | E5: =IF($B5="","",INDEX(02_実験計画!$H$5:$H$28,$B5)) -> 30 | F5: =IF($B5="","",INDEX(02_実験計画!$I$5:$I$28,$B5)) -> 3 | G5: =IF(OR(B5="",01_因子設定!$B$25=0),"",INDEX(D5:F5,01_因子設定!$B$25)) -> 65 | H5: 48.3
A6: 2 | B6: =IF(A6<=01_因子設定!$B$23,INDEX(02_実験計画!$A$5:$A$28,MATCH(A6,02_実験計画!$M$5:$M$28,0)),"") -> 15 | C6: =IF(B6="","",INDEX(02_実験計画!$B$5:$B$28,B6)) -> 中心点 | D6: =IF($B6="","",INDEX(02_実験計画!$G$5:$G$28,$B6)) -> 65 | E6: =IF($B6="","",INDEX(02_実験計画!$H$5:$H$28,$B6)) -> 30 | F6: =IF($B6="","",INDEX(02_実験計画!$I$5:$I$28,$B6)) -> 2 | G6: =IF(OR(B6="",01_因子設定!$B$25=0),"",INDEX(D6:F6,01_因子設定!$B$25)) -> 65 | H6: 48.5
A7: 3 | B7: =IF(A7<=01_因子設定!$B$23,INDEX(02_実験計画!$A$5:$A$28,MATCH(A7,02_実験計画!$M$5:$M$28,0)),"") -> 1 | C7: =IF(B7="","",INDEX(02_実験計画!$B$5:$B$28,B7)) -> 要因点 | D7: =IF($B7="","",INDEX(02_実験計画!$G$5:$G$28,$B7)) -> 55 | E7: =IF($B7="","",INDEX(02_実験計画!$H$5:$H$28,$B7)) -> 20 | F7: =IF($B7="","",INDEX(02_実験計画!$I$5:$I$28,$B7)) -> 1 | G7: =IF(OR(B7="",01_因子設定!$B$25=0),"",INDEX(D7:F7,01_因子設定!$B$25)) -> 55 | H7: 38.4
A8: 4 | B8: =IF(A8<=01_因子設定!$B$23,INDEX(02_実験計画!$A$5:$A$28,MATCH(A8,02_実験計画!$M$5:$M$28,0)),"") -> 7 | C8: =IF(B8="","",INDEX(02_実験計画!$B$5:$B$28,B8)) -> 要因点 | D8: =IF($B8="","",INDEX(02_実験計画!$G$5:$G$28,$B8)) -> 55 | E8: =IF($B8="","",INDEX(02_実験計画!$H$5:$H$28,$B8)) -> 40 | F8: =IF($B8="","",INDEX(02_実験計画!$I$5:$I$28,$B8)) -> 3 | G8: =IF(OR(B8="",01_因子設定!$B$25=0),"",INDEX(D8:F8,01_因子設定!$B$25)) -> 55 | H8: 43
A9: 5 | B9: =IF(A9<=01_因子設定!$B$23,INDEX(02_実験計画!$A$5:$A$28,MATCH(A9,02_実験計画!$M$5:$M$28,0)),"") -> 2 | C9: =IF(B9="","",INDEX(02_実験計画!$B$5:$B$28,B9)) -> 要因点 | D9: =IF($B9="","",INDEX(02_実験計画!$G$5:$G$28,$B9)) -> 75 | E9: =IF($B9="","",INDEX(02_実験計画!$H$5:$H$28,$B9)) -> 20 | F9: =IF($B9="","",INDEX(02_実験計画!$I$5:$I$28,$B9)) -> 1 | G9: =IF(OR(B9="",01_因子設定!$B$25=0),"",INDEX(D9:F9,01_因子設定!$B$25)) -> 75 | H9: 41.2
A10: 6 | B10: =IF(A10<=01_因子設定!$B$23,INDEX(02_実験計画!$A$5:$A$28,MATCH(A10,02_実験計画!$M$5:$M$28,0)),"") -> 16 | C10: =IF(B10="","",INDEX(02_実験計画!$B$5:$B$28,B10)) -> 中心点 | D10: =IF($B10="","",INDEX(02_実験計画!$G$5:$G$28,$B10)) -> 65 | E10: =IF($B10="","",INDEX(02_実験計画!$H$5:$H$28,$B10)) -> 30 | F10: =IF($B10="","",INDEX(02_実験計画!$I$5:$I$28,$B10)) -> 2 | G10: =IF(OR(B10="",01_因子設定!$B$25=0),"",INDEX(D10:F10,01_因子設定!$B$25)) -> 65 | H10: 48.2
A11: 7 | B11: =IF(A11<=01_因子設定!$B$23,INDEX(02_実験計画!$A$5:$A$28,MATCH(A11,02_実験計画!$M$5:$M$28,0)),"") -> 3 | C11: =IF(B11="","",INDEX(02_実験計画!$B$5:$B$28,B11)) -> 要因点 | D11: =IF($B11="","",INDEX(02_実験計画!$G$5:$G$28,$B11)) -> 55 | E11: =IF($B11="","",INDEX(02_実験計画!$H$5:$H$28,$B11)) -> 40 | F11: =IF($B11="","",INDEX(02_実験計画!$I$5:$I$28,$B11)) -> 1 | G11: =IF(OR(B11="",01_因子設定!$B$25=0),"",INDEX(D11:F11,01_因子設定!$B$25)) -> 55 | H11: 38.6
A12: 8 | B12: =IF(A12<=01_因子設定!$B$23,INDEX(02_実験計画!$A$5:$A$28,MATCH(A12,02_実験計画!$M$5:$M$28,0)),"") -> 9 | C12: =IF(B12="","",INDEX(02_実験計画!$B$5:$B$28,B12)) -> 軸点 | D12: =IF($B12="","",INDEX(02_実験計画!$G$5:$G$28,$B12)) -> 55 | E12: =IF($B12="","",INDEX(02_実験計画!$H$5:$H$28,$B12)) -> 30 | F12: =IF($B12="","",INDEX(02_実験計画!$I$5:$I$28,$B12)) -> 2 | G12: =IF(OR(B12="",01_因子設定!$B$25=0),"",INDEX(D12:F12,01_因子設定!$B$25)) -> 55 | H12: 43.3
A13: 9 | B13: =IF(A13<=01_因子設定!$B$23,INDEX(02_実験計画!$A$5:$A$28,MATCH(A13,02_実験計画!$M$5:$M$28,0)),"") -> 20 | C13: =IF(B13="","",INDEX(02_実験計画!$B$5:$B$28,B13)) -> 中心点 | D13: =IF($B13="","",INDEX(02_実験計画!$G$5:$G$28,$B13)) -> 65 | E13: =IF($B13="","",INDEX(02_実験計画!$H$5:$H$28,$B13)) -> 30 | F13: =IF($B13="","",INDEX(02_実験計画!$I$5:$I$28,$B13)) -> 2 | G13: =IF(OR(B13="",01_因子設定!$B$25=0),"",INDEX(D13:F13,01_因子設定!$B$25)) -> 65 | H13: 47.9
A14: 10 | B14: =IF(A14<=01_因子設定!$B$23,INDEX(02_実験計画!$A$5:$A$28,MATCH(A14,02_実験計画!$M$5:$M$28,0)),"") -> 13 | C14: =IF(B14="","",INDEX(02_実験計画!$B$5:$B$28,B14)) -> 軸点 | D14: =IF($B14="","",INDEX(02_実験計画!$G$5:$G$28,$B14)) -> 65 | E14: =IF($B14="","",INDEX(02_実験計画!$H$5:$H$28,$B14)) -> 30 | F14: =IF($B14="","",INDEX(02_実験計画!$I$5:$I$28,$B14)) -> 1 | G14: =IF(OR(B14="",01_因子設定!$B$25=0),"",INDEX(D14:F14,01_因子設定!$B$25)) -> 65 | H14: 45.9
A15: 11 | B15: =IF(A15<=01_因子設定!$B$23,INDEX(02_実験計画!$A$5:$A$28,MATCH(A15,02_実験計画!$M$5:$M$28,0)),"") -> 4 | C15: =IF(B15="","",INDEX(02_実験計画!$B$5:$B$28,B15)) -> 要因点 | D15: =IF($B15="","",INDEX(02_実験計画!$G$5:$G$28,$B15)) -> 75 | E15: =IF($B15="","",INDEX(02_実験計画!$H$5:$H$28,$B15)) -> 40 | F15: =IF($B15="","",INDEX(02_実験計画!$I$5:$I$28,$B15)) -> 1 | G15: =IF(OR(B15="",01_因子設定!$B$25=0),"",INDEX(D15:F15,01_因子設定!$B$25)) -> 75 | H15: 47
A16: 12 | B16: =IF(A16<=01_因子設定!$B$23,INDEX(02_実験計画!$A$5:$A$28,MATCH(A16,02_実験計画!$M$5:$M$28,0)),"") -> 10 | C16: =IF(B16="","",INDEX(02_実験計画!$B$5:$B$28,B16)) -> 軸点 | D16: =IF($B16="","",INDEX(02_実験計画!$G$5:$G$28,$B16)) -> 75 | E16: =IF($B16="","",INDEX(02_実験計画!$H$5:$H$28,$B16)) -> 30 | F16: =IF($B16="","",INDEX(02_実験計画!$I$5:$I$28,$B16)) -> 2 | G16: =IF(OR(B16="",01_因子設定!$B$25=0),"",INDEX(D16:F16,01_因子設定!$B$25)) -> 75 | H16: 48.3
... A24: 20 | B24: =IF(A24<=01_因子設定!$B$23,INDEX(02_実験計画!$A$5:$A$28,MATCH(A24,02_実験計画!$M$5:$M$28,0)),"") -> 5 | C24: =IF(B24="","",INDEX(02_実験計画!$B$5:$B$28,B24)) -> 要因点 | D24: =IF($B24="","",INDEX(02_実験計画!$G$5:$G$28,$B24)) -> 55 | E24: =IF($B24="","",INDEX(02_実験計画!$H$5:$H$28,$B24)) -> 20 | F24: =IF($B24="","",INDEX(02_実験計画!$I$5:$I$28,$B24)) -> 3 | G24: =IF(OR(B24="",01_因子設定!$B$25=0),"",INDEX(D24:F24,01_因子設定!$B$25)) -> 55 | H24: 40.3
A25: 21 | B25: =IF(A25<=01_因子設定!$B$23,INDEX(02_実験計画!$A$5:$A$28,MATCH(A25,02_実験計画!$M$5:$M$28,0)),"") | C25: =IF(B25="","",INDEX(02_実験計画!$B$5:$B$28,B25)) | D25: =IF($B25="","",INDEX(02_実験計画!$G$5:$G$28,$B25)) | E25: =IF($B25="","",INDEX(02_実験計画!$H$5:$H$28,$B25)) | F25: =IF($B25="","",INDEX(02_実験計画!$I$5:$I$28,$B25)) | G25: =IF(OR(B25="",01_因子設定!$B$25=0),"",INDEX(D25:F25,01_因子設定!$B$25))
A26: 22 | B26: =IF(A26<=01_因子設定!$B$23,INDEX(02_実験計画!$A$5:$A$28,MATCH(A26,02_実験計画!$M$5:$M$28,0)),"") | C26: =IF(B26="","",INDEX(02_実験計画!$B$5:$B$28,B26)) | D26: =IF($B26="","",INDEX(02_実験計画!$G$5:$G$28,$B26)) | E26: =IF($B26="","",INDEX(02_実験計画!$H$5:$H$28,$B26)) | F26: =IF($B26="","",INDEX(02_実験計画!$I$5:$I$28,$B26)) | G26: =IF(OR(B26="",01_因子設定!$B$25=0),"",INDEX(D26:F26,01_因子設定!$B$25))
A27: 23 | B27: =IF(A27<=01_因子設定!$B$23,INDEX(02_実験計画!$A$5:$A$28,MATCH(A27,02_実験計画!$M$5:$M$28,0)),"") | C27: =IF(B27="","",INDEX(02_実験計画!$B$5:$B$28,B27)) | D27: =IF($B27="","",INDEX(02_実験計画!$G$5:$G$28,$B27)) | E27: =IF($B27="","",INDEX(02_実験計画!$H$5:$H$28,$B27)) | F27: =IF($B27="","",INDEX(02_実験計画!$I$5:$I$28,$B27)) | G27: =IF(OR(B27="",01_因子設定!$B$25=0),"",INDEX(D27:F27,01_因子設定!$B$25))
A28: 24 | B28: =IF(A28<=01_因子設定!$B$23,INDEX(02_実験計画!$A$5:$A$28,MATCH(A28,02_実験計画!$M$5:$M$28,0)),"") | C28: =IF(B28="","",INDEX(02_実験計画!$B$5:$B$28,B28)) | D28: =IF($B28="","",INDEX(02_実験計画!$G$5:$G$28,$B28)) | E28: =IF($B28="","",INDEX(02_実験計画!$H$5:$H$28,$B28)) | F28: =IF($B28="","",INDEX(02_実験計画!$I$5:$I$28,$B28)) | G28: =IF(OR(B28="",01_因子設定!$B$25=0),"",INDEX(D28:F28,01_因子設定!$B$25))

Sheet 04_回帰ANOVA
A1: 04 2次回帰モデルとANOVA（コード化単位）
A2: B列を0にすると、その項を除外して再計算（モデル縮小）。切片は常に1。
A5: 項 | B5: 使用(1/0) | C5: 係数 | D5: 標準誤差 | E5: t値 | F5: p値 | G5: 有意 | H5: 階層性チェック | J5: 統計量 | K5: 値
A6: 切片 | B6: 1 | C6: =IF(B6=1,_XtX!M45,0) -> 48.380909 | D6: =IF(B6=1,SQRT($K$13*INDEX(_XtX!$B$58:$K$67,1,1)),"") -> 0.17634911 | E6: =IF(B6=1,C6/D6,"") -> 274.34734 | F6: =IF(B6=1,TDIST(ABS(E6),$K$8,2),"") -> 1.0181894e-20 | G6: =IF(F6="","",IF(F6<0.01,"**",IF(F6<0.05,"*",IF(F6<0.1,"△","")))) -> ** | J6: n（実験数） | K6: =SUM(_XtX!A5:A28) -> 20
A7: X1 | B7: 1 | C7: =IF(B7=1,_XtX!M46,0) -> 2.62 | D7: =IF(B7=1,SQRT($K$13*INDEX(_XtX!$B$58:$K$67,2,2)),"") -> 0.16221759 | E7: =IF(B7=1,C7/D7,"") -> 16.151146 | F7: =IF(B7=1,TDIST(ABS(E7),$K$8,2),"") -> 1.7146298e-08 | G7: =IF(F7="","",IF(F7<0.01,"**",IF(F7<0.05,"*",IF(F7<0.1,"△","")))) -> ** | J7: p（項数） | K7: =SUM($B$6:$B$15) -> 10
A8: X2 | B8: 1 | C8: =IF(B8=1,_XtX!M47,0) -> 2.07 | D8: =IF(B8=1,SQRT($K$13*INDEX(_XtX!$B$58:$K$67,3,3)),"") -> 0.16221759 | E8: =IF(B8=1,C8/D8,"") -> 12.760639 | F8: =IF(B8=1,TDIST(ABS(E8),$K$8,2),"") -> 1.6356809e-07 | G8: =IF(F8="","",IF(F8<0.01,"**",IF(F8<0.05,"*",IF(F8<0.1,"△","")))) -> ** | J8: 残差自由度 | K8: =K6-K7 -> 10
A9: X3 | B9: 1 | C9: =IF(B9=1,_XtX!M48,0) -> 1.38 | D9: =IF(B9=1,SQRT($K$13*INDEX(_XtX!$B$58:$K$67,4,4)),"") -> 0.16221759 | E9: =IF(B9=1,C9/D9,"") -> 8.5070924 | F9: =IF(B9=1,TDIST(ABS(E9),$K$8,2),"") -> 6.846328e-06 | G9: =IF(F9="","",IF(F9<0.01,"**",IF(F9<0.05,"*",IF(F9<0.1,"△","")))) -> ** | J9: SSE | K9: =SUMSQ(_XtX!P5:P28) -> 2.6314545
A10: X1·X2 | B10: 1 | C10: =IF(B10=1,_XtX!M49,0) -> 1.225 | D10: =IF(B10=1,SQRT($K$13*INDEX(_XtX!$B$58:$K$67,5,5)),"") -> 0.18136478 | E10: =IF(B10=1,C10/D10,"") -> 6.7543435 | F10: =IF(B10=1,TDIST(ABS(E10),$K$8,2),"") -> 5.0151792e-05 | G10: =IF(F10="","",IF(F10<0.01,"**",IF(F10<0.05,"*",IF(F10<0.1,"△","")))) -> ** | H10: =IF(AND(B10=1,OR($B$7=0,$B$8=0)),"主効果が除外されています","") | J10: Yの平均 | K10: =SUMPRODUCT(_XtX!L5:L28,_XtX!A5:A28)/K6 -> 45.54
A11: X1·X3 | B11: 1 | C11: =IF(B11=1,_XtX!M50,0) -> -0.15 | D11: =IF(B11=1,SQRT($K$13*INDEX(_XtX!$B$58:$K$67,6,6)),"") -> 0.18136478 | E11: =IF(B11=1,C11/D11,"") -> -0.82706247 | F11: =IF(B11=1,TDIST(ABS(E11),$K$8,2),"") -> 0.42749604 | G11: =IF(F11="","",IF(F11<0.01,"**",IF(F11<0.05,"*",IF(F11<0.1,"△","")))) | H11: =IF(AND(B11=1,OR($B$7=0,$B$9=0)),"主効果が除外されています","") | J11: SST | K11: =SUMPRODUCT(_XtX!A5:A28,(_XtX!L5:L28-K10)^2) -> 267.088
A12: X2·X3 | B12: 1 | C12: =IF(B12=1,_XtX!M51,0) -> 0.45 | D12: =IF(B12=1,SQRT($K$13*INDEX(_XtX!$B$58:$K$67,7,7)),"") -> 0.18136478 | E12: =IF(B12=1,C12/D12,"") -> 2.4811874 | F12: =IF(B12=1,TDIST(ABS(E12),$K$8,2),"") -> 0.032476715 | G12: =IF(F12="","",IF(F12<0.01,"**",IF(F12<0.05,"*",IF(F12<0.1,"△","")))) -> * | H12: =IF(AND(B12=1,OR($B$8=0,$B$9=0)),"主効果が除外されています","") | J12: SSR | K12: =K11-K9 -> 264.45655
A13: X1² | B13: 1 | C13: =IF(B13=1,_XtX!M52,0) -> -2.4772727 | D13: =IF(B13=1,SQRT($K$13*INDEX(_XtX!$B$58:$K$67,8,8)),"") -> 0.3093368 | E13: =IF(B13=1,C13/D13,"") -> -8.008335 | F13: =IF(B13=1,TDIST(ABS(E13),$K$8,2),"") -> 1.1668017e-05 | G13: =IF(F13="","",IF(F13<0.01,"**",IF(F13<0.05,"*",IF(F13<0.1,"△","")))) -> ** | H13: =IF(AND(B13=1,OR($B$7=0)),"主効果が除外されています","") | J13: MSE | K13: =K9/K8 -> 0.26314545
A14: X2² | B14: 1 | C14: =IF(B14=1,_XtX!M53,0) -> -2.0272727 | D14: =IF(B14=1,SQRT($K$13*INDEX(_XtX!$B$58:$K$67,9,9)),"") -> 0.3093368 | E14: =IF(B14=1,C14/D14,"") -> -6.5536099 | F14: =IF(B14=1,TDIST(ABS(E14),$K$8,2),"") -> 6.4434894e-05 | G14: =IF(F14="","",IF(F14<0.01,"**",IF(F14<0.05,"*",IF(F14<0.1,"△","")))) -> ** | H14: =IF(AND(B14=1,OR($B$8=0)),"主効果が除外されています","") | J14: s（残差標準偏差） | K14: =SQRT(K13) -> 0.51297705
A15: X3² | B15: 1 | C15: =IF(B15=1,_XtX!M54,0) -> -1.1772727 | D15: =IF(B15=1,SQRT($K$13*INDEX(_XtX!$B$58:$K$67,10,10)),"") -> 0.3093368 | E15: =IF(B15=1,C15/D15,"") -> -3.8057959 | F15: =IF(B15=1,TDIST(ABS(E15),$K$8,2),"") -> 0.0034528824 | G15: =IF(F15="","",IF(F15<0.01,"**",IF(F15<0.05,"*",IF(F15<0.1,"△","")))) -> ** | H15: =IF(AND(B15=1,OR($B$9=0)),"主効果が除外されています","") | J15: R² | K15: =1-K9/K11 -> 0.99014761
J16: 調整済みR² | K16: =1-(K9/K8)/(K11/(K6-1)) -> 0.98128046
A17: 有意：** p<0.01 * p<0.05 △ p<0.1。p値だけで機械的に削らず、技術的な意味と階層性を優先。 | J17: PRESS | K17: =SUMPRODUCT(_XtX!A5:A28,(_XtX!P5:P28/(1-_XtX!N5:N28))^2) -> 13.569427
J18: 予測R² | K18: =1-K17/K11 -> 0.94919492
J19: t値（工程窓・最適化用） | K19: =IF(01_因子設定!$B$13="目標値",TINV(1-01_因子設定!B17,K8),TINV(2*(1-01_因子設定!B17),K8)) -> 1.8124611
J20: Y未入力数 | K20: =SUMPRODUCT((03_実験結果!$A$5:$A$28<=01_因子設定!$B$23)*(03_実験結果!$H$5:$H$28="")) -> 0
J21: 中心点の数 | K21: =COUNTIF(02_実験計画!B5:B28,"中心点") -> 6
J22: 中心点Yの平均 | K22: =IFERROR(AVERAGEIF(02_実験計画!B5:B28,"中心点",02_実験計画!$N$5:$N$28),0) -> 48.45
J23: t値（両側・確認実験用） | K23: =TINV(1-01_因子設定!B17,K8) -> 2.2281389
J24: 工程窓用t：最大化・最小化＝片側（信頼水準95%なら t0.95）、目標値＝両側（t0.975）
A25: 要因 | B25: 自由度 | C25: 平方和 | D25: 平均平方 | E25: F値 | F25: p値 | G25: 判定
A26: 回帰 | B26: =K7-1 -> 9 | C26: =K12 -> 264.45655 | D26: =C26/B26 -> 29.384061 | E26: =D26/D27 -> 111.66471 | F26: =FDIST(E26,B26,B27) -> 7.7084534e-09 | G26: =IF(F26<0.05,"有意","有意でない") -> 有意
A27: 残差 | B27: =K8 -> 10 | C27: =K9 -> 2.6314545 | D27: =K13 -> 0.26314545
A28: 適合度の欠如 | B28: =B27-B29 -> 5 | C28: =C27-C29 -> 1.0364545 | D28: =IF(B28>0,C28/B28,"") -> 0.20729091 | E28: =IF(AND(B28>0,B29>0),D28/D29,"") -> 0.64981476 | F28: =IF(E28="","",FDIST(E28,B28,B29)) -> 0.67613857 | G28: =IF(F28="","検定不可",IF(F28<0.05,"有意（不適合）","有意でない（適合）")) -> 有意でない（適合）
A29: 純誤差 | B29: =MAX(K21-1,0) -> 5 | C29: =SUMPRODUCT((02_実験計画!$B$5:$B$28="中心点")*(02_実験計画!$N$5:$N$28-K22)^2) -> 1.595 | D29: =IF(B29>0,C29/B29,"") -> 0.319
A30: 合計 | B30: =K6-1 -> 19 | C30: =K11 -> 267.088
A33: 判断ゲート
A34: 計画の安全性 | B34: =IF(LEFT(01_因子設定!$B$32,1)="×","× 計画が安全限界を超過（01参照）→ 計画を変更してから実験する","○ 全実験点が安全限界内") -> ○ 全実験点が安全限界内
A35: ランダマイズ | B35: =IF(01_因子設定!$B$24="変更困難因子でグループ化",IF(01_因子設定!$B$25>0,"△ 分割区画の順序で実施。この解析は完全ランダムとみなした近似で、変更困難因子のp値は小さく（有意に）出やすい → 正式にはJMP/R等で分割区画解析","△ グループ化を選んでいるが変更困難因子に○がない（完全ランダムとして生成）"),IF(01_因子設定!$B$25>0,"△ 変更困難因子に○があるが完全ランダムで生成。現場で実施できるか確認（できなければグループ化＋正式解析はJMP/R等）","○ 完全ランダム")) -> △ 変更困難因子に○があるが完全ランダムで生成。現場で実施できるか確認（できなければグループ化＋正式解析はJMP/R等）
A36: データ | B36: =IF(K20>0,"× Yが"&K20&"件未入力 → 結果は無効","○ 全件入力済") -> ○ 全件入力済
A37: 回帰の有意性 | B37: =IF(F26<0.05,"○ 回帰は有意","× 有意でない → 因子・範囲の見直し。最適化に進まない") -> ○ 回帰は有意
A38: 適合度の欠如 | B38: =IF(F28="","－ 純誤差がないため検定不可（中心点を増やす）",IF(F28<0.05,"× 2次モデルで説明しきれない → 変換・領域縮小・因子追加を検討","○ 2次モデルで説明できている")) -> ○ 2次モデルで説明できている
A39: R²と予測R² | B39: =IF(K15-K18>0.2,"△ 差が0.2超 → 過学習の可能性。不要項の除外を検討","○ 差は0.2以内") -> ○ 差は0.2以内
A40: 残差 | B40: ="05_残差診断のグラフで、パターン・外れ値がないことを目視確認" -> 05_残差診断のグラフで、パターン・外れ値がないことを目視確認
A42: ×がなく、△の内容を理解・記録してから 06（正準解析）→07（最適化）→08（工程窓）へ進みます。

Sheet 05_残差診断
A1: 05 残差診断
A2: スチューデント化残差の絶対値が3超は要確認（測定ミス・異常の可能性）。消す前に原因を調べる。
A4: 標準順 | B4: 実験順 | C4: 使用 | D4: Y実測 | E4: 予測 | F4: 残差 | G4: 標準化残差 | H4: てこ比h | I4: スチューデント化残差 | J4: 判定 | L4: k | M4: 採用k | N4: 標準順 | O4: 予測 | P4: 残差 | Q4: 実験順 | R4: 残差(昇順) | S4: 理論分位点 | T4: 実測
A5: 1 | B5: =02_実験計画!M5 -> 3 | C5: =02_実験計画!C5 -> 1 | D5: =IF(C5=1,_XtX!L5,"") -> 38.4 | E5: =IF(C5=1,_XtX!O5,"") -> 38.154091 | F5: =IF(C5=1,D5-E5,"") -> 0.24590909 | G5: =IF(C5=1,F5/04_回帰ANOVA!$K$14,"") -> 0.4793764 | H5: =IF(C5=1,_XtX!N5,"") -> 0.79318182 | I5: =IF(C5=1,IF(H5<0.9999,F5/(04_回帰ANOVA!$K$14*SQRT(1-H5)),0),"") -> 1.0541012 | J5: =IF(C5=1,IF(ABS(I5)>3,"要確認",IF(ABS(I5)>2,"注意","")),"") | L5: 1 | M5: =MIN(L5,04_回帰ANOVA!$K$6) -> 1 | N5: =MATCH(M5,$B$5:$B$28,0) -> 14 | O5: =INDEX($E$5:$E$28,N5) -> 48.583636 | P5: =INDEX($F$5:$F$28,N5) -> -0.28363636 | Q5: =M5 -> 1 | R5: =SMALL($F$5:$F$28,M5) -> -0.58363636 | S5: =NORMSINV((M5-0.375)/(04_回帰ANOVA!$K$6+0.25)) -> -1.8682417 | T5: =INDEX($D$5:$D$28,N5) -> 48.3
A6: 2 | B6: =02_実験計画!M6 -> 5 | C6: =02_実験計画!C6 -> 1 | D6: =IF(C6=1,_XtX!L6,"") -> 41.2 | E6: =IF(C6=1,_XtX!O6,"") -> 41.244091 | F6: =IF(C6=1,D6-E6,"") -> -0.044090909 | G6: =IF(C6=1,F6/04_回帰ANOVA!$K$14,"") -> -0.085951036 | H6: =IF(C6=1,_XtX!N6,"") -> 0.79318182 | I6: =IF(C6=1,IF(H6<0.9999,F6/(04_回帰ANOVA!$K$14*SQRT(1-H6)),0),"") -> -0.1889978 | J6: =IF(C6=1,IF(ABS(I6)>3,"要確認",IF(ABS(I6)>2,"注意","")),"") | L6: 2 | M6: =MIN(L6,04_回帰ANOVA!$K$6) -> 2 | N6: =MATCH(M6,$B$5:$B$28,0) -> 15 | O6: =INDEX($E$5:$E$28,N6) -> 48.380909 | P6: =INDEX($F$5:$F$28,N6) -> 0.11909091 | Q6: =M6 -> 2 | R6: =SMALL($F$5:$F$28,M6) -> -0.48090909 | S6: =NORMSINV((M6-0.375)/(04_回帰ANOVA!$K$6+0.25)) -> -1.4034126 | T6: =INDEX($D$5:$D$28,N6) -> 48.5
A7: 3 | B7: =02_実験計画!M7 -> 7 | C7: =02_実験計画!C7 -> 1 | D7: =IF(C7=1,_XtX!L7,"") -> 38.6 | E7: =IF(C7=1,_XtX!O7,"") -> 38.944091 | F7: =IF(C7=1,D7-E7,"") -> -0.34409091 | G7: =IF(C7=1,F7/04_回帰ANOVA!$K$14,"") -> -0.67077252 | H7: =IF(C7=1,_XtX!N7,"") -> 0.79318182 | I7: =IF(C7=1,IF(H7<0.9999,F7/(04_回帰ANOVA!$K$14*SQRT(1-H7)),0),"") -> -1.4749622 | J7: =IF(C7=1,IF(ABS(I7)>3,"要確認",IF(ABS(I7)>2,"注意","")),"") | L7: 3 | M7: =MIN(L7,04_回帰ANOVA!$K$6) -> 3 | N7: =MATCH(M7,$B$5:$B$28,0) -> 1 | O7: =INDEX($E$5:$E$28,N7) -> 38.154091 | P7: =INDEX($F$5:$F$28,N7) -> 0.24590909 | Q7: =M7 -> 3 | R7: =SMALL($F$5:$F$28,M7) -> -0.48090909 | S7: =NORMSINV((M7-0.375)/(04_回帰ANOVA!$K$6+0.25)) -> -1.1281436 | T7: =INDEX($D$5:$D$28,N7) -> 38.4
A8: 4 | B8: =02_実験計画!M8 -> 11 | C8: =02_実験計画!C8 -> 1 | D8: =IF(C8=1,_XtX!L8,"") -> 47 | E8: =IF(C8=1,_XtX!O8,"") -> 46.934091 | F8: =IF(C8=1,D8-E8,"") -> 0.065909091 | G8: =IF(C8=1,F8/04_回帰ANOVA!$K$14,"") -> 0.12848351 | H8: =IF(C8=1,_XtX!N8,"") -> 0.79318182 | I8: =IF(C8=1,IF(H8<0.9999,F8/(04_回帰ANOVA!$K$14*SQRT(1-H8)),0),"") -> 0.28252249 | J8: =IF(C8=1,IF(ABS(I8)>3,"要確認",IF(ABS(I8)>2,"注意","")),"") | L8: 4 | M8: =MIN(L8,04_回帰ANOVA!$K$6) -> 4 | N8: =MATCH(M8,$B$5:$B$28,0) -> 7 | O8: =INDEX($E$5:$E$28,N8) -> 42.904091 | P8: =INDEX($F$5:$F$28,N8) -> 0.095909091 | Q8: =M8 -> 4 | R8: =SMALL($F$5:$F$28,M8) -> -0.34409091 | S8: =NORMSINV((M8-0.375)/(04_回帰ANOVA!$K$6+0.25)) -> -0.91913552 | T8: =INDEX($D$5:$D$28,N8) -> 43
A9: 5 | B9: =02_実験計画!M9 -> 20 | C9: =02_実験計画!C9 -> 1 | D9: =IF(C9=1,_XtX!L9,"") -> 40.3 | E9: =IF(C9=1,_XtX!O9,"") -> 40.314091 | F9: =IF(C9=1,D9-E9,"") -> -0.014090909 | G9: =IF(C9=1,F9/04_回帰ANOVA!$K$14,"") -> -0.027468888 | H9: =IF(C9=1,_XtX!N9,"") -> 0.79318182 | I9: =IF(C9=1,IF(H9<0.9999,F9/(04_回帰ANOVA!$K$14*SQRT(1-H9)),0),"") -> -0.06040136 | J9: =IF(C9=1,IF(ABS(I9)>3,"要確認",IF(ABS(I9)>2,"注意","")),"") | L9: 5 | M9: =MIN(L9,04_回帰ANOVA!$K$6) -> 5 | N9: =MATCH(M9,$B$5:$B$28,0) -> 2 | O9: =INDEX($E$5:$E$28,N9) -> 41.244091 | P9: =INDEX($F$5:$F$28,N9) -> -0.044090909 | Q9: =M9 -> 5 | R9: =SMALL($F$5:$F$28,M9) -> -0.28363636 | S9: =NORMSINV((M9-0.375)/(04_回帰ANOVA!$K$6+0.25)) -> -0.74414274 | T9: =INDEX($D$5:$D$28,N9) -> 41.2
A10: 6 | B10: =02_実験計画!M10 -> 13 | C10: =02_実験計画!C10 -> 1 | D10: =IF(C10=1,_XtX!L10,"") -> 43.2 | E10: =IF(C10=1,_XtX!O10,"") -> 42.804091 | F10: =IF(C10=1,D10-E10,"") -> 0.39590909 | G10: =IF(C10=1,F10/04_回帰ANOVA!$K$14,"") -> 0.77178714 | H10: =IF(C10=1,_XtX!N10,"") -> 0.79318182 | I10: =IF(C10=1,IF(H10<0.9999,F10/(04_回帰ANOVA!$K$14*SQRT(1-H10)),0),"") -> 1.6970834 | J10: =IF(C10=1,IF(ABS(I10)>3,"要確認",IF(ABS(I10)>2,"注意","")),"") | L10: 6 | M10: =MIN(L10,04_回帰ANOVA!$K$6) -> 6 | N10: =MATCH(M10,$B$5:$B$28,0) -> 16 | O10: =INDEX($E$5:$E$28,N10) -> 48.380909 | P10: =INDEX($F$5:$F$28,N10) -> -0.18090909 | Q10: =M10 -> 6 | R10: =SMALL($F$5:$F$28,M10) -> -0.22363636 | S10: =NORMSINV((M10-0.375)/(04_回帰ANOVA!$K$6+0.25)) -> -0.5894558 | T10: =INDEX($D$5:$D$28,N10) -> 48.2
A11: 7 | B11: =02_実験計画!M11 -> 4 | C11: =02_実験計画!C11 -> 1 | D11: =IF(C11=1,_XtX!L11,"") -> 43 | E11: =IF(C11=1,_XtX!O11,"") -> 42.904091 | F11: =IF(C11=1,D11-E11,"") -> 0.095909091 | G11: =IF(C11=1,F11/04_回帰ANOVA!$K$14,"") -> 0.18696566 | H11: =IF(C11=1,_XtX!N11,"") -> 0.79318182 | I11: =IF(C11=1,IF(H11<0.9999,F11/(04_回帰ANOVA!$K$14*SQRT(1-H11)),0),"") -> 0.41111894 | J11: =IF(C11=1,IF(ABS(I11)>3,"要確認",IF(ABS(I11)>2,"注意","")),"") | L11: 7 | M11: =MIN(L11,04_回帰ANOVA!$K$6) -> 7 | N11: =MATCH(M11,$B$5:$B$28,0) -> 3 | O11: =INDEX($E$5:$E$28,N11) -> 38.944091 | P11: =INDEX($F$5:$F$28,N11) -> -0.34409091 | Q11: =M11 -> 7 | R11: =SMALL($F$5:$F$28,M11) -> -0.19409091 | S11: =NORMSINV((M11-0.375)/(04_回帰ANOVA!$K$6+0.25)) -> -0.44776752 | T11: =INDEX($D$5:$D$28,N11) -> 38.6
A12: 8 | B12: =02_実験計画!M12 -> 15 | C12: =02_実験計画!C12 -> 1 | D12: =IF(C12=1,_XtX!L12,"") -> 50.1 | E12: =IF(C12=1,_XtX!O12,"") -> 50.294091 | F12: =IF(C12=1,D12-E12,"") -> -0.19409091 | G12: =IF(C12=1,F12/04_回帰ANOVA!$K$14,"") -> -0.37836178 | H12: =IF(C12=1,_XtX!N12,"") -> 0.79318182 | I12: =IF(C12=1,IF(H12<0.9999,F12/(04_回帰ANOVA!$K$14*SQRT(1-H12)),0),"") -> -0.83198003 | J12: =IF(C12=1,IF(ABS(I12)>3,"要確認",IF(ABS(I12)>2,"注意","")),"") | L12: 8 | M12: =MIN(L12,04_回帰ANOVA!$K$6) -> 8 | N12: =MATCH(M12,$B$5:$B$28,0) -> 9 | O12: =INDEX($E$5:$E$28,N12) -> 43.283636 | P12: =INDEX($F$5:$F$28,N12) -> 0.016363636 | Q12: =M12 -> 8 | R12: =SMALL($F$5:$F$28,M12) -> -0.18090909 | S12: =NORMSINV((M12-0.375)/(04_回帰ANOVA!$K$6+0.25)) -> -0.31457229 | T12: =INDEX($D$5:$D$28,N12) -> 43.3
A13: 9 | B13: =02_実験計画!M13 -> 8 | C13: =02_実験計画!C13 -> 1 | D13: =IF(C13=1,_XtX!L13,"") -> 43.3 | E13: =IF(C13=1,_XtX!O13,"") -> 43.283636 | F13: =IF(C13=1,D13-E13,"") -> 0.016363636 | G13: =IF(C13=1,F13/04_回帰ANOVA!$K$14,"") -> 0.031899354 | H13: =IF(C13=1,_XtX!N13,"") -> 0.49090909 | I13: =IF(C13=1,IF(H13<0.9999,F13/(04_回帰ANOVA!$K$14*SQRT(1-H13)),0),"") -> 0.044707894 | J13: =IF(C13=1,IF(ABS(I13)>3,"要確認",IF(ABS(I13)>2,"注意","")),"") | L13: 9 | M13: =MIN(L13,04_回帰ANOVA!$K$6) -> 9 | N13: =MATCH(M13,$B$5:$B$28,0) -> 20 | O13: =INDEX($E$5:$E$28,N13) -> 48.380909 | P13: =INDEX($F$5:$F$28,N13) -> -0.48090909 | Q13: =M13 -> 9 | R13: =SMALL($F$5:$F$28,M13) -> -0.044090909 | S13: =NORMSINV((M13-0.375)/(04_回帰ANOVA!$K$6+0.25)) -> -0.18675612 | T13: =INDEX($D$5:$D$28,N13) -> 47.9
A14: 10 | B14: =02_実験計画!M14 -> 12 | C14: =02_実験計画!C14 -> 1 | D14: =IF(C14=1,_XtX!L14,"") -> 48.3 | E14: =IF(C14=1,_XtX!O14,"") -> 48.523636 | F14: =IF(C14=1,D14-E14,"") -> -0.22363636 | G14: =IF(C14=1,F14/04_回帰ANOVA!$K$14,"") -> -0.43595783 | H14: =IF(C14=1,_XtX!N14,"") -> 0.49090909 | I14: =IF(C14=1,IF(H14<0.9999,F14/(04_回帰ANOVA!$K$14*SQRT(1-H14)),0),"") -> -0.61100788 | J14: =IF(C14=1,IF(ABS(I14)>3,"要確認",IF(ABS(I14)>2,"注意","")),"") | L14: 10 | M14: =MIN(L14,04_回帰ANOVA!$K$6) -> 10 | N14: =MATCH(M14,$B$5:$B$28,0) -> 13 | O14: =INDEX($E$5:$E$28,N14) -> 45.823636 | P14: =INDEX($F$5:$F$28,N14) -> 0.076363636 | Q14: =M14 -> 10 | R14: =SMALL($F$5:$F$28,M14) -> -0.014090909 | S14: =NORMSINV((M14-0.375)/(04_回帰ANOVA!$K$6+0.25)) -> -0.061931623 | T14: =INDEX($D$5:$D$28,N14) -> 45.9
A15: 11 | B15: =02_実験計画!M15 -> 16 | C15: =02_実験計画!C15 -> 1 | D15: =IF(C15=1,_XtX!L15,"") -> 43.7 | E15: =IF(C15=1,_XtX!O15,"") -> 44.283636 | F15: =IF(C15=1,D15-E15,"") -> -0.58363636 | G15: =IF(C15=1,F15/04_回帰ANOVA!$K$14,"") -> -1.1377436 | H15: =IF(C15=1,_XtX!N15,"") -> 0.49090909 | I15: =IF(C15=1,IF(H15<0.9999,F15/(04_回帰ANOVA!$K$14*SQRT(1-H15)),0),"") -> -1.5945816 | J15: =IF(C15=1,IF(ABS(I15)>3,"要確認",IF(ABS(I15)>2,"注意","")),"") | L15: 11 | M15: =MIN(L15,04_回帰ANOVA!$K$6) -> 11 | N15: =MATCH(M15,$B$5:$B$28,0) -> 4 | O15: =INDEX($E$5:$E$28,N15) -> 46.934091 | P15: =INDEX($F$5:$F$28,N15) -> 0.065909091 | Q15: =M15 -> 11 | R15: =SMALL($F$5:$F$28,M15) -> 0.016363636 | S15: =NORMSINV((M15-0.375)/(04_回帰ANOVA!$K$6+0.25)) -> 0.061931623 | T15: =INDEX($D$5:$D$28,N15) -> 47
A16: 12 | B16: =02_実験計画!M16 -> 19 | C16: =02_実験計画!C16 -> 1 | D16: =IF(C16=1,_XtX!L16,"") -> 48.8 | E16: =IF(C16=1,_XtX!O16,"") -> 48.423636 | F16: =IF(C16=1,D16-E16,"") -> 0.37636364 | G16: =IF(C16=1,F16/04_回帰ANOVA!$K$14,"") -> 0.73368513 | H16: =IF(C16=1,_XtX!N16,"") -> 0.49090909 | I16: =IF(C16=1,IF(H16<0.9999,F16/(04_回帰ANOVA!$K$14*SQRT(1-H16)),0),"") -> 1.0282816 | J16: =IF(C16=1,IF(ABS(I16)>3,"要確認",IF(ABS(I16)>2,"注意","")),"") | L16: 12 | M16: =MIN(L16,04_回帰ANOVA!$K$6) -> 12 | N16: =MATCH(M16,$B$5:$B$28,0) -> 10 | O16: =INDEX($E$5:$E$28,N16) -> 48.523636 | P16: =INDEX($F$5:$F$28,N16) -> -0.22363636 | Q16: =M16 -> 12 | R16: =SMALL($F$5:$F$28,M16) -> 0.065909091 | S16: =NORMSINV((M16-0.375)/(04_回帰ANOVA!$K$6+0.25)) -> 0.18675612 | T16: =INDEX($D$5:$D$28,N16) -> 48.3
... A28: 24 | B28: =02_実験計画!M28 | C28: =02_実験計画!C28 -> 0 | D28: =IF(C28=1,_XtX!L28,"") | E28: =IF(C28=1,_XtX!O28,"") | F28: =IF(C28=1,D28-E28,"") | G28: =IF(C28=1,F28/04_回帰ANOVA!$K$14,"") | H28: =IF(C28=1,_XtX!N28,"") | I28: =IF(C28=1,IF(H28<0.9999,F28/(04_回帰ANOVA!$K$14*SQRT(1-H28)),0),"") | J28: =IF(C28=1,IF(ABS(I28)>3,"要確認",IF(ABS(I28)>2,"注意","")),"") | L28: 24 | M28: =MIN(L28,04_回帰ANOVA!$K$6) -> 20 | N28: =MATCH(M28,$B$5:$B$28,0) -> 5 | O28: =INDEX($E$5:$E$28,N28) -> 40.314091 | P28: =INDEX($F$5:$F$28,N28) -> -0.014090909 | Q28: =M28 -> 20 | R28: =SMALL($F$5:$F$28,M28) -> 0.91909091 | S28: =NORMSINV((M28-0.375)/(04_回帰ANOVA!$K$6+0.25)) -> 1.8682417 | T28: =INDEX($D$5:$D$28,N28) -> 40.3
V37: 見方：①残差vs予測に漏斗形・曲線パターンがない ②正規確率がほぼ直線 ③実験順に傾向（ドリフト）がない ④実測vs予測が45°線上

Sheet 06_正準解析
A1: 06 正準解析（停留点の種類と位置）
A2: 最適化の前に必ず確認：停留点が最大点・最小点・鞍点のどれか、実験領域の内か外か。
A5: 2次係数行列 B | F5: 1次係数 b
A6: X1 | B6: =04_回帰ANOVA!C13 -> -2.4772727 | C6: =04_回帰ANOVA!C10/2 -> 0.6125 | D6: =04_回帰ANOVA!C11/2 -> -0.075 | F6: =04_回帰ANOVA!C7 -> 2.62
A7: X2 | B7: =04_回帰ANOVA!C10/2 -> 0.6125 | C7: =04_回帰ANOVA!C14 -> -2.0272727 | D7: =04_回帰ANOVA!C12/2 -> 0.225 | F7: =04_回帰ANOVA!C8 -> 2.07
A8: X3 | B8: =04_回帰ANOVA!C11/2 -> -0.075 | C8: =04_回帰ANOVA!C12/2 -> 0.225 | D8: =04_回帰ANOVA!C15 -> -1.1772727 | F8: =04_回帰ANOVA!C9 -> 1.38
A12: 因子 | B12: 停留点(コード) | C12: 停留点(実値) | D12: 単位
A13: =01_因子設定!B5 -> 炉温 | B13: =IFERROR(-0.5*INDEX(MMULT(MINVERSE($B$6:$D$8),$F$6:$F$8),1,1),"算出不可") -> 0.70579274 | C13: =IF(ISNUMBER(B13),01_因子設定!G5+B13*01_因子設定!H5,"") -> 72.057927 | D13: =01_因子設定!D5 -> ℃
A14: =01_因子設定!B6 -> 乾燥時間 | B14: =IFERROR(-0.5*INDEX(MMULT(MINVERSE($B$6:$D$8),$F$6:$F$8),2,1),"算出不可") -> 0.80082508 | C14: =IF(ISNUMBER(B14),01_因子設定!G6+B14*01_因子設定!H6,"") -> 38.008251 | D14: =01_因子設定!D6 -> min
A15: =01_因子設定!B7 -> 循環風速 | B15: =IFERROR(-0.5*INDEX(MMULT(MINVERSE($B$6:$D$8),$F$6:$F$8),3,1),"算出不可") -> 0.6941902 | C15: =IF(ISNUMBER(B15),01_因子設定!G7+B15*01_因子設定!H7,"") -> 2.6941902 | D15: =01_因子設定!D7 -> m/s
A18: 停留点での予測Y | B18: =IF(ISNUMBER(B13),04_回帰ANOVA!C6+0.5*SUMPRODUCT(F6:F8,B13:B15),"") -> 50.613343
A19: 中心からの距離 | B19: =IF(ISNUMBER(B13),SQRT(SUMSQ(B13:B15)),"") -> 1.273328
A20: 実験領域内か | B20: =IF(NOT(ISNUMBER(B13)),"－",IF(01_因子設定!$B$20="Box-Behnken",IF(B19<=SQRT(2),"領域内","領域外（外挿）"),IF(01_因子設定!$B$20="回転可能CCD(α=1.682)",IF(B19<=1.68179283050743,"領域内","領域外（外挿）"),IF(MAX(ABS(B13),ABS(B14),ABS(B15))<=1,"領域内","領域外（外挿）")))) -> 領域内
A22: 固有値 | B22: 値
A23: λ1 | B23: =SMALL((_eig!B125~_eig!C126~_eig!D127),1) -> -2.9256808
A24: λ2 | B24: =SMALL((_eig!B125~_eig!C126~_eig!D127),2) -> -1.640503
A25: λ3 | B25: =SMALL((_eig!B125~_eig!C126~_eig!D127),3) -> -1.1156344
A28: 停留点の種類 | B28: =IF(MAX(B23:B25)<0,"最大点",IF(MIN(B23:B25)>0,"最小点","鞍点")) -> 最大点
A29: 尾根（リッジ） | B29: =IF(MIN(ABS(B23),ABS(B24),ABS(B25))<0.1*MAX(ABS(B23),ABS(B24),ABS(B25)),"あり：ほぼ平らな方向がある → その方向には工程窓を広く取れる可能性","なし：全方向に明確な曲率") -> なし：全方向に明確な曲率
A30: 判断 | B30: =IF(NOT(ISNUMBER(B13)),"停留点を算出できない（2次項を除外している等）→ 07の探索結果を使う",IF(B20<>"領域内","停留点は実験領域外。外挿値は信用しない → 07の領域内探索結果を採用し、必要なら領域を移して追加実験",IF(OR(AND(01_因子設定!$B$13="最大化",B28="最大点"),AND(01_因子設定!$B$13="最小化",B28="最小点")),"停留点が領域内の最適点候補。07の結果と一致するか確認",IF(B28="鞍点","鞍点のため停留点は最適点ではない → 07の探索結果（領域境界上になりやすい）を採用","停留点は目的と逆向きの極値 → 07の探索結果を採用")))) -> 停留点が領域内の最適点候補。07の結果と一致するか確認
A32: 固有値はJacobi法で数値計算（_eigシート）。λが全て負→最大点、全て正→最小点、正負混在→鞍点。

Sheet 07_最適化
A1: 07 最適化（実験領域内の3次元グリッド探索）
A2: 『点予測の最適』と『予測限界で規格への余裕が最大の条件（ロバスト最適）』を並べて表示します。
A4: 項目 | B4: ロバスト最適（推奨） | C4: 点予測の最適 | E4: 説明
A5: グリッド行 | B5: =MATCH(MAX(_grid!$Y$5:$Y$4917),_grid!$Y$5:$Y$4917,0) -> 4009 | C5: =MATCH(MAX(_grid!$Z$5:$Z$4917),_grid!$Z$5:$Z$4917,0) -> 4316 | E5: ロバスト最適：規格側の予測限界（最大化なら下側限界）と規格の差が最大の条件。ばらつきを考慮した推奨条件。 点予測の最適：予測値そのものが最大（最小・目標値に最も近い）条件。境界に張り付きやすく、区間は広め。 両者が大きく違う場合、点予測の最適は『予測のばらつきが大きい場所』にある。原則ロバスト最適を採用。 判定用下限・上限：最大化・最小化は片側、目標値は両側の予測限界（04のt値を使用）。 ×の場合：規格が厳しすぎる／因子範囲が不適切／モデル誤差が大きい。範囲を移して追加実験、sの低減を検討。
A6: =01_因子設定!B5&"（コード）" -> 炉温（コード） | B6: =INDEX(_grid!$D$5:$D$4917,B$5) -> 0.625 | C6: =INDEX(_grid!$D$5:$D$4917,C$5) -> 0.75
A7: =01_因子設定!B6&"（コード）" -> 乾燥時間（コード） | B7: =INDEX(_grid!$E$5:$E$4917,B$5) -> 0.75 | C7: =INDEX(_grid!$E$5:$E$4917,C$5) -> 0.875
A8: =01_因子設定!B7&"（コード）" -> 循環風速（コード） | B8: =INDEX(_grid!$F$5:$F$4917,B$5) -> 0.625 | C8: =INDEX(_grid!$F$5:$F$4917,C$5) -> 0.75
A9: =01_因子設定!B5&"["&01_因子設定!D5&"]" -> 炉温[℃] | B9: =01_因子設定!$G$5+B6*01_因子設定!$H$5 -> 71.25 | C9: =01_因子設定!$G$5+C6*01_因子設定!$H$5 -> 72.5
A10: =01_因子設定!B6&"["&01_因子設定!D6&"]" -> 乾燥時間[min] | B10: =01_因子設定!$G$6+B7*01_因子設定!$H$6 -> 37.5 | C10: =01_因子設定!$G$6+C7*01_因子設定!$H$6 -> 38.75
A11: =01_因子設定!B7&"["&01_因子設定!D7&"]" -> 循環風速[m/s] | B11: =01_因子設定!$G$7+B8*01_因子設定!$H$7 -> 2.625 | C11: =01_因子設定!$G$7+C8*01_因子設定!$H$7 -> 2.75
A12: 予測Y | B12: =INDEX(_grid!$Q$5:$Q$4917,B$5) -> 50.592074 | C12: =INDEX(_grid!$Q$5:$Q$4917,C$5) -> 50.59919
A13: 判定用下限 | B13: =INDEX(_grid!$T$5:$T$4917,B$5) -> 49.544724 | C13: =INDEX(_grid!$T$5:$T$4917,C$5) -> 49.497266
A14: 判定用上限 | B14: =INDEX(_grid!$U$5:$U$4917,B$5) -> 51.639424 | C14: =INDEX(_grid!$U$5:$U$4917,C$5) -> 51.701114
A15: 規格への余裕 | B15: =INDEX(_grid!$W$5:$W$4917,B$5) -> 1.044724 | C15: =INDEX(_grid!$W$5:$W$4917,C$5) -> 0.99726622
A16: 判定 | B16: =IF(B15<-1E+029,"有効な点なし（安全限界・領域を確認）",IF(B15>=0,"○ 予測限界でも規格を満たす","× 予測限界では規格を満たせない")) -> ○ 予測限界でも規格を満たす | C16: =IF(C15<-1E+029,"有効な点なし（安全限界・領域を確認）",IF(C15>=0,"○ 予測限界でも規格を満たす","× 予測限界では規格を満たせない")) -> ○ 予測限界でも規格を満たす
A19: ロバスト最適の上位5候補（実値）
A20: 順位 | B20: グリッド行 | C20: =01_因子設定!B5 -> 炉温 | D20: =01_因子設定!B6 -> 乾燥時間 | E20: =01_因子設定!B7 -> 循環風速 | F20: 予測Y | G20: 判定用下限 | H20: 判定用上限 | I20: 余裕
A21: 1 | B21: =MATCH(LARGE(_grid!$Y$5:$Y$4917,1),_grid!$Y$5:$Y$4917,0) -> 4009 | C21: =01_因子設定!$G$5+INDEX(_grid!$D$5:$D$4917,$B21)*01_因子設定!$H$5 -> 71.25 | D21: =01_因子設定!$G$6+INDEX(_grid!$E$5:$E$4917,$B21)*01_因子設定!$H$6 -> 37.5 | E21: =01_因子設定!$G$7+INDEX(_grid!$F$5:$F$4917,$B21)*01_因子設定!$H$7 -> 2.625 | F21: =INDEX(_grid!$Q$5:$Q$4917,$B21) -> 50.592074 | G21: =INDEX(_grid!$T$5:$T$4917,$B21) -> 49.544724 | H21: =INDEX(_grid!$U$5:$U$4917,$B21) -> 51.639424 | I21: =INDEX(_grid!$W$5:$W$4917,$B21) -> 1.044724
