Workbook

Sheet 00_使い方
A1: 応答曲面法（RSM）ツール v1.1 ── 2因子・2次モデル
A2: 作成日 2026-09-30 ／ 同梱データは架空の乾燥炉データ（検証用） ／ 2因子版・3因子版・4因子版は別ファイル
A4: この版でできること
B5: 2因子の中心複合計画（面心／回転可能）（2因子にBox-Behnkenはない）の生成、安全限界チェック、ランダマイズ（完全ランダム／変更困難因子でグループ化した順序生成）、2次回帰・ANOVA・適合度の欠如・残差診断・モデル縮小、正準解析（停留点・固有値）、領域内の最適化（点予測／予測限界ベース）、工程窓の可視化と組合せチェック、確認実験の判定
A6: 手順と判断ゲート
A7: ① 01_因子設定 | B7: 因子名・単位・範囲（±1）・安全限界、Yの方向と規格、計画の種類、中心点数を入力。『安全限界チェック』が×の計画は実行不可。
A8: ② 02_実験計画 | B8: 標準順の計画と実験順序を確認（通常は触らない）。順序を変えたいときは乱数キーを入れ替え。
A9: ③ 03_実験結果 | B9: 実験順に実施し、Yを入力。異常があればメモ欄へ。
A10: ④ 04_回帰ANOVA | B10: 判断ゲートに×がないことを確認し、△は内容を理解して記録。不要項はB列を0にして除外（階層性に注意）。
A11: ⑤ 05_残差診断 | B11: グラフでパターン・外れ値を目視確認。外れ値は消す前に原因を調査。
A12: ⑥ 06_正準解析 | B12: 停留点が最大／最小／鞍点か、領域内か外かを確認。鞍点・領域外なら07の探索結果を採用。
A13: ⑦ 07_最適化 | B13: ロバスト最適（規格側の予測限界と規格の差が最大）を推奨条件とする。必要ならSolverで精密化。
A14: ⑧ 08_工程窓 | B14: 2因子断面の緑領域が工程窓。③の1因子窓は楽観的なので、④で運用範囲の全組合せを必ず確認。
A15: ⑨ 09_確認実験 | B15: 推奨条件で確認実験。両側予測区間内なら採用、外れたら計画・モデルを見直す。
A16: セルの色
A17: 黄色・青字 | B17: 入力セル。ほかは計算式なので編集しない。
A18: 『_』で始まるシート | B18: 計算用（編集不要）。_XtX＝回帰の行列計算、_grid＝1681点の探索、_eig＝固有値、_slice＝断面、_win＝工程窓。
A19: 前提と限界（重要）
A20: コード化単位 | B20: 回帰係数は −1〜+1 に正規化した単位。係数の大小がそのまま効果の大きさ比較になる。
A21: 予測限界の片側／両側 | B21: 工程窓・ロバスト最適は、最大化・最小化では片側の予測限界（信頼水準95%なら下側95%限界＝t0.95）、目標値では両側予測区間（t0.975）で判定。確認実験の判定は常に両側予測区間。
A22: 予測区間と許容区間 | B22: 予測区間が保証するのは『将来の1回の測定値』。量産で『ロットの大部分（例：99%）が規格内』と言うには許容区間（Tolerance Interval）が本来の指標で、予測区間より広くなる。この工程窓は量産の工程能力保証ではなく、条件設定の目安として使う。量産移行時は工程能力調査（Cpk）で確認。
A23: 探索範囲 | B23: 最適化・工程窓は ±1（要因点の範囲）内のみ。外挿はしない。
A24: 分割区画（Split-Plot） | B24: v1は分割区画の解析に対応していない。『変更困難因子でグループ化』は実験順序を作るだけで、解析は完全ランダムとみなした近似（変更困難因子のp値は小さく出やすい）。04の判断ゲートに△を表示。正式な解析はJMP・R（lme4等）で。
A25: 固有値 | B25: Jacobi法の数値計算（8回転）。2×2行列では十分収束する。
A26: この版にないもの | B26: スクリーニング（Plackett-Burman）・曲率判定・最急上昇法（v2予定）、多目的最適化（望ましさ関数）・モンテカルロ・分割区画の正式解析（v3予定）。
A27: 動作環境 | B27: Excel 2019以降または Microsoft 365（1因子窓で MAXIFS/MINIFS を使用）。マクロなし。
A28: 架空データについて | B28: 炉温55〜75℃・乾燥時間20〜40min、Y＝剥離強度（最大化、LSL=46.5）。数値はツール検証用の作り物。安全上限（炉温80℃等）も仮値なので、実案件では必ず再設定。

Sheet 01_因子設定
A1: 01 因子と目的変数の設定（2因子）
A2: 黄色セル（青字）が入力欄。架空の乾燥炉データ（接着剤塗布後の溶剤乾燥・バッチ式）を例として入れてあります。
A4: No | B4: 因子名 | C4: 記号 | D4: 単位 | E4: 下限(-1) | F4: 上限(+1) | G4: 中心(0) | H4: 半幅 | I4: 安全下限 | J4: 安全上限 | K4: 変更困難 | L4: 安全下限(コード) | M4: 安全上限(コード) | N4: 備考
A5: 1 | B5: 炉温 | C5: X1 | D5: ℃ | E5: 55 | F5: 75 | G5: =(E5+F5)/2 -> 65 | H5: =(F5-E5)/2 -> 10 | J5: 80 | K5: ○ | L5: =IF(I5="",-99,(I5-G5)/H5) -> -99 | M5: =IF(J5="",99,(J5-G5)/H5) -> 1.5 | N5: 安全上限80℃は仮値。溶剤の引火点・防爆の温度等級から必ず再設定
A6: 2 | B6: 乾燥時間 | C6: X2 | D6: min | E6: 20 | F6: 40 | G6: =(E6+F6)/2 -> 30 | H6: =(F6-E6)/2 -> 10 | I6: 10 | L6: =IF(I6="",-99,(I6-G6)/H6) -> -2 | M6: =IF(J6="",99,(J6-G6)/H6) -> 99
A10: 目的変数（Y）
A11: 名称 | B11: 剥離強度
A12: 単位 | B12: N/25mm
A13: 最適化の方向 | B13: 最大化 | C13: 最大化→LSLのみ使用 / 最小化→USLのみ / 目標値→LSL・USL・T を使用
A14: 下限規格 LSL | B14: 46.5
A15: 上限規格 USL
A16: 目標値 T
A17: 予測区間の信頼水準 | B17: 0.95 | C17: 最大化・最小化は片側の予測限界（例：95%なら下側95%限界）、目標値は両側の予測区間で工程窓を判定
A19: 実験計画
A20: 計画の種類 | B20: 面心CCD(α=1) | C20: 2因子: CCD=要因4+軸4+中心。2因子にはBox-Behnken計画はありません（面心CCD＝3水準全組合せ）
A21: 中心点の数 | B21: 5 | C21: 純誤差（適合度の欠如の検定）に使うため3以上。推奨5〜6
A22: α（軸点距離） | B22: =IF(B20="回転可能CCD(α=1.414)",1.4142135623731,1) -> 1
A23: 総実験数 N | B23: =B26+B21 -> 13
A24: ランダマイズ方式 | B24: 完全ランダム | C24: グループ化＝変更困難因子の水準ごとに実験をまとめる順序生成のみ。解析は分割区画に対応していない（04に警告表示）
A25: 変更困難因子 No | B25: =IFERROR(MATCH("○",K5:K6,0),0) -> 1
A26: 計画点数（中心点除く） | B26: =IF(B20="Box-Behnken",0,8) -> 8
A27: 安全限界チェック（計画上の最小・最大の実値）
A28: 因子 | B28: 計画の最小 | C28: 計画の最大 | D28: 安全下限 | E28: 安全上限 | F28: 判定
A29: =B5 -> 炉温 | B29: =G5-$B$22*H5 -> 55 | C29: =G5+$B$22*H5 -> 75 | D29: =IF(I5="","―",I5) -> ― | E29: =IF(J5="","―",J5) -> 80 | F29: =IF(AND(OR(I5="",B29>=I5),OR(J5="",C29<=J5)),"OK","安全限界超過") -> OK
A30: =B6 -> 乾燥時間 | B30: =G6-$B$22*H6 -> 20 | C30: =G6+$B$22*H6 -> 40 | D30: =IF(I6="","―",I6) -> 10 | E30: =IF(J6="","―",J6) -> ― | F30: =IF(AND(OR(I6="",B30>=I6),OR(J6="",C30<=J6)),"OK","安全限界超過") -> OK
A31: 総合判定 | B31: =IF(COUNTIF(F29:F30,"安全限界超過")>0,"× 安全限界を超える実験点あり → この計画は実行不可。面心CCDへ変更、または範囲を縮小","○ 全実験点が安全限界内") -> ○ 全実験点が安全限界内

Sheet 02_実験計画
A1: 02 実験計画（標準順）とランダマイズ
A2: 計画の種類・中心点数は01で選択。乱数キーを入れ替えると実験順序が変わります（=RAND()を入れ→コピー→値貼り付け）。
A4: 標準順 | B4: 区分 | C4: 使用 | D4: X1(コード) | E4: X2(コード) | F4: ="X1 "&01_因子設定!B5&"["&01_因子設定!D5&"]" -> X1 炉温[℃] | G4: ="X2 "&01_因子設定!B6&"["&01_因子設定!D6&"]" -> X2 乾燥時間[min] | H4: 安全判定 | I4: 乱数キー | J4: 並べ替えキー | K4: 実験順序 | L4: Y（03から） | N4: CCD1 | O4: CCD2 | S4: 水準(コード) | T4: グループ順位
A5: 1 | B5: =IF(A5>01_因子設定!$B$23,"未使用",IF(A5>01_因子設定!$B$26,"中心点",IF(01_因子設定!$B$20="Box-Behnken","BBD点",IF(A5<=4,"要因点","軸点")))) -> 要因点 | C5: =IF(A5<=01_因子設定!$B$23,1,0) -> 1 | D5: =IF($C5=0,0,N5*IF($A5>4,01_因子設定!$B$22,1)) -> -1 | E5: =IF($C5=0,0,O5*IF($A5>4,01_因子設定!$B$22,1)) -> -1 | F5: =IF($C5=1,01_因子設定!$G$5+D5*01_因子設定!$H$5,"") -> 55 | G5: =IF($C5=1,01_因子設定!$G$6+E5*01_因子設定!$H$6,"") -> 20 | H5: =IF(C5=0,"",IF(AND(OR(01_因子設定!$I$5="",F5>=01_因子設定!$I$5),OR(01_因子設定!$J$5="",F5<=01_因子設定!$J$5),OR(01_因子設定!$I$6="",G5>=01_因子設定!$I$6),OR(01_因子設定!$J$6="",G5<=01_因子設定!$J$6)),"OK","安全限界超過")) -> OK | I5: 0.304772 | J5: =IF(C5=0,99,IF(AND(01_因子設定!$B$24="変更困難因子でグループ化",01_因子設定!$B$25>0),VLOOKUP(ROUND(INDEX(D5:E5,01_因子設定!$B$25),6),$S$5:$T$9,2,FALSE())+I5*0.9,I5)) -> 0.304772 | K5: =IF(C5=1,SUMPRODUCT(($C$5:$C$22=1)*($J$5:$J$22<J5))+1,"") -> 4 | L5: =IF(C5=1,INDEX(03_実験結果!$G$5:$G$22,K5),0) -> 40 | N5: -1 | O5: -1 | S5: -1.414214 | T5: 3
A6: 2 | B6: =IF(A6>01_因子設定!$B$23,"未使用",IF(A6>01_因子設定!$B$26,"中心点",IF(01_因子設定!$B$20="Box-Behnken","BBD点",IF(A6<=4,"要因点","軸点")))) -> 要因点 | C6: =IF(A6<=01_因子設定!$B$23,1,0) -> 1 | D6: =IF($C6=0,0,N6*IF($A6>4,01_因子設定!$B$22,1)) -> 1 | E6: =IF($C6=0,0,O6*IF($A6>4,01_因子設定!$B$22,1)) -> -1 | F6: =IF($C6=1,01_因子設定!$G$5+D6*01_因子設定!$H$5,"") -> 75 | G6: =IF($C6=1,01_因子設定!$G$6+E6*01_因子設定!$H$6,"") -> 20 | H6: =IF(C6=0,"",IF(AND(OR(01_因子設定!$I$5="",F6>=01_因子設定!$I$5),OR(01_因子設定!$J$5="",F6<=01_因子設定!$J$5),OR(01_因子設定!$I$6="",G6>=01_因子設定!$I$6),OR(01_因子設定!$J$6="",G6<=01_因子設定!$J$6)),"OK","安全限界超過")) -> OK | I6: 0.414749 | J6: =IF(C6=0,99,IF(AND(01_因子設定!$B$24="変更困難因子でグループ化",01_因子設定!$B$25>0),VLOOKUP(ROUND(INDEX(D6:E6,01_因子設定!$B$25),6),$S$5:$T$9,2,FALSE())+I6*0.9,I6)) -> 0.414749 | K6: =IF(C6=1,SUMPRODUCT(($C$5:$C$22=1)*($J$5:$J$22<J6))+1,"") -> 5 | L6: =IF(C6=1,INDEX(03_実験結果!$G$5:$G$22,K6),0) -> 43.2 | N6: 1 | O6: -1 | S6: -1 | T6: 1
A7: 3 | B7: =IF(A7>01_因子設定!$B$23,"未使用",IF(A7>01_因子設定!$B$26,"中心点",IF(01_因子設定!$B$20="Box-Behnken","BBD点",IF(A7<=4,"要因点","軸点")))) -> 要因点 | C7: =IF(A7<=01_因子設定!$B$23,1,0) -> 1 | D7: =IF($C7=0,0,N7*IF($A7>4,01_因子設定!$B$22,1)) -> -1 | E7: =IF($C7=0,0,O7*IF($A7>4,01_因子設定!$B$22,1)) -> 1 | F7: =IF($C7=1,01_因子設定!$G$5+D7*01_因子設定!$H$5,"") -> 55 | G7: =IF($C7=1,01_因子設定!$G$6+E7*01_因子設定!$H$6,"") -> 40 | H7: =IF(C7=0,"",IF(AND(OR(01_因子設定!$I$5="",F7>=01_因子設定!$I$5),OR(01_因子設定!$J$5="",F7<=01_因子設定!$J$5),OR(01_因子設定!$I$6="",G7>=01_因子設定!$I$6),OR(01_因子設定!$J$6="",G7<=01_因子設定!$J$6)),"OK","安全限界超過")) -> OK | I7: 0.255268 | J7: =IF(C7=0,99,IF(AND(01_因子設定!$B$24="変更困難因子でグループ化",01_因子設定!$B$25>0),VLOOKUP(ROUND(INDEX(D7:E7,01_因子設定!$B$25),6),$S$5:$T$9,2,FALSE())+I7*0.9,I7)) -> 0.255268 | K7: =IF(C7=1,SUMPRODUCT(($C$5:$C$22=1)*($J$5:$J$22<J7))+1,"") -> 3 | L7: =IF(C7=1,INDEX(03_実験結果!$G$5:$G$22,K7),0) -> 43.5 | N7: -1 | O7: 1 | S7: 0 | T7: 5
A8: 4 | B8: =IF(A8>01_因子設定!$B$23,"未使用",IF(A8>01_因子設定!$B$26,"中心点",IF(01_因子設定!$B$20="Box-Behnken","BBD点",IF(A8<=4,"要因点","軸点")))) -> 要因点 | C8: =IF(A8<=01_因子設定!$B$23,1,0) -> 1 | D8: =IF($C8=0,0,N8*IF($A8>4,01_因子設定!$B$22,1)) -> 1 | E8: =IF($C8=0,0,O8*IF($A8>4,01_因子設定!$B$22,1)) -> 1 | F8: =IF($C8=1,01_因子設定!$G$5+D8*01_因子設定!$H$5,"") -> 75 | G8: =IF($C8=1,01_因子設定!$G$6+E8*01_因子設定!$H$6,"") -> 40 | H8: =IF(C8=0,"",IF(AND(OR(01_因子設定!$I$5="",F8>=01_因子設定!$I$5),OR(01_因子設定!$J$5="",F8<=01_因子設定!$J$5),OR(01_因子設定!$I$6="",G8>=01_因子設定!$I$6),OR(01_因子設定!$J$6="",G8<=01_因子設定!$J$6)),"OK","安全限界超過")) -> OK | I8: 0.768538 | J8: =IF(C8=0,99,IF(AND(01_因子設定!$B$24="変更困難因子でグループ化",01_因子設定!$B$25>0),VLOOKUP(ROUND(INDEX(D8:E8,01_因子設定!$B$25),6),$S$5:$T$9,2,FALSE())+I8*0.9,I8)) -> 0.768538 | K8: =IF(C8=1,SUMPRODUCT(($C$5:$C$22=1)*($J$5:$J$22<J8))+1,"") -> 9 | L8: =IF(C8=1,INDEX(03_実験結果!$G$5:$G$22,K8),0) -> 48.8 | N8: 1 | O8: 1 | S8: 1 | T8: 2
A9: 5 | B9: =IF(A9>01_因子設定!$B$23,"未使用",IF(A9>01_因子設定!$B$26,"中心点",IF(01_因子設定!$B$20="Box-Behnken","BBD点",IF(A9<=4,"要因点","軸点")))) -> 軸点 | C9: =IF(A9<=01_因子設定!$B$23,1,0) -> 1 | D9: =IF($C9=0,0,N9*IF($A9>4,01_因子設定!$B$22,1)) -> -1 | E9: =IF($C9=0,0,O9*IF($A9>4,01_因子設定!$B$22,1)) -> 0 | F9: =IF($C9=1,01_因子設定!$G$5+D9*01_因子設定!$H$5,"") -> 55 | G9: =IF($C9=1,01_因子設定!$G$6+E9*01_因子設定!$H$6,"") -> 30 | H9: =IF(C9=0,"",IF(AND(OR(01_因子設定!$I$5="",F9>=01_因子設定!$I$5),OR(01_因子設定!$J$5="",F9<=01_因子設定!$J$5),OR(01_因子設定!$I$6="",G9>=01_因子設定!$I$6),OR(01_因子設定!$J$6="",G9<=01_因子設定!$J$6)),"OK","安全限界超過")) -> OK | I9: 0.535958 | J9: =IF(C9=0,99,IF(AND(01_因子設定!$B$24="変更困難因子でグループ化",01_因子設定!$B$25>0),VLOOKUP(ROUND(INDEX(D9:E9,01_因子設定!$B$25),6),$S$5:$T$9,2,FALSE())+I9*0.9,I9)) -> 0.535958 | K9: =IF(C9=1,SUMPRODUCT(($C$5:$C$22=1)*($J$5:$J$22<J9))+1,"") -> 6 | L9: =IF(C9=1,INDEX(03_実験結果!$G$5:$G$22,K9),0) -> 43 | N9: -1 | O9: 0 | S9: 1.414214 | T9: 4
A10: 6 | B10: =IF(A10>01_因子設定!$B$23,"未使用",IF(A10>01_因子設定!$B$26,"中心点",IF(01_因子設定!$B$20="Box-Behnken","BBD点",IF(A10<=4,"要因点","軸点")))) -> 軸点 | C10: =IF(A10<=01_因子設定!$B$23,1,0) -> 1 | D10: =IF($C10=0,0,N10*IF($A10>4,01_因子設定!$B$22,1)) -> 1 | E10: =IF($C10=0,0,O10*IF($A10>4,01_因子設定!$B$22,1)) -> 0 | F10: =IF($C10=1,01_因子設定!$G$5+D10*01_因子設定!$H$5,"") -> 75 | G10: =IF($C10=1,01_因子設定!$G$6+E10*01_因子設定!$H$6,"") -> 30 | H10: =IF(C10=0,"",IF(AND(OR(01_因子設定!$I$5="",F10>=01_因子設定!$I$5),OR(01_因子設定!$J$5="",F10<=01_因子設定!$J$5),OR(01_因子設定!$I$6="",G10>=01_因子設定!$I$6),OR(01_因子設定!$J$6="",G10<=01_因子設定!$J$6)),"OK","安全限界超過")) -> OK | I10: 0.821638 | J10: =IF(C10=0,99,IF(AND(01_因子設定!$B$24="変更困難因子でグループ化",01_因子設定!$B$25>0),VLOOKUP(ROUND(INDEX(D10:E10,01_因子設定!$B$25),6),$S$5:$T$9,2,FALSE())+I10*0.9,I10)) -> 0.821638 | K10: =IF(C10=1,SUMPRODUCT(($C$5:$C$22=1)*($J$5:$J$22<J10))+1,"") -> 10 | L10: =IF(C10=1,INDEX(03_実験結果!$G$5:$G$22,K10),0) -> 47.2 | N10: 1 | O10: 0
A11: 7 | B11: =IF(A11>01_因子設定!$B$23,"未使用",IF(A11>01_因子設定!$B$26,"中心点",IF(01_因子設定!$B$20="Box-Behnken","BBD点",IF(A11<=4,"要因点","軸点")))) -> 軸点 | C11: =IF(A11<=01_因子設定!$B$23,1,0) -> 1 | D11: =IF($C11=0,0,N11*IF($A11>4,01_因子設定!$B$22,1)) -> 0 | E11: =IF($C11=0,0,O11*IF($A11>4,01_因子設定!$B$22,1)) -> -1 | F11: =IF($C11=1,01_因子設定!$G$5+D11*01_因子設定!$H$5,"") -> 65 | G11: =IF($C11=1,01_因子設定!$G$6+E11*01_因子設定!$H$6,"") -> 20 | H11: =IF(C11=0,"",IF(AND(OR(01_因子設定!$I$5="",F11>=01_因子設定!$I$5),OR(01_因子設定!$J$5="",F11<=01_因子設定!$J$5),OR(01_因子設定!$I$6="",G11>=01_因子設定!$I$6),OR(01_因子設定!$J$6="",G11<=01_因子設定!$J$6)),"OK","安全限界超過")) -> OK | I11: 0.741846 | J11: =IF(C11=0,99,IF(AND(01_因子設定!$B$24="変更困難因子でグループ化",01_因子設定!$B$25>0),VLOOKUP(ROUND(INDEX(D11:E11,01_因子設定!$B$25),6),$S$5:$T$9,2,FALSE())+I11*0.9,I11)) -> 0.741846 | K11: =IF(C11=1,SUMPRODUCT(($C$5:$C$22=1)*($J$5:$J$22<J11))+1,"") -> 8 | L11: =IF(C11=1,INDEX(03_実験結果!$G$5:$G$22,K11),0) -> 44.1 | N11: 0 | O11: -1 | S11: グループ順位＝変更困難因子の水準を実施する順番（1が最初）。入れ替え可
A12: 8 | B12: =IF(A12>01_因子設定!$B$23,"未使用",IF(A12>01_因子設定!$B$26,"中心点",IF(01_因子設定!$B$20="Box-Behnken","BBD点",IF(A12<=4,"要因点","軸点")))) -> 軸点 | C12: =IF(A12<=01_因子設定!$B$23,1,0) -> 1 | D12: =IF($C12=0,0,N12*IF($A12>4,01_因子設定!$B$22,1)) -> 0 | E12: =IF($C12=0,0,O12*IF($A12>4,01_因子設定!$B$22,1)) -> 1 | F12: =IF($C12=1,01_因子設定!$G$5+D12*01_因子設定!$H$5,"") -> 65 | G12: =IF($C12=1,01_因子設定!$G$6+E12*01_因子設定!$H$6,"") -> 40 | H12: =IF(C12=0,"",IF(AND(OR(01_因子設定!$I$5="",F12>=01_因子設定!$I$5),OR(01_因子設定!$J$5="",F12<=01_因子設定!$J$5),OR(01_因子設定!$I$6="",G12>=01_因子設定!$I$6),OR(01_因子設定!$J$6="",G12<=01_因子設定!$J$6)),"OK","安全限界超過")) -> OK | I12: 0.85567 | J12: =IF(C12=0,99,IF(AND(01_因子設定!$B$24="変更困難因子でグループ化",01_因子設定!$B$25>0),VLOOKUP(ROUND(INDEX(D12:E12,01_因子設定!$B$25),6),$S$5:$T$9,2,FALSE())+I12*0.9,I12)) -> 0.85567 | K12: =IF(C12=1,SUMPRODUCT(($C$5:$C$22=1)*($J$5:$J$22<J12))+1,"") -> 11 | L12: =IF(C12=1,INDEX(03_実験結果!$G$5:$G$22,K12),0) -> 48.5 | N12: 0 | O12: 1
A13: 9 | B13: =IF(A13>01_因子設定!$B$23,"未使用",IF(A13>01_因子設定!$B$26,"中心点",IF(01_因子設定!$B$20="Box-Behnken","BBD点",IF(A13<=4,"要因点","軸点")))) -> 中心点 | C13: =IF(A13<=01_因子設定!$B$23,1,0) -> 1 | D13: =IF($C13=0,0,N13*IF($A13>4,01_因子設定!$B$22,1)) -> 0 | E13: =IF($C13=0,0,O13*IF($A13>4,01_因子設定!$B$22,1)) -> 0 | F13: =IF($C13=1,01_因子設定!$G$5+D13*01_因子設定!$H$5,"") -> 65 | G13: =IF($C13=1,01_因子設定!$G$6+E13*01_因子設定!$H$6,"") -> 30 | H13: =IF(C13=0,"",IF(AND(OR(01_因子設定!$I$5="",F13>=01_因子設定!$I$5),OR(01_因子設定!$J$5="",F13<=01_因子設定!$J$5),OR(01_因子設定!$I$6="",G13>=01_因子設定!$I$6),OR(01_因子設定!$J$6="",G13<=01_因子設定!$J$6)),"OK","安全限界超過")) -> OK | I13: 0.967413 | J13: =IF(C13=0,99,IF(AND(01_因子設定!$B$24="変更困難因子でグループ化",01_因子設定!$B$25>0),VLOOKUP(ROUND(INDEX(D13:E13,01_因子設定!$B$25),6),$S$5:$T$9,2,FALSE())+I13*0.9,I13)) -> 0.967413 | K13: =IF(C13=1,SUMPRODUCT(($C$5:$C$22=1)*($J$5:$J$22<J13))+1,"") -> 12 | L13: =IF(C13=1,INDEX(03_実験結果!$G$5:$G$22,K13),0) -> 48.5 | N13: 0 | O13: 0
A14: 10 | B14: =IF(A14>01_因子設定!$B$23,"未使用",IF(A14>01_因子設定!$B$26,"中心点",IF(01_因子設定!$B$20="Box-Behnken","BBD点",IF(A14<=4,"要因点","軸点")))) -> 中心点 | C14: =IF(A14<=01_因子設定!$B$23,1,0) -> 1 | D14: =IF($C14=0,0,N14*IF($A14>4,01_因子設定!$B$22,1)) -> 0 | E14: =IF($C14=0,0,O14*IF($A14>4,01_因子設定!$B$22,1)) -> 0 | F14: =IF($C14=1,01_因子設定!$G$5+D14*01_因子設定!$H$5,"") -> 65 | G14: =IF($C14=1,01_因子設定!$G$6+E14*01_因子設定!$H$6,"") -> 30 | H14: =IF(C14=0,"",IF(AND(OR(01_因子設定!$I$5="",F14>=01_因子設定!$I$5),OR(01_因子設定!$J$5="",F14<=01_因子設定!$J$5),OR(01_因子設定!$I$6="",G14>=01_因子設定!$I$6),OR(01_因子設定!$J$6="",G14<=01_因子設定!$J$6)),"OK","安全限界超過")) -> OK | I14: 0.064566 | J14: =IF(C14=0,99,IF(AND(01_因子設定!$B$24="変更困難因子でグループ化",01_因子設定!$B$25>0),VLOOKUP(ROUND(INDEX(D14:E14,01_因子設定!$B$25),6),$S$5:$T$9,2,FALSE())+I14*0.9,I14)) -> 0.064566 | K14: =IF(C14=1,SUMPRODUCT(($C$5:$C$22=1)*($J$5:$J$22<J14))+1,"") -> 2 | L14: =IF(C14=1,INDEX(03_実験結果!$G$5:$G$22,K14),0) -> 46.7 | N14: 0 | O14: 0
A15: 11 | B15: =IF(A15>01_因子設定!$B$23,"未使用",IF(A15>01_因子設定!$B$26,"中心点",IF(01_因子設定!$B$20="Box-Behnken","BBD点",IF(A15<=4,"要因点","軸点")))) -> 中心点 | C15: =IF(A15<=01_因子設定!$B$23,1,0) -> 1 | D15: =IF($C15=0,0,N15*IF($A15>4,01_因子設定!$B$22,1)) -> 0 | E15: =IF($C15=0,0,O15*IF($A15>4,01_因子設定!$B$22,1)) -> 0 | F15: =IF($C15=1,01_因子設定!$G$5+D15*01_因子設定!$H$5,"") -> 65 | G15: =IF($C15=1,01_因子設定!$G$6+E15*01_因子設定!$H$6,"") -> 30 | H15: =IF(C15=0,"",IF(AND(OR(01_因子設定!$I$5="",F15>=01_因子設定!$I$5),OR(01_因子設定!$J$5="",F15<=01_因子設定!$J$5),OR(01_因子設定!$I$6="",G15>=01_因子設定!$I$6),OR(01_因子設定!$J$6="",G15<=01_因子設定!$J$6)),"OK","安全限界超過")) -> OK | I15: 0.977205 | J15: =IF(C15=0,99,IF(AND(01_因子設定!$B$24="変更困難因子でグループ化",01_因子設定!$B$25>0),VLOOKUP(ROUND(INDEX(D15:E15,01_因子設定!$B$25),6),$S$5:$T$9,2,FALSE())+I15*0.9,I15)) -> 0.977205 | K15: =IF(C15=1,SUMPRODUCT(($C$5:$C$22=1)*($J$5:$J$22<J15))+1,"") -> 13 | L15: =IF(C15=1,INDEX(03_実験結果!$G$5:$G$22,K15),0) -> 49.1 | N15: 0 | O15: 0
A16: 12 | B16: =IF(A16>01_因子設定!$B$23,"未使用",IF(A16>01_因子設定!$B$26,"中心点",IF(01_因子設定!$B$20="Box-Behnken","BBD点",IF(A16<=4,"要因点","軸点")))) -> 中心点 | C16: =IF(A16<=01_因子設定!$B$23,1,0) -> 1 | D16: =IF($C16=0,0,N16*IF($A16>4,01_因子設定!$B$22,1)) -> 0 | E16: =IF($C16=0,0,O16*IF($A16>4,01_因子設定!$B$22,1)) -> 0 | F16: =IF($C16=1,01_因子設定!$G$5+D16*01_因子設定!$H$5,"") -> 65 | G16: =IF($C16=1,01_因子設定!$G$6+E16*01_因子設定!$H$6,"") -> 30 | H16: =IF(C16=0,"",IF(AND(OR(01_因子設定!$I$5="",F16>=01_因子設定!$I$5),OR(01_因子設定!$J$5="",F16<=01_因子設定!$J$5),OR(01_因子設定!$I$6="",G16>=01_因子設定!$I$6),OR(01_因子設定!$J$6="",G16<=01_因子設定!$J$6)),"OK","安全限界超過")) -> OK | I16: 0.062067 | J16: =IF(C16=0,99,IF(AND(01_因子設定!$B$24="変更困難因子でグループ化",01_因子設定!$B$25>0),VLOOKUP(ROUND(INDEX(D16:E16,01_因子設定!$B$25),6),$S$5:$T$9,2,FALSE())+I16*0.9,I16)) -> 0.062067 | K16: =IF(C16=1,SUMPRODUCT(($C$5:$C$22=1)*($J$5:$J$22<J16))+1,"") -> 1 | L16: =IF(C16=1,INDEX(03_実験結果!$G$5:$G$22,K16),0) -> 47.9 | N16: 0 | O16: 0
A17: 13 | B17: =IF(A17>01_因子設定!$B$23,"未使用",IF(A17>01_因子設定!$B$26,"中心点",IF(01_因子設定!$B$20="Box-Behnken","BBD点",IF(A17<=4,"要因点","軸点")))) -> 中心点 | C17: =IF(A17<=01_因子設定!$B$23,1,0) -> 1 | D17: =IF($C17=0,0,N17*IF($A17>4,01_因子設定!$B$22,1)) -> 0 | E17: =IF($C17=0,0,O17*IF($A17>4,01_因子設定!$B$22,1)) -> 0 | F17: =IF($C17=1,01_因子設定!$G$5+D17*01_因子設定!$H$5,"") -> 65 | G17: =IF($C17=1,01_因子設定!$G$6+E17*01_因子設定!$H$6,"") -> 30 | H17: =IF(C17=0,"",IF(AND(OR(01_因子設定!$I$5="",F17>=01_因子設定!$I$5),OR(01_因子設定!$J$5="",F17<=01_因子設定!$J$5),OR(01_因子設定!$I$6="",G17>=01_因子設定!$I$6),OR(01_因子設定!$J$6="",G17<=01_因子設定!$J$6)),"OK","安全限界超過")) -> OK | I17: 0.536927 | J17: =IF(C17=0,99,IF(AND(01_因子設定!$B$24="変更困難因子でグループ化",01_因子設定!$B$25>0),VLOOKUP(ROUND(INDEX(D17:E17,01_因子設定!$B$25),6),$S$5:$T$9,2,FALSE())+I17*0.9,I17)) -> 0.536927 | K17: =IF(C17=1,SUMPRODUCT(($C$5:$C$22=1)*($J$5:$J$22<J17))+1,"") -> 7 | L17: =IF(C17=1,INDEX(03_実験結果!$G$5:$G$22,K17),0) -> 48.5 | N17: 0 | O17: 0
A18: 14 | B18: =IF(A18>01_因子設定!$B$23,"未使用",IF(A18>01_因子設定!$B$26,"中心点",IF(01_因子設定!$B$20="Box-Behnken","BBD点",IF(A18<=4,"要因点","軸点")))) -> 未使用 | C18: =IF(A18<=01_因子設定!$B$23,1,0) -> 0 | D18: =IF($C18=0,0,N18*IF($A18>4,01_因子設定!$B$22,1)) -> 0 | E18: =IF($C18=0,0,O18*IF($A18>4,01_因子設定!$B$22,1)) -> 0 | F18: =IF($C18=1,01_因子設定!$G$5+D18*01_因子設定!$H$5,"") | G18: =IF($C18=1,01_因子設定!$G$6+E18*01_因子設定!$H$6,"") | H18: =IF(C18=0,"",IF(AND(OR(01_因子設定!$I$5="",F18>=01_因子設定!$I$5),OR(01_因子設定!$J$5="",F18<=01_因子設定!$J$5),OR(01_因子設定!$I$6="",G18>=01_因子設定!$I$6),OR(01_因子設定!$J$6="",G18<=01_因子設定!$J$6)),"OK","安全限界超過")) | I18: 0.110535 | J18: =IF(C18=0,99,IF(AND(01_因子設定!$B$24="変更困難因子でグループ化",01_因子設定!$B$25>0),VLOOKUP(ROUND(INDEX(D18:E18,01_因子設定!$B$25),6),$S$5:$T$9,2,FALSE())+I18*0.9,I18)) -> 99 | K18: =IF(C18=1,SUMPRODUCT(($C$5:$C$22=1)*($J$5:$J$22<J18))+1,"") | L18: =IF(C18=1,INDEX(03_実験結果!$G$5:$G$22,K18),0) -> 0 | N18: 0 | O18: 0
A19: 15 | B19: =IF(A19>01_因子設定!$B$23,"未使用",IF(A19>01_因子設定!$B$26,"中心点",IF(01_因子設定!$B$20="Box-Behnken","BBD点",IF(A19<=4,"要因点","軸点")))) -> 未使用 | C19: =IF(A19<=01_因子設定!$B$23,1,0) -> 0 | D19: =IF($C19=0,0,N19*IF($A19>4,01_因子設定!$B$22,1)) -> 0 | E19: =IF($C19=0,0,O19*IF($A19>4,01_因子設定!$B$22,1)) -> 0 | F19: =IF($C19=1,01_因子設定!$G$5+D19*01_因子設定!$H$5,"") | G19: =IF($C19=1,01_因子設定!$G$6+E19*01_因子設定!$H$6,"") | H19: =IF(C19=0,"",IF(AND(OR(01_因子設定!$I$5="",F19>=01_因子設定!$I$5),OR(01_因子設定!$J$5="",F19<=01_因子設定!$J$5),OR(01_因子設定!$I$6="",G19>=01_因子設定!$I$6),OR(01_因子設定!$J$6="",G19<=01_因子設定!$J$6)),"OK","安全限界超過")) | I19: 0.201322 | J19: =IF(C19=0,99,IF(AND(01_因子設定!$B$24="変更困難因子でグループ化",01_因子設定!$B$25>0),VLOOKUP(ROUND(INDEX(D19:E19,01_因子設定!$B$25),6),$S$5:$T$9,2,FALSE())+I19*0.9,I19)) -> 99 | K19: =IF(C19=1,SUMPRODUCT(($C$5:$C$22=1)*($J$5:$J$22<J19))+1,"") | L19: =IF(C19=1,INDEX(03_実験結果!$G$5:$G$22,K19),0) -> 0 | N19: 0 | O19: 0
A20: 16 | B20: =IF(A20>01_因子設定!$B$23,"未使用",IF(A20>01_因子設定!$B$26,"中心点",IF(01_因子設定!$B$20="Box-Behnken","BBD点",IF(A20<=4,"要因点","軸点")))) -> 未使用 | C20: =IF(A20<=01_因子設定!$B$23,1,0) -> 0 | D20: =IF($C20=0,0,N20*IF($A20>4,01_因子設定!$B$22,1)) -> 0 | E20: =IF($C20=0,0,O20*IF($A20>4,01_因子設定!$B$22,1)) -> 0 | F20: =IF($C20=1,01_因子設定!$G$5+D20*01_因子設定!$H$5,"") | G20: =IF($C20=1,01_因子設定!$G$6+E20*01_因子設定!$H$6,"") | H20: =IF(C20=0,"",IF(AND(OR(01_因子設定!$I$5="",F20>=01_因子設定!$I$5),OR(01_因子設定!$J$5="",F20<=01_因子設定!$J$5),OR(01_因子設定!$I$6="",G20>=01_因子設定!$I$6),OR(01_因子設定!$J$6="",G20<=01_因子設定!$J$6)),"OK","安全限界超過")) | I20: 0.319799 | J20: =IF(C20=0,99,IF(AND(01_因子設定!$B$24="変更困難因子でグループ化",01_因子設定!$B$25>0),VLOOKUP(ROUND(INDEX(D20:E20,01_因子設定!$B$25),6),$S$5:$T$9,2,FALSE())+I20*0.9,I20)) -> 99 | K20: =IF(C20=1,SUMPRODUCT(($C$5:$C$22=1)*($J$5:$J$22<J20))+1,"") | L20: =IF(C20=1,INDEX(03_実験結果!$G$5:$G$22,K20),0) -> 0 | N20: 0 | O20: 0
A21: 17 | B21: =IF(A21>01_因子設定!$B$23,"未使用",IF(A21>01_因子設定!$B$26,"中心点",IF(01_因子設定!$B$20="Box-Behnken","BBD点",IF(A21<=4,"要因点","軸点")))) -> 未使用 | C21: =IF(A21<=01_因子設定!$B$23,1,0) -> 0 | D21: =IF($C21=0,0,N21*IF($A21>4,01_因子設定!$B$22,1)) -> 0 | E21: =IF($C21=0,0,O21*IF($A21>4,01_因子設定!$B$22,1)) -> 0 | F21: =IF($C21=1,01_因子設定!$G$5+D21*01_因子設定!$H$5,"") | G21: =IF($C21=1,01_因子設定!$G$6+E21*01_因子設定!$H$6,"") | H21: =IF(C21=0,"",IF(AND(OR(01_因子設定!$I$5="",F21>=01_因子設定!$I$5),OR(01_因子設定!$J$5="",F21<=01_因子設定!$J$5),OR(01_因子設定!$I$6="",G21>=01_因子設定!$I$6),OR(01_因子設定!$J$6="",G21<=01_因子設定!$J$6)),"OK","安全限界超過")) | I21: 0.665792 | J21: =IF(C21=0,99,IF(AND(01_因子設定!$B$24="変更困難因子でグループ化",01_因子設定!$B$25>0),VLOOKUP(ROUND(INDEX(D21:E21,01_因子設定!$B$25),6),$S$5:$T$9,2,FALSE())+I21*0.9,I21)) -> 99 | K21: =IF(C21=1,SUMPRODUCT(($C$5:$C$22=1)*($J$5:$J$22<J21))+1,"") | L21: =IF(C21=1,INDEX(03_実験結果!$G$5:$G$22,K21),0) -> 0 | N21: 0 | O21: 0
A22: 18 | B22: =IF(A22>01_因子設定!$B$23,"未使用",IF(A22>01_因子設定!$B$26,"中心点",IF(01_因子設定!$B$20="Box-Behnken","BBD点",IF(A22<=4,"要因点","軸点")))) -> 未使用 | C22: =IF(A22<=01_因子設定!$B$23,1,0) -> 0 | D22: =IF($C22=0,0,N22*IF($A22>4,01_因子設定!$B$22,1)) -> 0 | E22: =IF($C22=0,0,O22*IF($A22>4,01_因子設定!$B$22,1)) -> 0 | F22: =IF($C22=1,01_因子設定!$G$5+D22*01_因子設定!$H$5,"") | G22: =IF($C22=1,01_因子設定!$G$6+E22*01_因子設定!$H$6,"") | H22: =IF(C22=0,"",IF(AND(OR(01_因子設定!$I$5="",F22>=01_因子設定!$I$5),OR(01_因子設定!$J$5="",F22<=01_因子設定!$J$5),OR(01_因子設定!$I$6="",G22>=01_因子設定!$I$6),OR(01_因子設定!$J$6="",G22<=01_因子設定!$J$6)),"OK","安全限界超過")) | I22: 0.101479 | J22: =IF(C22=0,99,IF(AND(01_因子設定!$B$24="変更困難因子でグループ化",01_因子設定!$B$25>0),VLOOKUP(ROUND(INDEX(D22:E22,01_因子設定!$B$25),6),$S$5:$T$9,2,FALSE())+I22*0.9,I22)) -> 99 | K22: =IF(C22=1,SUMPRODUCT(($C$5:$C$22=1)*($J$5:$J$22<J22))+1,"") | L22: =IF(C22=1,INDEX(03_実験結果!$G$5:$G$22,K22),0) -> 0 | N22: 0 | O22: 0
N24: 右側のパターン列：CCD／BBDの基本パターン（編集不要）

Sheet 03_実験結果
A1: 03 実験指示書・結果入力（実験順）
A2: この順番で実験し、Yを入力。現在のYは検証用の架空データ。計画を変えたら入れ直してください。
A4: 実験順序 | B4: 標準順 | C4: 区分 | D4: =01_因子設定!B5&"["&01_因子設定!D5&"]" -> 炉温[℃] | E4: =01_因子設定!B6&"["&01_因子設定!D6&"]" -> 乾燥時間[min] | F4: 変更困難因子の水準 | G4: ="Y："&01_因子設定!B11&"["&01_因子設定!B12&"]" -> Y：剥離強度[N/25mm] | H4: メモ（異常・気付き）
A5: 1 | B5: =IF(A5<=01_因子設定!$B$23,INDEX(02_実験計画!$A$5:$A$22,MATCH(A5,02_実験計画!$K$5:$K$22,0)),"") -> 12 | C5: =IF(B5="","",INDEX(02_実験計画!$B$5:$B$22,B5)) -> 中心点 | D5: =IF($B5="","",INDEX(02_実験計画!$F$5:$F$22,$B5)) -> 65 | E5: =IF($B5="","",INDEX(02_実験計画!$G$5:$G$22,$B5)) -> 30 | F5: =IF(OR(B5="",01_因子設定!$B$25=0),"",INDEX(D5:E5,01_因子設定!$B$25)) -> 65 | G5: 47.9
A6: 2 | B6: =IF(A6<=01_因子設定!$B$23,INDEX(02_実験計画!$A$5:$A$22,MATCH(A6,02_実験計画!$K$5:$K$22,0)),"") -> 10 | C6: =IF(B6="","",INDEX(02_実験計画!$B$5:$B$22,B6)) -> 中心点 | D6: =IF($B6="","",INDEX(02_実験計画!$F$5:$F$22,$B6)) -> 65 | E6: =IF($B6="","",INDEX(02_実験計画!$G$5:$G$22,$B6)) -> 30 | F6: =IF(OR(B6="",01_因子設定!$B$25=0),"",INDEX(D6:E6,01_因子設定!$B$25)) -> 65 | G6: 46.7
A7: 3 | B7: =IF(A7<=01_因子設定!$B$23,INDEX(02_実験計画!$A$5:$A$22,MATCH(A7,02_実験計画!$K$5:$K$22,0)),"") -> 3 | C7: =IF(B7="","",INDEX(02_実験計画!$B$5:$B$22,B7)) -> 要因点 | D7: =IF($B7="","",INDEX(02_実験計画!$F$5:$F$22,$B7)) -> 55 | E7: =IF($B7="","",INDEX(02_実験計画!$G$5:$G$22,$B7)) -> 40 | F7: =IF(OR(B7="",01_因子設定!$B$25=0),"",INDEX(D7:E7,01_因子設定!$B$25)) -> 55 | G7: 43.5
A8: 4 | B8: =IF(A8<=01_因子設定!$B$23,INDEX(02_実験計画!$A$5:$A$22,MATCH(A8,02_実験計画!$K$5:$K$22,0)),"") -> 1 | C8: =IF(B8="","",INDEX(02_実験計画!$B$5:$B$22,B8)) -> 要因点 | D8: =IF($B8="","",INDEX(02_実験計画!$F$5:$F$22,$B8)) -> 55 | E8: =IF($B8="","",INDEX(02_実験計画!$G$5:$G$22,$B8)) -> 20 | F8: =IF(OR(B8="",01_因子設定!$B$25=0),"",INDEX(D8:E8,01_因子設定!$B$25)) -> 55 | G8: 40
A9: 5 | B9: =IF(A9<=01_因子設定!$B$23,INDEX(02_実験計画!$A$5:$A$22,MATCH(A9,02_実験計画!$K$5:$K$22,0)),"") -> 2 | C9: =IF(B9="","",INDEX(02_実験計画!$B$5:$B$22,B9)) -> 要因点 | D9: =IF($B9="","",INDEX(02_実験計画!$F$5:$F$22,$B9)) -> 75 | E9: =IF($B9="","",INDEX(02_実験計画!$G$5:$G$22,$B9)) -> 20 | F9: =IF(OR(B9="",01_因子設定!$B$25=0),"",INDEX(D9:E9,01_因子設定!$B$25)) -> 75 | G9: 43.2
A10: 6 | B10: =IF(A10<=01_因子設定!$B$23,INDEX(02_実験計画!$A$5:$A$22,MATCH(A10,02_実験計画!$K$5:$K$22,0)),"") -> 5 | C10: =IF(B10="","",INDEX(02_実験計画!$B$5:$B$22,B10)) -> 軸点 | D10: =IF($B10="","",INDEX(02_実験計画!$F$5:$F$22,$B10)) -> 55 | E10: =IF($B10="","",INDEX(02_実験計画!$G$5:$G$22,$B10)) -> 30 | F10: =IF(OR(B10="",01_因子設定!$B$25=0),"",INDEX(D10:E10,01_因子設定!$B$25)) -> 55 | G10: 43
A11: 7 | B11: =IF(A11<=01_因子設定!$B$23,INDEX(02_実験計画!$A$5:$A$22,MATCH(A11,02_実験計画!$K$5:$K$22,0)),"") -> 13 | C11: =IF(B11="","",INDEX(02_実験計画!$B$5:$B$22,B11)) -> 中心点 | D11: =IF($B11="","",INDEX(02_実験計画!$F$5:$F$22,$B11)) -> 65 | E11: =IF($B11="","",INDEX(02_実験計画!$G$5:$G$22,$B11)) -> 30 | F11: =IF(OR(B11="",01_因子設定!$B$25=0),"",INDEX(D11:E11,01_因子設定!$B$25)) -> 65 | G11: 48.5
A12: 8 | B12: =IF(A12<=01_因子設定!$B$23,INDEX(02_実験計画!$A$5:$A$22,MATCH(A12,02_実験計画!$K$5:$K$22,0)),"") -> 7 | C12: =IF(B12="","",INDEX(02_実験計画!$B$5:$B$22,B12)) -> 軸点 | D12: =IF($B12="","",INDEX(02_実験計画!$F$5:$F$22,$B12)) -> 65 | E12: =IF($B12="","",INDEX(02_実験計画!$G$5:$G$22,$B12)) -> 20 | F12: =IF(OR(B12="",01_因子設定!$B$25=0),"",INDEX(D12:E12,01_因子設定!$B$25)) -> 65 | G12: 44.1
A13: 9 | B13: =IF(A13<=01_因子設定!$B$23,INDEX(02_実験計画!$A$5:$A$22,MATCH(A13,02_実験計画!$K$5:$K$22,0)),"") -> 4 | C13: =IF(B13="","",INDEX(02_実験計画!$B$5:$B$22,B13)) -> 要因点 | D13: =IF($B13="","",INDEX(02_実験計画!$F$5:$F$22,$B13)) -> 75 | E13: =IF($B13="","",INDEX(02_実験計画!$G$5:$G$22,$B13)) -> 40 | F13: =IF(OR(B13="",01_因子設定!$B$25=0),"",INDEX(D13:E13,01_因子設定!$B$25)) -> 75 | G13: 48.8
A14: 10 | B14: =IF(A14<=01_因子設定!$B$23,INDEX(02_実験計画!$A$5:$A$22,MATCH(A14,02_実験計画!$K$5:$K$22,0)),"") -> 6 | C14: =IF(B14="","",INDEX(02_実験計画!$B$5:$B$22,B14)) -> 軸点 | D14: =IF($B14="","",INDEX(02_実験計画!$F$5:$F$22,$B14)) -> 75 | E14: =IF($B14="","",INDEX(02_実験計画!$G$5:$G$22,$B14)) -> 30 | F14: =IF(OR(B14="",01_因子設定!$B$25=0),"",INDEX(D14:E14,01_因子設定!$B$25)) -> 75 | G14: 47.2
A15: 11 | B15: =IF(A15<=01_因子設定!$B$23,INDEX(02_実験計画!$A$5:$A$22,MATCH(A15,02_実験計画!$K$5:$K$22,0)),"") -> 8 | C15: =IF(B15="","",INDEX(02_実験計画!$B$5:$B$22,B15)) -> 軸点 | D15: =IF($B15="","",INDEX(02_実験計画!$F$5:$F$22,$B15)) -> 65 | E15: =IF($B15="","",INDEX(02_実験計画!$G$5:$G$22,$B15)) -> 40 | F15: =IF(OR(B15="",01_因子設定!$B$25=0),"",INDEX(D15:E15,01_因子設定!$B$25)) -> 65 | G15: 48.5
A16: 12 | B16: =IF(A16<=01_因子設定!$B$23,INDEX(02_実験計画!$A$5:$A$22,MATCH(A16,02_実験計画!$K$5:$K$22,0)),"") -> 9 | C16: =IF(B16="","",INDEX(02_実験計画!$B$5:$B$22,B16)) -> 中心点 | D16: =IF($B16="","",INDEX(02_実験計画!$F$5:$F$22,$B16)) -> 65 | E16: =IF($B16="","",INDEX(02_実験計画!$G$5:$G$22,$B16)) -> 30 | F16: =IF(OR(B16="",01_因子設定!$B$25=0),"",INDEX(D16:E16,01_因子設定!$B$25)) -> 65 | G16: 48.5
A17: 13 | B17: =IF(A17<=01_因子設定!$B$23,INDEX(02_実験計画!$A$5:$A$22,MATCH(A17,02_実験計画!$K$5:$K$22,0)),"") -> 11 | C17: =IF(B17="","",INDEX(02_実験計画!$B$5:$B$22,B17)) -> 中心点 | D17: =IF($B17="","",INDEX(02_実験計画!$F$5:$F$22,$B17)) -> 65 | E17: =IF($B17="","",INDEX(02_実験計画!$G$5:$G$22,$B17)) -> 30 | F17: =IF(OR(B17="",01_因子設定!$B$25=0),"",INDEX(D17:E17,01_因子設定!$B$25)) -> 65 | G17: 49.1
A18: 14 | B18: =IF(A18<=01_因子設定!$B$23,INDEX(02_実験計画!$A$5:$A$22,MATCH(A18,02_実験計画!$K$5:$K$22,0)),"") | C18: =IF(B18="","",INDEX(02_実験計画!$B$5:$B$22,B18)) | D18: =IF($B18="","",INDEX(02_実験計画!$F$5:$F$22,$B18)) | E18: =IF($B18="","",INDEX(02_実験計画!$G$5:$G$22,$B18)) | F18: =IF(OR(B18="",01_因子設定!$B$25=0),"",INDEX(D18:E18,01_因子設定!$B$25))
A19: 15 | B19: =IF(A19<=01_因子設定!$B$23,INDEX(02_実験計画!$A$5:$A$22,MATCH(A19,02_実験計画!$K$5:$K$22,0)),"") | C19: =IF(B19="","",INDEX(02_実験計画!$B$5:$B$22,B19)) | D19: =IF($B19="","",INDEX(02_実験計画!$F$5:$F$22,$B19)) | E19: =IF($B19="","",INDEX(02_実験計画!$G$5:$G$22,$B19)) | F19: =IF(OR(B19="",01_因子設定!$B$25=0),"",INDEX(D19:E19,01_因子設定!$B$25))
A20: 16 | B20: =IF(A20<=01_因子設定!$B$23,INDEX(02_実験計画!$A$5:$A$22,MATCH(A20,02_実験計画!$K$5:$K$22,0)),"") | C20: =IF(B20="","",INDEX(02_実験計画!$B$5:$B$22,B20)) | D20: =IF($B20="","",INDEX(02_実験計画!$F$5:$F$22,$B20)) | E20: =IF($B20="","",INDEX(02_実験計画!$G$5:$G$22,$B20)) | F20: =IF(OR(B20="",01_因子設定!$B$25=0),"",INDEX(D20:E20,01_因子設定!$B$25))
A21: 17 | B21: =IF(A21<=01_因子設定!$B$23,INDEX(02_実験計画!$A$5:$A$22,MATCH(A21,02_実験計画!$K$5:$K$22,0)),"") | C21: =IF(B21="","",INDEX(02_実験計画!$B$5:$B$22,B21)) | D21: =IF($B21="","",INDEX(02_実験計画!$F$5:$F$22,$B21)) | E21: =IF($B21="","",INDEX(02_実験計画!$G$5:$G$22,$B21)) | F21: =IF(OR(B21="",01_因子設定!$B$25=0),"",INDEX(D21:E21,01_因子設定!$B$25))
A22: 18 | B22: =IF(A22<=01_因子設定!$B$23,INDEX(02_実験計画!$A$5:$A$22,MATCH(A22,02_実験計画!$K$5:$K$22,0)),"") | C22: =IF(B22="","",INDEX(02_実験計画!$B$5:$B$22,B22)) | D22: =IF($B22="","",INDEX(02_実験計画!$F$5:$F$22,$B22)) | E22: =IF($B22="","",INDEX(02_実験計画!$G$5:$G$22,$B22)) | F22: =IF(OR(B22="",01_因子設定!$B$25=0),"",INDEX(D22:E22,01_因子設定!$B$25))

Sheet 04_回帰ANOVA
A1: 04 2次回帰モデルとANOVA（コード化単位）
A2: B列を0にすると、その項を除外して再計算（モデル縮小）。切片は常に1。
A5: 項 | B5: 使用(1/0) | C5: 係数 | D5: 標準誤差 | E5: t値 | F5: p値 | G5: 有意 | H5: 階層性チェック | J5: 統計量 | K5: 値
A6: 切片 | B6: 1 | C6: =IF(B6=1,_XtX!I35,0) -> 48.055172 | D6: =IF(B6=1,SQRT($K$13*INDEX(_XtX!$B$44:$G$49,1,1)),"") -> 0.29699555 | E6: =IF(B6=1,C6/D6,"") -> 161.80435 | F6: =IF(B6=1,TDIST(ABS(E6),$K$8,2),"") -> 9.0882997e-14 | G6: =IF(F6="","",IF(F6<0.01,"**",IF(F6<0.05,"*",IF(F6<0.1,"△","")))) -> ** | J6: n（実験数） | K6: =SUM(_XtX!A5:A22) -> 13
A7: X1 | B7: 1 | C7: =IF(B7=1,_XtX!I36,0) -> 2.1166667 | D7: =IF(B7=1,SQRT($K$13*INDEX(_XtX!$B$44:$G$49,2,2)),"") -> 0.29200368 | E7: =IF(B7=1,C7/D7,"") -> 7.2487672 | F7: =IF(B7=1,TDIST(ABS(E7),$K$8,2),"") -> 0.00017011097 | G7: =IF(F7="","",IF(F7<0.01,"**",IF(F7<0.05,"*",IF(F7<0.1,"△","")))) -> ** | J7: p（項数） | K7: =SUM($B$6:$B$11) -> 6
A8: X2 | B8: 1 | C8: =IF(B8=1,_XtX!I37,0) -> 2.25 | D8: =IF(B8=1,SQRT($K$13*INDEX(_XtX!$B$44:$G$49,3,3)),"") -> 0.29200368 | E8: =IF(B8=1,C8/D8,"") -> 7.7053825 | F8: =IF(B8=1,TDIST(ABS(E8),$K$8,2),"") -> 0.00011573343 | G8: =IF(F8="","",IF(F8<0.01,"**",IF(F8<0.05,"*",IF(F8<0.1,"△","")))) -> ** | J8: 残差自由度 | K8: =K6-K7 -> 7
A9: X1·X2 | B9: 1 | C9: =IF(B9=1,_XtX!I38,0) -> 0.525 | D9: =IF(B9=1,SQRT($K$13*INDEX(_XtX!$B$44:$G$49,4,4)),"") -> 0.35763 | E9: =IF(B9=1,C9/D9,"") -> 1.4679976 | F9: =IF(B9=1,TDIST(ABS(E9),$K$8,2),"") -> 0.18554938 | G9: =IF(F9="","",IF(F9<0.01,"**",IF(F9<0.05,"*",IF(F9<0.1,"△","")))) | H9: =IF(AND(B9=1,OR($B$7=0,$B$8=0)),"主効果が除外されています","") | J9: SSE | K9: =SUMSQ(_XtX!L5:L22) -> 3.5811782
A10: X1² | B10: 1 | C10: =IF(B10=1,_XtX!I39,0) -> -2.7431034 | D10: =IF(B10=1,SQRT($K$13*INDEX(_XtX!$B$44:$G$49,5,5)),"") -> 0.43038745 | E10: =IF(B10=1,C10/D10,"") -> -6.3735675 | F10: =IF(B10=1,TDIST(ABS(E10),$K$8,2),"") -> 0.00037664977 | G10: =IF(F10="","",IF(F10<0.01,"**",IF(F10<0.05,"*",IF(F10<0.1,"△","")))) -> ** | H10: =IF(AND(B10=1,OR($B$7=0)),"主効果が除外されています","") | J10: Yの平均 | K10: =SUMPRODUCT(_XtX!H5:H22,_XtX!A5:A22)/K6 -> 46.076923
A11: X2² | B11: 1 | C11: =IF(B11=1,_XtX!I40,0) -> -1.5431034 | D11: =IF(B11=1,SQRT($K$13*INDEX(_XtX!$B$44:$G$49,6,6)),"") -> 0.43038745 | E11: =IF(B11=1,C11/D11,"") -> -3.5853821 | F11: =IF(B11=1,TDIST(ABS(E11),$K$8,2),"") -> 0.0089118884 | G11: =IF(F11="","",IF(F11<0.01,"**",IF(F11<0.05,"*",IF(F11<0.1,"△","")))) -> ** | H11: =IF(AND(B11=1,OR($B$8=0)),"主効果が除外されています","") | J11: SST | K11: =SUMPRODUCT(_XtX!A5:A22,(_XtX!H5:H22-K10)^2) -> 104.36308
J12: SSR | K12: =K11-K9 -> 100.7819
A13: 有意：** p<0.01 * p<0.05 △ p<0.1。p値だけで機械的に削らず、技術的な意味と階層性を優先。 | J13: MSE | K13: =K9/K8 -> 0.51159688
J14: s（残差標準偏差） | K14: =SQRT(K13) -> 0.71526001
J15: R² | K15: =1-K9/K11 -> 0.96568539
J16: 調整済みR² | K16: =1-(K9/K8)/(K11/(K6-1)) -> 0.94117496
J17: PRESS | K17: =SUMPRODUCT(_XtX!A5:A22,(_XtX!L5:L22/(1-_XtX!J5:J22))^2) -> 6.6984764
J18: 予測R² | K18: =1-K17/K11 -> 0.93581565
J19: t値（工程窓・最適化用） | K19: =IF(01_因子設定!$B$13="目標値",TINV(1-01_因子設定!B17,K8),TINV(2*(1-01_因子設定!B17),K8)) -> 1.8945786
J20: Y未入力数 | K20: =SUMPRODUCT((03_実験結果!$A$5:$A$22<=01_因子設定!$B$23)*(03_実験結果!$G$5:$G$22="")) -> 0
J21: 中心点の数 | K21: =COUNTIF(02_実験計画!B5:B22,"中心点") -> 5
J22: 中心点Yの平均 | K22: =IFERROR(AVERAGEIF(02_実験計画!B5:B22,"中心点",02_実験計画!$L$5:$L$22),0) -> 48.14
J23: t値（両側・確認実験用） | K23: =TINV(1-01_因子設定!B17,K8) -> 2.3646243
J24: 工程窓用t：最大化・最小化＝片側（信頼水準95%なら t0.95）、目標値＝両側（t0.975）
A25: 要因 | B25: 自由度 | C25: 平方和 | D25: 平均平方 | E25: F値 | F25: p値 | G25: 判定
A26: 回帰 | B26: =K7-1 -> 5 | C26: =K12 -> 100.7819 | D26: =C26/B26 -> 20.15638 | E26: =D26/D27 -> 39.39895 | F26: =FDIST(E26,B26,B27) -> 5.5777775e-05 | G26: =IF(F26<0.05,"有意","有意でない") -> 有意
A27: 残差 | B27: =K8 -> 7 | C27: =K9 -> 3.5811782 | D27: =K13 -> 0.51159688
A28: 適合度の欠如 | B28: =B27-B29 -> 3 | C28: =C27-C29 -> 0.26917816 | D28: =IF(B28>0,C28/B28,"") -> 0.089726054 | E28: =IF(AND(B28>0,B29>0),D28/D29,"") -> 0.1083648 | F28: =IF(E28="","",FDIST(E28,B28,B29)) -> 0.95080519 | G28: =IF(F28="","検定不可",IF(F28<0.05,"有意（不適合）","有意でない（適合）")) -> 有意でない（適合）
A29: 純誤差 | B29: =MAX(K21-1,0) -> 4 | C29: =SUMPRODUCT((02_実験計画!$B$5:$B$22="中心点")*(02_実験計画!$L$5:$L$22-K22)^2) -> 3.312 | D29: =IF(B29>0,C29/B29,"") -> 0.828
A30: 合計 | B30: =K6-1 -> 12 | C30: =K11 -> 104.36308
A33: 判断ゲート
A34: 計画の安全性 | B34: =IF(LEFT(01_因子設定!$B$31,1)="×","× 計画が安全限界を超過（01参照）→ 計画を変更してから実験する","○ 全実験点が安全限界内") -> ○ 全実験点が安全限界内
A35: ランダマイズ | B35: =IF(01_因子設定!$B$24="変更困難因子でグループ化",IF(01_因子設定!$B$25>0,"△ 分割区画の順序で実施。この解析は完全ランダムとみなした近似で、変更困難因子のp値は小さく（有意に）出やすい → 正式にはJMP/R等で分割区画解析","△ グループ化を選んでいるが変更困難因子に○がない（完全ランダムとして生成）"),IF(01_因子設定!$B$25>0,"△ 変更困難因子に○があるが完全ランダムで生成。現場で実施できるか確認（できなければグループ化＋正式解析はJMP/R等）","○ 完全ランダム")) -> △ 変更困難因子に○があるが完全ランダムで生成。現場で実施できるか確認（できなければグループ化＋正式解析はJMP/R等）
A36: データ | B36: =IF(K20>0,"× Yが"&K20&"件未入力 → 結果は無効","○ 全件入力済") -> ○ 全件入力済
A37: 回帰の有意性 | B37: =IF(F26<0.05,"○ 回帰は有意","× 有意でない → 因子・範囲の見直し。最適化に進まない") -> ○ 回帰は有意
A38: 適合度の欠如 | B38: =IF(F28="","－ 純誤差がないため検定不可（中心点を増やす）",IF(F28<0.05,"× 2次モデルで説明しきれない → 変換・領域縮小・因子追加を検討","○ 2次モデルで説明できている")) -> ○ 2次モデルで説明できている
A39: R²と予測R² | B39: =IF(K15-K18>0.2,"△ 差が0.2超 → 過学習の可能性。不要項の除外を検討","○ 差は0.2以内") -> ○ 差は0.2以内
A40: 残差 | B40: ="05_残差診断のグラフで、パターン・外れ値がないことを目視確認" -> 05_残差診断のグラフで、パターン・外れ値がないことを目視確認
A42: ×がなく、△の内容を理解・記録してから 06（正準解析）→07（最適化）→08（工程窓）へ進みます。

Sheet 05_残差診断
A1: 05 残差診断
A2: スチューデント化残差の絶対値が3超は要確認（測定ミス・異常の可能性）。消す前に原因を調べる。
A4: 標準順 | B4: 実験順 | C4: 使用 | D4: Y実測 | E4: 予測 | F4: 残差 | G4: 標準化残差 | H4: てこ比h | I4: スチューデント化残差 | J4: 判定 | L4: k | M4: 採用k | N4: 標準順 | O4: 予測 | P4: 残差 | Q4: 実験順 | R4: 残差(昇順) | S4: 理論分位点 | T4: 実測
A5: 1 | B5: =02_実験計画!K5 -> 4 | C5: =02_実験計画!C5 -> 1 | D5: =IF(C5=1,_XtX!H5,"") -> 40 | E5: =IF(C5=1,_XtX!K5,"") -> 39.927299 | F5: =IF(C5=1,D5-E5,"") -> 0.072701149 | G5: =IF(C5=1,F5/04_回帰ANOVA!$K$14,"") -> 0.10164297 | H5: =IF(C5=1,_XtX!J5,"") -> 0.79022989 | I5: =IF(C5=1,IF(H5<0.9999,F5/(04_回帰ANOVA!$K$14*SQRT(1-H5)),0),"") -> 0.22192464 | J5: =IF(C5=1,IF(ABS(I5)>3,"要確認",IF(ABS(I5)>2,"注意","")),"") | L5: 1 | M5: =MIN(L5,04_回帰ANOVA!$K$6) -> 1 | N5: =MATCH(M5,$B$5:$B$22,0) -> 12 | O5: =INDEX($E$5:$E$22,N5) -> 48.055172 | P5: =INDEX($F$5:$F$22,N5) -> -0.15517241 | Q5: =M5 -> 1 | R5: =SMALL($F$5:$F$22,M5) -> -1.3551724 | S5: =NORMSINV((M5-0.375)/(04_回帰ANOVA!$K$6+0.25)) -> -1.6729374 | T5: =INDEX($D$5:$D$22,N5) -> 47.9
A6: 2 | B6: =02_実験計画!K6 -> 5 | C6: =02_実験計画!C6 -> 1 | D6: =IF(C6=1,_XtX!H6,"") -> 43.2 | E6: =IF(C6=1,_XtX!K6,"") -> 43.110632 | F6: =IF(C6=1,D6-E6,"") -> 0.089367816 | G6: =IF(C6=1,F6/04_回帰ANOVA!$K$14,"") -> 0.12494452 | H6: =IF(C6=1,_XtX!J6,"") -> 0.79022989 | I6: =IF(C6=1,IF(H6<0.9999,F6/(04_回帰ANOVA!$K$14*SQRT(1-H6)),0),"") -> 0.27280065 | J6: =IF(C6=1,IF(ABS(I6)>3,"要確認",IF(ABS(I6)>2,"注意","")),"") | L6: 2 | M6: =MIN(L6,04_回帰ANOVA!$K$6) -> 2 | N6: =MATCH(M6,$B$5:$B$22,0) -> 10 | O6: =INDEX($E$5:$E$22,N6) -> 48.055172 | P6: =INDEX($F$5:$F$22,N6) -> -1.3551724 | Q6: =M6 -> 2 | R6: =SMALL($F$5:$F$22,M6) -> -0.26206897 | S6: =NORMSINV((M6-0.375)/(04_回帰ANOVA!$K$6+0.25)) -> -1.1618829 | T6: =INDEX($D$5:$D$22,N6) -> 46.7
A7: 3 | B7: =02_実験計画!K7 -> 3 | C7: =02_実験計画!C7 -> 1 | D7: =IF(C7=1,_XtX!H7,"") -> 43.5 | E7: =IF(C7=1,_XtX!K7,"") -> 43.377299 | F7: =IF(C7=1,D7-E7,"") -> 0.12270115 | G7: =IF(C7=1,F7/04_回帰ANOVA!$K$14,"") -> 0.17154762 | H7: =IF(C7=1,_XtX!J7,"") -> 0.79022989 | I7: =IF(C7=1,IF(H7<0.9999,F7/(04_回帰ANOVA!$K$14*SQRT(1-H7)),0),"") -> 0.37455265 | J7: =IF(C7=1,IF(ABS(I7)>3,"要確認",IF(ABS(I7)>2,"注意","")),"") | L7: 3 | M7: =MIN(L7,04_回帰ANOVA!$K$6) -> 3 | N7: =MATCH(M7,$B$5:$B$22,0) -> 3 | O7: =INDEX($E$5:$E$22,N7) -> 43.377299 | P7: =INDEX($F$5:$F$22,N7) -> 0.12270115 | Q7: =M7 -> 3 | R7: =SMALL($F$5:$F$22,M7) -> -0.22873563 | S7: =NORMSINV((M7-0.375)/(04_回帰ANOVA!$K$6+0.25)) -> -0.84837993 | T7: =INDEX($D$5:$D$22,N7) -> 43.5
A8: 4 | B8: =02_実験計画!K8 -> 9 | C8: =02_実験計画!C8 -> 1 | D8: =IF(C8=1,_XtX!H8,"") -> 48.8 | E8: =IF(C8=1,_XtX!K8,"") -> 48.660632 | F8: =IF(C8=1,D8-E8,"") -> 0.13936782 | G8: =IF(C8=1,F8/04_回帰ANOVA!$K$14,"") -> 0.19484917 | H8: =IF(C8=1,_XtX!J8,"") -> 0.79022989 | I8: =IF(C8=1,IF(H8<0.9999,F8/(04_回帰ANOVA!$K$14*SQRT(1-H8)),0),"") -> 0.42542866 | J8: =IF(C8=1,IF(ABS(I8)>3,"要確認",IF(ABS(I8)>2,"注意","")),"") | L8: 4 | M8: =MIN(L8,04_回帰ANOVA!$K$6) -> 4 | N8: =MATCH(M8,$B$5:$B$22,0) -> 1 | O8: =INDEX($E$5:$E$22,N8) -> 39.927299 | P8: =INDEX($F$5:$F$22,N8) -> 0.072701149 | Q8: =M8 -> 4 | R8: =SMALL($F$5:$F$22,M8) -> -0.1954023 | S8: =NORMSINV((M8-0.375)/(04_回帰ANOVA!$K$6+0.25)) -> -0.6020065 | T8: =INDEX($D$5:$D$22,N8) -> 40
A9: 5 | B9: =02_実験計画!K9 -> 6 | C9: =02_実験計画!C9 -> 1 | D9: =IF(C9=1,_XtX!H9,"") -> 43 | E9: =IF(C9=1,_XtX!K9,"") -> 43.195402 | F9: =IF(C9=1,D9-E9,"") -> -0.1954023 | G9: =IF(C9=1,F9/04_回帰ANOVA!$K$14,"") -> -0.27319058 | H9: =IF(C9=1,_XtX!J9,"") -> 0.49425287 | I9: =IF(C9=1,IF(H9<0.9999,F9/(04_回帰ANOVA!$K$14*SQRT(1-H9)),0),"") -> -0.38414839 | J9: =IF(C9=1,IF(ABS(I9)>3,"要確認",IF(ABS(I9)>2,"注意","")),"") | L9: 5 | M9: =MIN(L9,04_回帰ANOVA!$K$6) -> 5 | N9: =MATCH(M9,$B$5:$B$22,0) -> 2 | O9: =INDEX($E$5:$E$22,N9) -> 43.110632 | P9: =INDEX($F$5:$F$22,N9) -> 0.089367816 | Q9: =M9 -> 5 | R9: =SMALL($F$5:$F$22,M9) -> -0.16206897 | S9: =NORMSINV((M9-0.375)/(04_回帰ANOVA!$K$6+0.25)) -> -0.38786869 | T9: =INDEX($D$5:$D$22,N9) -> 43.2
A10: 6 | B10: =02_実験計画!K10 -> 10 | C10: =02_実験計画!C10 -> 1 | D10: =IF(C10=1,_XtX!H10,"") -> 47.2 | E10: =IF(C10=1,_XtX!K10,"") -> 47.428736 | F10: =IF(C10=1,D10-E10,"") -> -0.22873563 | G10: =IF(C10=1,F10/04_回帰ANOVA!$K$14,"") -> -0.31979368 | H10: =IF(C10=1,_XtX!J10,"") -> 0.49425287 | I10: =IF(C10=1,IF(H10<0.9999,F10/(04_回帰ANOVA!$K$14*SQRT(1-H10)),0),"") -> -0.44967958 | J10: =IF(C10=1,IF(ABS(I10)>3,"要確認",IF(ABS(I10)>2,"注意","")),"") | L10: 6 | M10: =MIN(L10,04_回帰ANOVA!$K$6) -> 6 | N10: =MATCH(M10,$B$5:$B$22,0) -> 5 | O10: =INDEX($E$5:$E$22,N10) -> 43.195402 | P10: =INDEX($F$5:$F$22,N10) -> -0.1954023 | Q10: =M10 -> 6 | R10: =SMALL($F$5:$F$22,M10) -> -0.15517241 | S10: =NORMSINV((M10-0.375)/(04_回帰ANOVA!$K$6+0.25)) -> -0.19032227 | T10: =INDEX($D$5:$D$22,N10) -> 43
A11: 7 | B11: =02_実験計画!K11 -> 8 | C11: =02_実験計画!C11 -> 1 | D11: =IF(C11=1,_XtX!H11,"") -> 44.1 | E11: =IF(C11=1,_XtX!K11,"") -> 44.262069 | F11: =IF(C11=1,D11-E11,"") -> -0.16206897 | G11: =IF(C11=1,F11/04_回帰ANOVA!$K$14,"") -> -0.22658748 | H11: =IF(C11=1,_XtX!J11,"") -> 0.49425287 | I11: =IF(C11=1,IF(H11<0.9999,F11/(04_回帰ANOVA!$K$14*SQRT(1-H11)),0),"") -> -0.31861719 | J11: =IF(C11=1,IF(ABS(I11)>3,"要確認",IF(ABS(I11)>2,"注意","")),"") | L11: 7 | M11: =MIN(L11,04_回帰ANOVA!$K$6) -> 7 | N11: =MATCH(M11,$B$5:$B$22,0) -> 13 | O11: =INDEX($E$5:$E$22,N11) -> 48.055172 | P11: =INDEX($F$5:$F$22,N11) -> 0.44482759 | Q11: =M11 -> 7 | R11: =SMALL($F$5:$F$22,M11) -> 0.072701149 | S11: =NORMSINV((M11-0.375)/(04_回帰ANOVA!$K$6+0.25)) -> 0 | T11: =INDEX($D$5:$D$22,N11) -> 48.5
A12: 8 | B12: =02_実験計画!K12 -> 11 | C12: =02_実験計画!C12 -> 1 | D12: =IF(C12=1,_XtX!H12,"") -> 48.5 | E12: =IF(C12=1,_XtX!K12,"") -> 48.762069 | F12: =IF(C12=1,D12-E12,"") -> -0.26206897 | G12: =IF(C12=1,F12/04_回帰ANOVA!$K$14,"") -> -0.36639678 | H12: =IF(C12=1,_XtX!J12,"") -> 0.49425287 | I12: =IF(C12=1,IF(H12<0.9999,F12/(04_回帰ANOVA!$K$14*SQRT(1-H12)),0),"") -> -0.51521078 | J12: =IF(C12=1,IF(ABS(I12)>3,"要確認",IF(ABS(I12)>2,"注意","")),"") | L12: 8 | M12: =MIN(L12,04_回帰ANOVA!$K$6) -> 8 | N12: =MATCH(M12,$B$5:$B$22,0) -> 7 | O12: =INDEX($E$5:$E$22,N12) -> 44.262069 | P12: =INDEX($F$5:$F$22,N12) -> -0.16206897 | Q12: =M12 -> 8 | R12: =SMALL($F$5:$F$22,M12) -> 0.089367816 | S12: =NORMSINV((M12-0.375)/(04_回帰ANOVA!$K$6+0.25)) -> 0.19032227 | T12: =INDEX($D$5:$D$22,N12) -> 44.1
A13: 9 | B13: =02_実験計画!K13 -> 12 | C13: =02_実験計画!C13 -> 1 | D13: =IF(C13=1,_XtX!H13,"") -> 48.5 | E13: =IF(C13=1,_XtX!K13,"") -> 48.055172 | F13: =IF(C13=1,D13-E13,"") -> 0.44482759 | G13: =IF(C13=1,F13/04_回帰ANOVA!$K$14,"") -> 0.62191033 | H13: =IF(C13=1,_XtX!J13,"") -> 0.17241379 | I13: =IF(C13=1,IF(H13<0.9999,F13/(04_回帰ANOVA!$K$14*SQRT(1-H13)),0),"") -> 0.68363005 | J13: =IF(C13=1,IF(ABS(I13)>3,"要確認",IF(ABS(I13)>2,"注意","")),"") | L13: 9 | M13: =MIN(L13,04_回帰ANOVA!$K$6) -> 9 | N13: =MATCH(M13,$B$5:$B$22,0) -> 4 | O13: =INDEX($E$5:$E$22,N13) -> 48.660632 | P13: =INDEX($F$5:$F$22,N13) -> 0.13936782 | Q13: =M13 -> 9 | R13: =SMALL($F$5:$F$22,M13) -> 0.12270115 | S13: =NORMSINV((M13-0.375)/(04_回帰ANOVA!$K$6+0.25)) -> 0.38786869 | T13: =INDEX($D$5:$D$22,N13) -> 48.8
A14: 10 | B14: =02_実験計画!K14 -> 2 | C14: =02_実験計画!C14 -> 1 | D14: =IF(C14=1,_XtX!H14,"") -> 46.7 | E14: =IF(C14=1,_XtX!K14,"") -> 48.055172 | F14: =IF(C14=1,D14-E14,"") -> -1.3551724 | G14: =IF(C14=1,F14/04_回帰ANOVA!$K$14,"") -> -1.894657 | H14: =IF(C14=1,_XtX!J14,"") -> 0.17241379 | I14: =IF(C14=1,IF(H14<0.9999,F14/(04_回帰ANOVA!$K$14*SQRT(1-H14)),0),"") -> -2.0826869 | J14: =IF(C14=1,IF(ABS(I14)>3,"要確認",IF(ABS(I14)>2,"注意","")),"") -> 注意 | L14: 10 | M14: =MIN(L14,04_回帰ANOVA!$K$6) -> 10 | N14: =MATCH(M14,$B$5:$B$22,0) -> 6 | O14: =INDEX($E$5:$E$22,N14) -> 47.428736 | P14: =INDEX($F$5:$F$22,N14) -> -0.22873563 | Q14: =M14 -> 10 | R14: =SMALL($F$5:$F$22,M14) -> 0.13936782 | S14: =NORMSINV((M14-0.375)/(04_回帰ANOVA!$K$6+0.25)) -> 0.6020065 | T14: =INDEX($D$5:$D$22,N14) -> 47.2
A15: 11 | B15: =02_実験計画!K15 -> 13 | C15: =02_実験計画!C15 -> 1 | D15: =IF(C15=1,_XtX!H15,"") -> 49.1 | E15: =IF(C15=1,_XtX!K15,"") -> 48.055172 | F15: =IF(C15=1,D15-E15,"") -> 1.0448276 | G15: =IF(C15=1,F15/04_回帰ANOVA!$K$14,"") -> 1.4607661 | H15: =IF(C15=1,_XtX!J15,"") -> 0.17241379 | I15: =IF(C15=1,IF(H15<0.9999,F15/(04_回帰ANOVA!$K$14*SQRT(1-H15)),0),"") -> 1.6057357 | J15: =IF(C15=1,IF(ABS(I15)>3,"要確認",IF(ABS(I15)>2,"注意","")),"") | L15: 11 | M15: =MIN(L15,04_回帰ANOVA!$K$6) -> 11 | N15: =MATCH(M15,$B$5:$B$22,0) -> 8 | O15: =INDEX($E$5:$E$22,N15) -> 48.762069 | P15: =INDEX($F$5:$F$22,N15) -> -0.26206897 | Q15: =M15 -> 11 | R15: =SMALL($F$5:$F$22,M15) -> 0.44482759 | S15: =NORMSINV((M15-0.375)/(04_回帰ANOVA!$K$6+0.25)) -> 0.84837993 | T15: =INDEX($D$5:$D$22,N15) -> 48.5
A16: 12 | B16: =02_実験計画!K16 -> 1 | C16: =02_実験計画!C16 -> 1 | D16: =IF(C16=1,_XtX!H16,"") -> 47.9 | E16: =IF(C16=1,_XtX!K16,"") -> 48.055172 | F16: =IF(C16=1,D16-E16,"") -> -0.15517241 | G16: =IF(C16=1,F16/04_回帰ANOVA!$K$14,"") -> -0.21694546 | H16: =IF(C16=1,_XtX!J16,"") -> 0.17241379 | I16: =IF(C16=1,IF(H16<0.9999,F16/(04_回帰ANOVA!$K$14*SQRT(1-H16)),0),"") -> -0.2384756 | J16: =IF(C16=1,IF(ABS(I16)>3,"要確認",IF(ABS(I16)>2,"注意","")),"") | L16: 12 | M16: =MIN(L16,04_回帰ANOVA!$K$6) -> 12 | N16: =MATCH(M16,$B$5:$B$22,0) -> 9 | O16: =INDEX($E$5:$E$22,N16) -> 48.055172 | P16: =INDEX($F$5:$F$22,N16) -> 0.44482759 | Q16: =M16 -> 12 | R16: =SMALL($F$5:$F$22,M16) -> 0.44482759 | S16: =NORMSINV((M16-0.375)/(04_回帰ANOVA!$K$6+0.25)) -> 1.1618829 | T16: =INDEX($D$5:$D$22,N16) -> 48.5
... A22: 18 | B22: =02_実験計画!K22 | C22: =02_実験計画!C22 -> 0 | D22: =IF(C22=1,_XtX!H22,"") | E22: =IF(C22=1,_XtX!K22,"") | F22: =IF(C22=1,D22-E22,"") | G22: =IF(C22=1,F22/04_回帰ANOVA!$K$14,"") | H22: =IF(C22=1,_XtX!J22,"") | I22: =IF(C22=1,IF(H22<0.9999,F22/(04_回帰ANOVA!$K$14*SQRT(1-H22)),0),"") | J22: =IF(C22=1,IF(ABS(I22)>3,"要確認",IF(ABS(I22)>2,"注意","")),"") | L22: 18 | M22: =MIN(L22,04_回帰ANOVA!$K$6) -> 13 | N22: =MATCH(M22,$B$5:$B$22,0) -> 11 | O22: =INDEX($E$5:$E$22,N22) -> 48.055172 | P22: =INDEX($F$5:$F$22,N22) -> 1.0448276 | Q22: =M22 -> 13 | R22: =SMALL($F$5:$F$22,M22) -> 1.0448276 | S22: =NORMSINV((M22-0.375)/(04_回帰ANOVA!$K$6+0.25)) -> 1.6729374 | T22: =INDEX($D$5:$D$22,N22) -> 49.1
V37: 見方：①残差vs予測に漏斗形・曲線パターンがない ②正規確率がほぼ直線 ③実験順に傾向（ドリフト）がない ④実測vs予測が45°線上

Sheet 06_正準解析
A1: 06 正準解析（停留点の種類と位置）
A2: 最適化の前に必ず確認：停留点が最大点・最小点・鞍点のどれか、実験領域の内か外か。
A5: 2次係数行列 B | E5: 1次係数 b
A6: X1 | B6: =04_回帰ANOVA!C10 -> -2.7431034 | C6: =04_回帰ANOVA!C9/2 -> 0.2625 | E6: =04_回帰ANOVA!C7 -> 2.1166667
A7: X2 | B7: =04_回帰ANOVA!C9/2 -> 0.2625 | C7: =04_回帰ANOVA!C11 -> -1.5431034 | E7: =04_回帰ANOVA!C8 -> 2.25
A12: 因子 | B12: 停留点(コード) | C12: 停留点(実値) | D12: 単位
A13: =01_因子設定!B5 -> 炉温 | B13: =IFERROR(-0.5*INDEX(MMULT(MINVERSE($B$6:$C$7),$E$6:$E$7),1,1),"算出不可") -> 0.46312121 | C13: =IF(ISNUMBER(B13),01_因子設定!G5+B13*01_因子設定!H5,"") -> 69.631212 | D13: =01_因子設定!D5 -> ℃
A14: =01_因子設定!B6 -> 乾燥時間 | B14: =IFERROR(-0.5*INDEX(MMULT(MINVERSE($B$6:$C$7),$E$6:$E$7),2,1),"算出不可") -> 0.80783263 | C14: =IF(ISNUMBER(B14),01_因子設定!G6+B14*01_因子設定!H6,"") -> 38.078326 | D14: =01_因子設定!D6 -> min
A18: 停留点での予測Y | B18: =IF(ISNUMBER(B13),04_回帰ANOVA!C6+0.5*SUMPRODUCT(E6:E7,B13:B14),"") -> 49.454121
A19: 中心からの距離 | B19: =IF(ISNUMBER(B13),SQRT(SUMSQ(B13:B14)),"") -> 0.93116852
A20: 実験領域内か | B20: =IF(NOT(ISNUMBER(B13)),"－",IF(01_因子設定!$B$20="Box-Behnken",IF(B19<=SQRT(2),"領域内","領域外（外挿）"),IF(01_因子設定!$B$20="回転可能CCD(α=1.414)",IF(B19<=1.4142135623731,"領域内","領域外（外挿）"),IF(MAX(ABS(B13),ABS(B14))<=1,"領域内","領域外（外挿）")))) -> 領域内
A22: 固有値 | B22: 値
A23: λ1 | B23: =SMALL((_eig!B37~_eig!C38),1) -> -2.7980128
A24: λ2 | B24: =SMALL((_eig!B37~_eig!C38),2) -> -1.4881941
A28: 停留点の種類 | B28: =IF(MAX(B23:B24)<0,"最大点",IF(MIN(B23:B24)>0,"最小点","鞍点")) -> 最大点
A29: 尾根（リッジ） | B29: =IF(MIN(ABS(B23),ABS(B24))<0.1*MAX(ABS(B23),ABS(B24)),"あり：ほぼ平らな方向がある → その方向には工程窓を広く取れる可能性","なし：全方向に明確な曲率") -> なし：全方向に明確な曲率
A30: 判断 | B30: =IF(NOT(ISNUMBER(B13)),"停留点を算出できない（2次項を除外している等）→ 07の探索結果を使う",IF(B20<>"領域内","停留点は実験領域外。外挿値は信用しない → 07の領域内探索結果を採用し、必要なら領域を移して追加実験",IF(OR(AND(01_因子設定!$B$13="最大化",B28="最大点"),AND(01_因子設定!$B$13="最小化",B28="最小点")),"停留点が領域内の最適点候補。07の結果と一致するか確認",IF(B28="鞍点","鞍点のため停留点は最適点ではない → 07の探索結果（領域境界上になりやすい）を採用","停留点は目的と逆向きの極値 → 07の探索結果を採用")))) -> 停留点が領域内の最適点候補。07の結果と一致するか確認
A32: 固有値はJacobi法で数値計算（_eigシート）。λが全て負→最大点、全て正→最小点、正負混在→鞍点。

Sheet 07_最適化
A1: 07 最適化（実験領域内の2次元グリッド探索）
A2: 『点予測の最適』と『予測限界で規格への余裕が最大の条件（ロバスト最適）』を並べて表示します。
A4: 項目 | B4: ロバスト最適（推奨） | C4: 点予測の最適 | E4: 説明
A5: グリッド行 | B5: =MATCH(MAX(_grid!$S$5:$S$1685),_grid!$S$5:$S$1685,0) -> 1224 | C5: =MATCH(MAX(_grid!$T$5:$T$1685),_grid!$T$5:$T$1685,0) -> 1226 | E5: ロバスト最適：規格側の予測限界（最大化なら下側限界）と規格の差が最大の条件。ばらつきを考慮した推奨条件。 点予測の最適：予測値そのものが最大（最小・目標値に最も近い）条件。境界に張り付きやすく、区間は広め。 両者が大きく違う場合、点予測の最適は『予測のばらつきが大きい場所』にある。原則ロバスト最適を採用。 判定用下限・上限：最大化・最小化は片側、目標値は両側の予測限界（04のt値を使用）。 ×の場合：規格が厳しすぎる／因子範囲が不適切／モデル誤差が大きい。範囲を移して追加実験、sの低減を検討。
A6: =01_因子設定!B5&"（コード）" -> 炉温（コード） | B6: =INDEX(_grid!$C$5:$C$1685,B$5) -> 0.45 | C6: =INDEX(_grid!$C$5:$C$1685,C$5) -> 0.45
A7: =01_因子設定!B6&"（コード）" -> 乾燥時間（コード） | B7: =INDEX(_grid!$D$5:$D$1685,B$5) -> 0.7 | C7: =INDEX(_grid!$D$5:$D$1685,C$5) -> 0.8
A8: =01_因子設定!B5&"["&01_因子設定!D5&"]" -> 炉温[℃] | B8: =01_因子設定!$G$5+B6*01_因子設定!$H$5 -> 69.5 | C8: =01_因子設定!$G$5+C6*01_因子設定!$H$5 -> 69.5
A9: =01_因子設定!B6&"["&01_因子設定!D6&"]" -> 乾燥時間[min] | B9: =01_因子設定!$G$6+B7*01_因子設定!$H$6 -> 37 | C9: =01_因子設定!$G$6+C7*01_因子設定!$H$6 -> 38
A10: 予測Y | B10: =INDEX(_grid!$K$5:$K$1685,B$5) -> 49.436448 | C10: =INDEX(_grid!$K$5:$K$1685,C$5) -> 49.453608
A11: 判定用下限 | B11: =INDEX(_grid!$N$5:$N$1685,B$5) -> 47.925163 | C11: =INDEX(_grid!$N$5:$N$1685,C$5) -> 47.909537
A12: 判定用上限 | B12: =INDEX(_grid!$O$5:$O$1685,B$5) -> 50.947733 | C12: =INDEX(_grid!$O$5:$O$1685,C$5) -> 50.997679
A13: 規格への余裕 | B13: =INDEX(_grid!$Q$5:$Q$1685,B$5) -> 1.4251635 | C13: =INDEX(_grid!$Q$5:$Q$1685,C$5) -> 1.4095368
A14: 判定 | B14: =IF(B13<-1E+029,"有効な点なし（安全限界・領域を確認）",IF(B13>=0,"○ 予測限界でも規格を満たす","× 予測限界では規格を満たせない")) -> ○ 予測限界でも規格を満たす | C14: =IF(C13<-1E+029,"有効な点なし（安全限界・領域を確認）",IF(C13>=0,"○ 予測限界でも規格を満たす","× 予測限界では規格を満たせない")) -> ○ 予測限界でも規格を満たす
A17: ロバスト最適の上位5候補（実値）
A18: 順位 | B18: グリッド行 | C18: =01_因子設定!B5 -> 炉温 | D18: =01_因子設定!B6 -> 乾燥時間 | E18: 予測Y | F18: 判定用下限 | G18: 判定用上限 | H18: 余裕
A19: 1 | B19: =MATCH(LARGE(_grid!$S$5:$S$1685,1),_grid!$S$5:$S$1685,0) -> 1224 | C19: =01_因子設定!$G$5+INDEX(_grid!$C$5:$C$1685,$B19)*01_因子設定!$H$5 -> 69.5 | D19: =01_因子設定!$G$6+INDEX(_grid!$D$5:$D$1685,$B19)*01_因子設定!$H$6 -> 37 | E19: =INDEX(_grid!$K$5:$K$1685,$B19) -> 49.436448 | F19: =INDEX(_grid!$N$5:$N$1685,$B19) -> 47.925163 | G19: =INDEX(_grid!$O$5:$O$1685,$B19) -> 50.947733 | H19: =INDEX(_grid!$Q$5:$Q$1685,$B19) -> 1.4251635
A20: 2 | B20: =MATCH(LARGE(_grid!$S$5:$S$1685,2),_grid!$S$5:$S$1685,0) -> 1225 | C20: =01_因子設定!$G$5+INDEX(_grid!$C$5:$C$1685,$B20)*01_因子設定!$H$5 -> 69.5 | D20: =01_因子設定!$G$6+INDEX(_grid!$D$5:$D$1685,$B20)*01_因子設定!$H$6 -> 37.5 | E20: =INDEX(_grid!$K$5:$K$1685,$B20) -> 49.448886 | F20: =INDEX(_grid!$N$5:$N$1685,$B20) -> 47.92289 | G20: =INDEX(_grid!$O$5:$O$1685,$B20) -> 50.974882 | H20: =INDEX(_grid!$Q$5:$Q$1685,$B20) -> 1.42289
A21: 3 | B21: =MATCH(LARGE(_grid!$S$5:$S$1685,3),_grid!$S$5:$S$1685,0) -> 1183 | C21: =01_因子設定!$G$5+INDEX(_grid!$C$5:$C$1685,$B21)*01_因子設定!$H$5 -> 69 | D21: =01_因子設定!$G$6+INDEX(_grid!$D$5:$D$1685,$B21)*01_因子設定!$H$6 -> 37 | E21: =INDEX(_grid!$K$5:$K$1685,$B21) -> 49.428822 | F21: =INDEX(_grid!$N$5:$N$1685,$B21) -> 47.919561 | G21: =INDEX(_grid!$O$5:$O$1685,$B21) -> 50.938082 | H21: =INDEX(_grid!$Q$5:$Q$1685,$B21) -> 1.4195614
A22: 4 | B22: =MATCH(LARGE(_grid!$S$5:$S$1685,4),_grid!$S$5:$S$1685,0) -> 1223 | C22: =01_因子設定!$G$5+INDEX(_grid!$C$5:$C$1685,$B22)*01_因子設定!$H$5 -> 69.5 | D22: =01_因子設定!$G$6+INDEX(_grid!$D$5:$D$1685,$B22)*01_因子設定!$H$6 -> 36.5 | E22: =INDEX(_grid!$K$5:$K$1685,$B22) -> 49.416295 | F22: =INDEX(_grid!$N$5:$N$1685,$B22) -> 47.91674 | G22: =INDEX(_grid!$O$5:$O$1685,$B22) -> 50.91585 | H22: =INDEX(_grid!$Q$5:$Q$1685,$B22) -> 1.4167404
A23: 5 | B23: =MATCH(LARGE(_grid!$S$5:$S$1685,5),_grid!$S$5:$S$1685,0) -> 1184 | C23: =01_因子設定!$G$5+INDEX(_grid!$C$5:$C$1685,$B23)*01_因子設定!$H$5 -> 69 | D23: =01_因子設定!$G$6+INDEX(_grid!$D$5:$D$1685,$B23)*01_因子設定!$H$6 -> 37.5 | E23: =INDEX(_grid!$K$5:$K$1685,$B23) -> 49.439947 | F23: =INDEX(_grid!$N$5:$N$1685,$B23) -> 47.915908 | G23: =INDEX(_grid!$O$5:$O$1685,$B23) -> 50.963986 | H23: =INDEX(_grid!$Q$5:$Q$1685,$B23) -> 1.4159078
A24: 上位候補が近い値に集まっていれば最適点は安定。ばらばらなら平坦（尾根）で、工程窓を広く取れる可能性。
A26: （任意）Solverで精密化
A27: グリッドは0.050刻み。細かく詰める場合は、下の黄色セルにロバスト最適のコード値を値貼り付け→データ→ソルバー：目的セル『余裕』を最大化、変数セルは黄色セル、制約は右の表示、解法『GRG非線形』（マルチスタート推奨）。
A28: =01_因子設定!B5&"（コード）" -> 炉温（コード） | B28: 0 | C28: ="制約："&TEXT(MAX(-1,01_因子設定!L5),"0.00")&" ≦ B28 ≦ "&TEXT(MIN(1,01_因子設定!M5),"0.00") -> 制約：-1.00 ≦ B28 ≦ 1.00 | D28: =01_因子設定!$G$5+B28*01_因子設定!$H$5 -> 65 | M28: 切片 | N28: X1 | O28: X2 | P28: X1·X2 | Q28: X1² | R28: X2²
A29: =01_因子設定!B6&"（コード）" -> 乾燥時間（コード） | B29: 0 | C29: ="制約："&TEXT(MAX(-1,01_因子設定!L6),"0.00")&" ≦ B29 ≦ "&TEXT(MIN(1,01_因子設定!M6),"0.00") -> 制約：-1.00 ≦ B29 ≦ 1.00 | D29: =01_因子設定!$G$6+B29*01_因子設定!$H$6 -> 30 | M29: =1 -> 1 | N29: =$B$28 -> 0 | O29: =$B$29 -> 0 | P29: =$B$28*$B$29 -> 0 | Q29: =$B$28*$B$28 -> 0 | R29: =$B$29*$B$29 -> 0
A31: 予測Y | B31: =SUMPRODUCT(M29:R29,_XtX!$B$53:$G$53) -> 48.055172
A32: q | B32: =SUMPRODUCT(MMULT(M29:R29,_XtX!$B$44:$G$49),M29:R29) -> 0.17241379
A33: 判定用下限／上限 | B33: =B31-04_回帰ANOVA!$K$19*04_回帰ANOVA!$K$14*SQRT(1+B32) -> 46.587879 | C33: =B31+04_回帰ANOVA!$K$19*04_回帰ANOVA!$K$14*SQRT(1+B32) -> 49.522466
A34: 余裕（目的セル） | B34: =IF(01_因子設定!$B$13="最大化",B33-01_因子設定!$B$14,IF(01_因子設定!$B$13="最小化",01_因子設定!$B$15-C33,MIN(B33-01_因子設定!$B$14,01_因子設定!$B$15-C33))) -> 0.087878785

Sheet 08_工程窓
A1: 08 工程窓（予測限界ベース）
A2: 2因子を軸にした断面で予測値と『規格への余裕』を表示。余裕≧0（緑）が工程窓。
A4: 横軸の因子 | B4: X1 | C4: =VALUE(RIGHT(B4,1)) -> 1 | D4: =INDEX(01_因子設定!$B$5:$B$6,C4)&"["&INDEX(01_因子設定!$D$5:$D$6,C4)&"]" -> 炉温[℃] | E4: =IF(C4=C5,"× 横軸と縦軸に同じ因子は指定できません","")
A5: 縦軸の因子 | B5: X2 | C5: =VALUE(RIGHT(B5,1)) -> 2 | D5: =INDEX(01_因子設定!$B$5:$B$6,C5)&"["&INDEX(01_因子設定!$D$5:$D$6,C5)&"]" -> 乾燥時間[min]
A6: 固定因子の値 | B6: ロバスト最適点
A8: 因子 | B8: 手入力(コード) | C8: 使用する固定値(コード) | D8: 実値 | E8: 役割
A9: =01_因子設定!B5 -> 炉温 | B9: 0 | C9: =IF($B$6="手入力",B9,IF($B$6="点予測最適点",07_最適化!$C$6,07_最適化!$B$6)) -> 0.45 | D9: =01_因子設定!G5+C9*01_因子設定!H5 -> 69.5 | E9: =IF($C$4=1,"横軸",IF($C$5=1,"縦軸","固定")) -> 横軸
A10: =01_因子設定!B6 -> 乾燥時間 | B10: 0 | C10: =IF($B$6="手入力",B10,IF($B$6="点予測最適点",07_最適化!$C$7,07_最適化!$B$7)) -> 0.7 | D10: =01_因子設定!G6+C10*01_因子設定!H6 -> 37 | E10: =IF($C$4=2,"横軸",IF($C$5=2,"縦軸","固定")) -> 縦軸
A12: ① 予測値 Ŷ（点予測）
A13: 縦↓ 実値 | B13: コード | C13: -1 | D13: -0.9 | E13: -0.8 | F13: -0.7 | G13: -0.6 | H13: -0.5 | I13: -0.4 | J13: -0.3 | K13: -0.2 | L13: -0.1 | M13: 0 | N13: 0.1 | O13: 0.2 | P13: 0.3 | Q13: 0.4 | R13: 0.5 | S13: 0.6 | T13: 0.7 | U13: 0.8 | V13: 0.9 | W13: 1
A14: ="縦↓ "&$D$5 -> 縦↓ 乾燥時間[min] | B14: ="横→ "&$D$4 -> 横→ 炉温[℃] | C14: =INDEX(01_因子設定!$G$5:$G$6,$C$4)+C13*INDEX(01_因子設定!$H$5:$H$6,$C$4) -> 55 | D14: =INDEX(01_因子設定!$G$5:$G$6,$C$4)+D13*INDEX(01_因子設定!$H$5:$H$6,$C$4) -> 56 | E14: =INDEX(01_因子設定!$G$5:$G$6,$C$4)+E13*INDEX(01_因子設定!$H$5:$H$6,$C$4) -> 57 | F14: =INDEX(01_因子設定!$G$5:$G$6,$C$4)+F13*INDEX(01_因子設定!$H$5:$H$6,$C$4) -> 58 | G14: =INDEX(01_因子設定!$G$5:$G$6,$C$4)+G13*INDEX(01_因子設定!$H$5:$H$6,$C$4) -> 59 | H14: =INDEX(01_因子設定!$G$5:$G$6,$C$4)+H13*INDEX(01_因子設定!$H$5:$H$6,$C$4) -> 60 | I14: =INDEX(01_因子設定!$G$5:$G$6,$C$4)+I13*INDEX(01_因子設定!$H$5:$H$6,$C$4) -> 61 | J14: =INDEX(01_因子設定!$G$5:$G$6,$C$4)+J13*INDEX(01_因子設定!$H$5:$H$6,$C$4) -> 62 | ... W14: =INDEX(01_因子設定!$G$5:$G$6,$C$4)+W13*INDEX(01_因子設定!$H$5:$H$6,$C$4) -> 75
A15: =INDEX(01_因子設定!$G$5:$G$6,$C$5)+B15*INDEX(01_因子設定!$H$5:$H$6,$C$5) -> 40 | B15: 1 | C15: =IF(AND(_slice!$H$5=1,C$13>=_slice!$H$6-0.000000001,C$13<=_slice!$I$6+0.000000001,$B15>=_slice!$H$7-0.000000001,$B15<=_slice!$I$7+0.000000001,IF(01_因子設定!$B$20="Box-Behnken",C$13^2+$B15^2+_slice!$H$8<=2+0.000000001,TRUE())),_slice!C66,"外") -> 43.377299 | D15: =IF(AND(_slice!$H$5=1,D$13>=_slice!$H$6-0.000000001,D$13<=_slice!$I$6+0.000000001,$B15>=_slice!$H$7-0.000000001,$B15<=_slice!$I$7+0.000000001,IF(01_因子設定!$B$20="Box-Behnken",D$13^2+$B15^2+_slice!$H$8<=2+0.000000001,TRUE())),_slice!D66,"外") -> 44.162655 | E15: =IF(AND(_slice!$H$5=1,E$13>=_slice!$H$6-0.000000001,E$13<=_slice!$I$6+0.000000001,$B15>=_slice!$H$7-0.000000001,$B15<=_slice!$I$7+0.000000001,IF(01_因子設定!$B$20="Box-Behnken",E$13^2+$B15^2+_slice!$H$8<=2+0.000000001,TRUE())),_slice!E66,"外") -> 44.893149 | F15: =IF(AND(_slice!$H$5=1,F$13>=_slice!$H$6-0.000000001,F$13<=_slice!$I$6+0.000000001,$B15>=_slice!$H$7-0.000000001,$B15<=_slice!$I$7+0.000000001,IF(01_因子設定!$B$20="Box-Behnken",F$13^2+$B15^2+_slice!$H$8<=2+0.000000001,TRUE())),_slice!F66,"外") -> 45.568782 | G15: =IF(AND(_slice!$H$5=1,G$13>=_slice!$H$6-0.000000001,G$13<=_slice!$I$6+0.000000001,$B15>=_slice!$H$7-0.000000001,$B15<=_slice!$I$7+0.000000001,IF(01_因子設定!$B$20="Box-Behnken",G$13^2+$B15^2+_slice!$H$8<=2+0.000000001,TRUE())),_slice!G66,"外") -> 46.189552 | H15: =IF(AND(_slice!$H$5=1,H$13>=_slice!$H$6-0.000000001,H$13<=_slice!$I$6+0.000000001,$B15>=_slice!$H$7-0.000000001,$B15<=_slice!$I$7+0.000000001,IF(01_因子設定!$B$20="Box-Behnken",H$13^2+$B15^2+_slice!$H$8<=2+0.000000001,TRUE())),_slice!H66,"外") -> 46.75546 | I15: =IF(AND(_slice!$H$5=1,I$13>=_slice!$H$6-0.000000001,I$13<=_slice!$I$6+0.000000001,$B15>=_slice!$H$7-0.000000001,$B15<=_slice!$I$7+0.000000001,IF(01_因子設定!$B$20="Box-Behnken",I$13^2+$B15^2+_slice!$H$8<=2+0.000000001,TRUE())),_slice!I66,"外") -> 47.266506 | J15: =IF(AND(_slice!$H$5=1,J$13>=_slice!$H$6-0.000000001,J$13<=_slice!$I$6+0.000000001,$B15>=_slice!$H$7-0.000000001,$B15<=_slice!$I$7+0.000000001,IF(01_因子設定!$B$20="Box-Behnken",J$13^2+$B15^2+_slice!$H$8<=2+0.000000001,TRUE())),_slice!J66,"外") -> 47.72269 | ... W15: =IF(AND(_slice!$H$5=1,W$13>=_slice!$H$6-0.000000001,W$13<=_slice!$I$6+0.000000001,$B15>=_slice!$H$7-0.000000001,$B15<=_slice!$I$7+0.000000001,IF(01_因子設定!$B$20="Box-Behnken",W$13^2+$B15^2+_slice!$H$8<=2+0.000000001,TRUE())),_slice!W66,"外") -> 48.660632
A16: =INDEX(01_因子設定!$G$5:$G$6,$C$5)+B16*INDEX(01_因子設定!$H$5:$H$6,$C$5) -> 39 | B16: 0.9 | C16: =IF(AND(_slice!$H$5=1,C$13>=_slice!$H$6-0.000000001,C$13<=_slice!$I$6+0.000000001,$B16>=_slice!$H$7-0.000000001,$B16<=_slice!$I$7+0.000000001,IF(01_因子設定!$B$20="Box-Behnken",C$13^2+$B16^2+_slice!$H$8<=2+0.000000001,TRUE())),_slice!C67,"外") -> 43.497989 | D16: =IF(AND(_slice!$H$5=1,D$13>=_slice!$H$6-0.000000001,D$13<=_slice!$I$6+0.000000001,$B16>=_slice!$H$7-0.000000001,$B16<=_slice!$I$7+0.000000001,IF(01_因子設定!$B$20="Box-Behnken",D$13^2+$B16^2+_slice!$H$8<=2+0.000000001,TRUE())),_slice!D67,"外") -> 44.278095 | E16: =IF(AND(_slice!$H$5=1,E$13>=_slice!$H$6-0.000000001,E$13<=_slice!$I$6+0.000000001,$B16>=_slice!$H$7-0.000000001,$B16<=_slice!$I$7+0.000000001,IF(01_因子設定!$B$20="Box-Behnken",E$13^2+$B16^2+_slice!$H$8<=2+0.000000001,TRUE())),_slice!E67,"外") -> 45.003339 | F16: =IF(AND(_slice!$H$5=1,F$13>=_slice!$H$6-0.000000001,F$13<=_slice!$I$6+0.000000001,$B16>=_slice!$H$7-0.000000001,$B16<=_slice!$I$7+0.000000001,IF(01_因子設定!$B$20="Box-Behnken",F$13^2+$B16^2+_slice!$H$8<=2+0.000000001,TRUE())),_slice!F67,"外") -> 45.673721 | G16: =IF(AND(_slice!$H$5=1,G$13>=_slice!$H$6-0.000000001,G$13<=_slice!$I$6+0.000000001,$B16>=_slice!$H$7-0.000000001,$B16<=_slice!$I$7+0.000000001,IF(01_因子設定!$B$20="Box-Behnken",G$13^2+$B16^2+_slice!$H$8<=2+0.000000001,TRUE())),_slice!G67,"外") -> 46.289241 | H16: =IF(AND(_slice!$H$5=1,H$13>=_slice!$H$6-0.000000001,H$13<=_slice!$I$6+0.000000001,$B16>=_slice!$H$7-0.000000001,$B16<=_slice!$I$7+0.000000001,IF(01_因子設定!$B$20="Box-Behnken",H$13^2+$B16^2+_slice!$H$8<=2+0.000000001,TRUE())),_slice!H67,"外") -> 46.849899 | I16: =IF(AND(_slice!$H$5=1,I$13>=_slice!$H$6-0.000000001,I$13<=_slice!$I$6+0.000000001,$B16>=_slice!$H$7-0.000000001,$B16<=_slice!$I$7+0.000000001,IF(01_因子設定!$B$20="Box-Behnken",I$13^2+$B16^2+_slice!$H$8<=2+0.000000001,TRUE())),_slice!I67,"外") -> 47.355695 | J16: =IF(AND(_slice!$H$5=1,J$13>=_slice!$H$6-0.000000001,J$13<=_slice!$I$6+0.000000001,$B16>=_slice!$H$7-0.000000001,$B16<=_slice!$I$7+0.000000001,IF(01_因子設定!$B$20="Box-Behnken",J$13^2+$B16^2+_slice!$H$8<=2+0.000000001,TRUE())),_slice!J67,"外") -> 47.806629 | ... W16: =IF(AND(_slice!$H$5=1,W$13>=_slice!$H$6-0.000000001,W$13<=_slice!$I$6+0.000000001,$B16>=_slice!$H$7-0.000000001,$B16<=_slice!$I$7+0.000000001,IF(01_因子設定!$B$20="Box-Behnken",W$13^2+$B16^2+_slice!$H$8<=2+0.000000001,TRUE())),_slice!W67,"外") -> 48.676322
A17: =INDEX(01_因子設定!$G$5:$G$6,$C$5)+B17*INDEX(01_因子設定!$H$5:$H$6,$C$5) -> 38 | B17: 0.8 | C17: =IF(AND(_slice!$H$5=1,C$13>=_slice!$H$6-0.000000001,C$13<=_slice!$I$6+0.000000001,$B17>=_slice!$H$7-0.000000001,$B17<=_slice!$I$7+0.000000001,IF(01_因子設定!$B$20="Box-Behnken",C$13^2+$B17^2+_slice!$H$8<=2+0.000000001,TRUE())),_slice!C68,"外") -> 43.587816 | D17: =IF(AND(_slice!$H$5=1,D$13>=_slice!$H$6-0.000000001,D$13<=_slice!$I$6+0.000000001,$B17>=_slice!$H$7-0.000000001,$B17<=_slice!$I$7+0.000000001,IF(01_因子設定!$B$20="Box-Behnken",D$13^2+$B17^2+_slice!$H$8<=2+0.000000001,TRUE())),_slice!D68,"外") -> 44.362672 | E17: =IF(AND(_slice!$H$5=1,E$13>=_slice!$H$6-0.000000001,E$13<=_slice!$I$6+0.000000001,$B17>=_slice!$H$7-0.000000001,$B17<=_slice!$I$7+0.000000001,IF(01_因子設定!$B$20="Box-Behnken",E$13^2+$B17^2+_slice!$H$8<=2+0.000000001,TRUE())),_slice!E68,"外") -> 45.082667 | F17: =IF(AND(_slice!$H$5=1,F$13>=_slice!$H$6-0.000000001,F$13<=_slice!$I$6+0.000000001,$B17>=_slice!$H$7-0.000000001,$B17<=_slice!$I$7+0.000000001,IF(01_因子設定!$B$20="Box-Behnken",F$13^2+$B17^2+_slice!$H$8<=2+0.000000001,TRUE())),_slice!F68,"外") -> 45.747799 | G17: =IF(AND(_slice!$H$5=1,G$13>=_slice!$H$6-0.000000001,G$13<=_slice!$I$6+0.000000001,$B17>=_slice!$H$7-0.000000001,$B17<=_slice!$I$7+0.000000001,IF(01_因子設定!$B$20="Box-Behnken",G$13^2+$B17^2+_slice!$H$8<=2+0.000000001,TRUE())),_slice!G68,"外") -> 46.358069 | H17: =IF(AND(_slice!$H$5=1,H$13>=_slice!$H$6-0.000000001,H$13<=_slice!$I$6+0.000000001,$B17>=_slice!$H$7-0.000000001,$B17<=_slice!$I$7+0.000000001,IF(01_因子設定!$B$20="Box-Behnken",H$13^2+$B17^2+_slice!$H$8<=2+0.000000001,TRUE())),_slice!H68,"外") -> 46.913477 | I17: =IF(AND(_slice!$H$5=1,I$13>=_slice!$H$6-0.000000001,I$13<=_slice!$I$6+0.000000001,$B17>=_slice!$H$7-0.000000001,$B17<=_slice!$I$7+0.000000001,IF(01_因子設定!$B$20="Box-Behnken",I$13^2+$B17^2+_slice!$H$8<=2+0.000000001,TRUE())),_slice!I68,"外") -> 47.414023 | J17: =IF(AND(_slice!$H$5=1,J$13>=_slice!$H$6-0.000000001,J$13<=_slice!$I$6+0.000000001,$B17>=_slice!$H$7-0.000000001,$B17<=_slice!$I$7+0.000000001,IF(01_因子設定!$B$20="Box-Behnken",J$13^2+$B17^2+_slice!$H$8<=2+0.000000001,TRUE())),_slice!J68,"外") -> 47.859707 | ... W17: =IF(AND(_slice!$H$5=1,W$13>=_slice!$H$6-0.000000001,W$13<=_slice!$I$6+0.000000001,$B17>=_slice!$H$7-0.000000001,$B17<=_slice!$I$7+0.000000001,IF(01_因子設定!$B$20="Box-Behnken",W$13^2+$B17^2+_slice!$H$8<=2+0.000000001,TRUE())),_slice!W68,"外") -> 48.661149
